<?xml version="1.0" ?>
<!-- =================================================================================== -->
<!-- |    This document was autogenerated by xacro from stickbot_humanoid_32dof_controlit/xacro/stickbot_humanoid_32dof.xacro | -->
<!-- |    EDITING THIS FILE BY HAND IS NOT RECOMMENDED                                 | -->
<!-- =================================================================================== -->
<robot name="stickRobot" xmlns:xacro="http://ros.org/wiki/xacro">
  <!-- Its seems that zero mass links are not kosher. I can't find any solid data, only suggestions from people
    as to what small but not too small should be for mass numbers.
    Until better evidence/experience says otherwise, we will use a mass that is ~0.1% * total_mass, and
    the inertia properties of a cylinder. Justification: Most of these virtual links are the rotor attached
    to gearing and any attachment structure.
     -->
  <link name="pelvis">
    <inertial>
      <mass value="2"/>
      <origin xyz="0.0 0.0 0.05"/>
      <inertia ixx="0.008667" ixy="0" ixz="0" iyy="0.008667" iyz="0" izz="0.01667"/>
    </inertial>
    <visual>
      <origin rpy="0 0 0 " xyz="0.0 -0.0 0.05"/>
      <geometry name="pelvis">
        <box size="0.05 0.4 0.1"/>
      </geometry>
      <material name="grey">
        <color rgba="0.627 0.627 0.627 1"/>
      </material>
    </visual>
    <collision>
      <origin rpy="0 0 0 " xyz="0.0 -0.0 0.05"/>
      <geometry name="pelvis">
        <box size="0.05 0.4 0.1"/>
      </geometry>
    </collision>
  </link>
  <!--LEFT LEG-->
  <joint name="leftHipYaw" type="revolute">
    <axis xyz="0 0 1"/>
    <origin rpy="0 0 0" xyz="0 0.2 0.0"/>
    <parent link="pelvis"/>
    <child link="leftHipYawLink"/>
    <dynamics damping="0.1"/>
    <limit effort="100" lower="-3.14" upper="3.14" velocity="1"/>
    <provide_feedback>true</provide_feedback>
  </joint>
  <link name="leftHipYawLink">
    <inertial>
      <mass value="2.0"/>
      <origin xyz="0.0 0.0 -0.015"/>
      <inertia ixx="0.00015" ixy="0" ixz="0" iyy="0.00015" iyz="0" izz="0.000225"/>
    </inertial>
    <visual>
      <origin rpy="0 1.507 0" xyz="0 0.0 -0.015"/>
      <geometry name="leftHipYawLink">
        <cylinder length="0.03" radius="0.03"/>
      </geometry>
      <material name="grey">
        <color rgba="0.627 0.627 0.627 1"/>
      </material>
    </visual>
    <collision>
      <origin rpy="1.507 0 0.0 " xyz="0 0.0 -0.015"/>
      <geometry name="leftHipYawLink">
        <cylinder length="0.03" radius="0.03"/>
      </geometry>
    </collision>
  </link>
  <joint name="leftHipRoll" type="revolute">
    <axis xyz="0 1 0"/>
    <origin rpy="0 0 0" xyz="0 0 -0.03"/>
    <parent link="leftHipYawLink"/>
    <child link="leftHipRollLink"/>
    <dynamics damping="0.1"/>
    <limit effort="100" lower="-3.14" upper="3.14" velocity="1"/>
    <provide_feedback>true</provide_feedback>
  </joint>
  <link name="leftHipRollLink">
    <inertial>
      <mass value="2.0"/>
      <origin xyz="0.0 0.0 -0.015"/>
      <inertia ixx="0.00015" ixy="0" ixz="0" iyy="0.00015" iyz="0" izz="0.000225"/>
    </inertial>
    <visual>
      <origin rpy="1.507 0 0" xyz="0 0 -0.015"/>
      <geometry name="leftHipRollLink">
        <cylinder length="0.03" radius="0.03"/>
      </geometry>
      <material name="grey">
        <color rgba="0.627 0.627 0.627 1"/>
      </material>
    </visual>
    <collision>
      <origin rpy="1.507 0 0.0 " xyz="0 0 -0.015"/>
      <geometry name="leftHipRollLink">
        <cylinder length="0.03" radius="0.03"/>
      </geometry>
    </collision>
  </link>
  <joint name="leftHipPitch" type="revolute">
    <axis xyz="1 0 0"/>
    <origin rpy="0 0 0" xyz="0 0 -0.03"/>
    <parent link="leftHipRollLink"/>
    <child link="leftHipPitchLink"/>
    <dynamics damping="0.1"/>
    <limit effort="100" lower="-3.14" upper="3.14" velocity="1"/>
    <provide_feedback>true</provide_feedback>
  </joint>
  <link name="leftHipPitchLink">
    <inertial>
      <mass value="2.0"/>
      <origin xyz="-0.0 0 -0.15"/>
      <inertia ixx="0.01545" ixy="0" ixz="0" iyy="0.01545" iyz="0" izz="0.0009"/>
    </inertial>
    <visual>
      <origin rpy="0 0 0 " xyz="0 0 -0.15"/>
      <geometry name="leftHipPitchLink">
        <cylinder length="0.3" radius="0.03"/>
      </geometry>
      <material name="grey">
        <color rgba="0.627 0.627 0.627 1"/>
      </material>
    </visual>
    <collision>
      <origin rpy="0 0 0 " xyz="0 0 -0.3"/>
      <geometry name="leftHipPitchLink">
        <cylinder length="0.3" radius="0.03"/>
      </geometry>
    </collision>
  </link>
  <joint name="leftKneePitch" type="revolute">
    <axis xyz="0 1 0"/>
    <origin rpy="0 0 0" xyz="0 0 -0.3"/>
    <parent link="leftHipPitchLink"/>
    <child link="leftKneePitchLink"/>
    <dynamics damping="0.1"/>
    <limit effort="100" lower="-3.14" upper="3.14" velocity="1"/>
    <provide_feedback>true</provide_feedback>
  </joint>
  <link name="leftKneePitchLink">
    <inertial>
      <mass value="2.0"/>
      <origin xyz="-0.0 0 -0.15"/>
      <inertia ixx="0.01545" ixy="0" ixz="0" iyy="0.01545" iyz="0" izz="0.0009"/>
    </inertial>
    <visual>
      <origin rpy="0 0 0 " xyz="0 0 -0.15"/>
      <geometry name="leftKneePitchLink">
        <cylinder length="0.3" radius="0.03"/>
      </geometry>
      <material name="grey">
        <color rgba="0.627 0.627 0.627 1"/>
      </material>
    </visual>
    <collision>
      <origin rpy="0 0 0 " xyz="0 0 -0.15"/>
      <geometry name="leftKneePitchLink">
        <cylinder length="0.3" radius="0.03"/>
      </geometry>
    </collision>
  </link>
  <joint name="leftAnklePitch" type="revolute">
    <axis xyz="0 1 0"/>
    <origin rpy="0 0 0" xyz="0 0 -0.3"/>
    <parent link="leftKneePitchLink"/>
    <child link="leftAnklePitchLink"/>
    <dynamics damping="0.1"/>
    <limit effort="100" lower="-3.14" upper="3.14" velocity="1"/>
    <provide_feedback>true</provide_feedback>
  </joint>
  <link name="leftAnklePitchLink">
    <inertial>
      <mass value="3.0"/>
      <origin xyz="0.0 0.0 -0.015"/>
      <inertia ixx="0.00015" ixy="0" ixz="0" iyy="0.00015" iyz="0" izz="0.000225"/>
    </inertial>
    <visual>
      <origin rpy="1.507 0 0" xyz="0 0 -0.015"/>
      <geometry name="leftAnklePitchLink">
        <cylinder length="0.03" radius="0.03"/>
      </geometry>
      <material name="grey">
        <color rgba="0.627 0.627 0.627 1"/>
      </material>
    </visual>
    <collision>
      <origin rpy="0 0 0.0 " xyz="0 0 -0.015"/>
      <geometry name="leftAnklePitchLink">
        <cylinder length="0.03" radius="0.03"/>
      </geometry>
    </collision>
  </link>
  <joint name="leftAnkleRoll" type="revolute">
    <axis xyz="1 0 0"/>
    <origin rpy="0 0 0" xyz="0.025 0 -0.03"/>
    <parent link="leftAnklePitchLink"/>
    <child link="leftFoot"/>
    <dynamics damping="0.1"/>
    <limit effort="100" lower="-3.14" upper="3.14" velocity="1"/>
    <provide_feedback>true</provide_feedback>
  </joint>
  <link name="leftFoot">
    <inertial>
      <mass value="10"/>
      <origin xyz="0.03 0 -0.01"/>
      <inertia ixx="0.008667" ixy="0" ixz="0" iyy="0.008667" iyz="0" izz="0.01667"/>
    </inertial>
    <visual>
      <origin rpy="0 0 0 " xyz="0.0 0 -0.02"/>
      <geometry name="leftFoot">
        <box size="0.5 0.3 0.04"/>
      </geometry>
      <material name="grey">
        <color rgba="0.627 0.627 0.627 1"/>
      </material>
    </visual>
    <collision>
      <origin rpy="0 0 0 " xyz="0.0 0 -0.02"/>
      <geometry name="leftFoot">
        <box size="0.5 0.3 0.04"/>
      </geometry>
    </collision>
  </link>
  <!--RIGHT LEG-->
  <joint name="rightHipYaw" type="revolute">
    <axis xyz="0 0 1"/>
    <origin rpy="0 0 0" xyz="0 -0.2 0.0"/>
    <dynamics damping="0.1"/>
    <parent link="pelvis"/>
    <child link="rightHipYawLink"/>
    <limit effort="100" lower="-3.14" upper="3.14" velocity="1"/>
    <provide_feedback>true</provide_feedback>
  </joint>
  <link name="rightHipYawLink">
    <inertial>
      <mass value="2.0"/>
      <origin xyz="0.0 0.0 -0.015"/>
      <inertia ixx="0.00015" ixy="0" ixz="0" iyy="0.00015" iyz="0" izz="0.000225"/>
    </inertial>
    <visual>
      <origin rpy="0 1.507 0" xyz="0 0.0 -0.015"/>
      <geometry name="rightHipYawLink">
        <cylinder length="0.03" radius="0.03"/>
      </geometry>
      <material name="grey">
        <color rgba="0.627 0.627 0.627 1"/>
      </material>
    </visual>
    <collision>
      <origin rpy="1.507 0 0.0 " xyz="0 0.0 -0.015"/>
      <geometry name="rightHipYawLink">
        <cylinder length="0.03" radius="0.03"/>
      </geometry>
    </collision>
  </link>
  <joint name="rightHipRoll" type="revolute">
    <axis xyz="0 1 0"/>
    <origin rpy="0 0 0" xyz="0 0 -0.03"/>
    <dynamics damping="0.1"/>
    <parent link="rightHipYawLink"/>
    <child link="rightHipRollLink"/>
    <limit effort="100" lower="-3.14" upper="3.14" velocity="1"/>
    <provide_feedback>true</provide_feedback>
  </joint>
  <link name="rightHipRollLink">
    <inertial>
      <mass value="2.0"/>
      <origin xyz="0.0 0.0 -0.015"/>
      <inertia ixx="0.00015" ixy="0" ixz="0" iyy="0.00015" iyz="0" izz="0.000225"/>
    </inertial>
    <visual>
      <origin rpy="1.507 0 0" xyz="0 0 -0.015"/>
      <geometry name="rightHipRollLink">
        <cylinder length="0.03" radius="0.03"/>
      </geometry>
      <material name="grey">
        <color rgba="0.627 0.627 0.627 1"/>
      </material>
    </visual>
    <collision>
      <origin rpy="1.507 0 0.0 " xyz="0 0 -0.015"/>
      <geometry name="rightHipRollLink">
        <cylinder length="0.03" radius="0.03"/>
      </geometry>
    </collision>
  </link>
  <joint name="rightHipPitch" type="revolute">
    <axis xyz="1 0 0"/>
    <origin rpy="0 0 0" xyz="0 0 -0.03"/>
    <parent link="rightHipRollLink"/>
    <child link="rightHipPitchLink"/>
    <dynamics damping="0.1"/>
    <limit effort="100" lower="-3.14" upper="3.14" velocity="1"/>
    <provide_feedback>true</provide_feedback>
  </joint>
  <link name="rightHipPitchLink">
    <inertial>
      <mass value="2.0"/>
      <origin xyz="-0.0 0 -0.15"/>
      <inertia ixx="0.01545" ixy="0" ixz="0" iyy="0.01545" iyz="0" izz="0.0009"/>
    </inertial>
    <visual>
      <origin rpy="0 0 0 " xyz="0 0 -0.15"/>
      <geometry name="rightHipPitchLink">
        <cylinder length="0.3" radius="0.03"/>
      </geometry>
      <material name="grey">
        <color rgba="0.627 0.627 0.627 1"/>
      </material>
    </visual>
    <collision>
      <origin rpy="0 0 0 " xyz="0 0 -0.3"/>
      <geometry name="rightHipPitchLink">
        <cylinder length="0.3" radius="0.03"/>
      </geometry>
    </collision>
  </link>
  <joint name="rightKneePitch" type="revolute">
    <axis xyz="0 1 0"/>
    <origin rpy="0 0 0" xyz="0 0 -0.3"/>
    <parent link="rightHipPitchLink"/>
    <child link="rightKneePitchLink"/>
    <dynamics damping="0.1"/>
    <limit effort="100" lower="-3.14" upper="3.14" velocity="1"/>
    <provide_feedback>true</provide_feedback>
  </joint>
  <link name="rightKneePitchLink">
    <inertial>
      <mass value="2.0"/>
      <origin xyz="-0.0 0 -0.15"/>
      <inertia ixx="0.01545" ixy="0" ixz="0" iyy="0.01545" iyz="0" izz="0.0009"/>
    </inertial>
    <visual>
      <origin rpy="0 0 0 " xyz="0 0 -0.15"/>
      <geometry name="rightKneePitchLink">
        <cylinder length="0.3" radius="0.03"/>
      </geometry>
      <material name="grey">
        <color rgba="0.627 0.627 0.627 1"/>
      </material>
    </visual>
    <collision>
      <origin rpy="0 0 0 " xyz="0 0 -0.15"/>
      <geometry name="rightKneePitchLink">
        <cylinder length="0.3" radius="0.03"/>
      </geometry>
    </collision>
  </link>
  <joint name="rightAnklePitch" type="revolute">
    <axis xyz="0 1 0"/>
    <origin rpy="0 0 0" xyz="0 0 -0.3"/>
    <dynamics damping="0.1"/>
    <parent link="rightKneePitchLink"/>
    <child link="rightAnklePitchLink"/>
    <limit effort="100" lower="-3.14" upper="3.14" velocity="1"/>
    <provide_feedback>true</provide_feedback>
  </joint>
  <link name="rightAnklePitchLink">
    <inertial>
      <mass value="3.0"/>
      <origin xyz="0.0 0.0 -0.015"/>
      <inertia ixx="0.00015" ixy="0" ixz="0" iyy="0.00015" iyz="0" izz="0.000225"/>
    </inertial>
    <visual>
      <origin rpy="1.507 0 0" xyz="0 0 -0.015"/>
      <geometry name="rightAnklePitchLink">
        <cylinder length="0.03" radius="0.03"/>
      </geometry>
      <material name="grey">
        <color rgba="0.627 0.627 0.627 1"/>
      </material>
    </visual>
    <collision>
      <origin rpy="1.507 0 0" xyz="0 0 -0.015"/>
      <geometry name="rightAnklePitchLink">
        <cylinder length="0.03" radius="0.03"/>
      </geometry>
    </collision>
  </link>
  <joint name="rightAnkleRoll" type="revolute">
    <axis xyz="1 0 0"/>
    <origin rpy="0 0 0" xyz="0.025 0 -0.03"/>
    <parent link="rightAnklePitchLink"/>
    <child link="rightFoot"/>
    <dynamics damping="0.1"/>
    <limit effort="100" lower="-3.14" upper="3.14" velocity="1"/>
    <provide_feedback>true</provide_feedback>
  </joint>
  <link name="rightFoot">
    <inertial>
      <mass value="10"/>
      <origin xyz="0.03 0 -0.02"/>
      <inertia ixx="0.008667" ixy="0" ixz="0" iyy="0.008667" iyz="0" izz="0.01667"/>
    </inertial>
    <visual>
      <origin rpy="0 0 0 " xyz="0.0 0 -0.02"/>
      <geometry name="rightFoot">
        <box size="0.5 0.3 0.04"/>
      </geometry>
      <material name="grey">
        <color rgba="0.627 0.627 0.627 1"/>
      </material>
    </visual>
    <collision>
      <origin rpy="0 0 0 " xyz="0.0 0 -0.02"/>
      <geometry name="rightFoot">
        <box size="0.5 0.3 0.04"/>
      </geometry>
    </collision>
  </link>
  <joint name="torsoYaw" type="revolute">
    <axis xyz="0 0 1"/>
    <origin rpy="0 0 0" xyz="0.0 0.0 0.1"/>
    <dynamics damping="0.1"/>
    <parent link="pelvis"/>
    <child link="torsoYawLink"/>
    <limit effort="100" lower="-3.14" upper="3.14" velocity="10"/>
    <provide_feedback>true</provide_feedback>
  </joint>
  <link name="torsoYawLink">
    <inertial>
      <mass value="1.0"/>
      <origin xyz="0.0 0.0 0.125"/>
      <inertia ixx="0.028125" ixy="0" ixz="0" iyy="0.045" iyz="0" izz="0.028125"/>
    </inertial>
    <visual>
      <origin rpy="0.0 0.0 0.0" xyz="0.0 0.0 0.015"/>
      <geometry name="torsoYawLink">
        <cylinder length="0.03" radius="0.1"/>
      </geometry>
      <material name="grey">
        <color rgba="0.627 0.627 0.627 1"/>
      </material>
    </visual>
    <collision>
      <origin rpy="0.0 0.0 0.0" xyz="0.0 0.0 0.015"/>
      <geometry name="torsoYawLink">
        <cylinder length="0.03" radius="0.1"/>
      </geometry>
    </collision>
  </link>
  <joint name="torsoPitch" type="revolute">
    <axis xyz="0 1 0"/>
    <origin rpy="0 0 0" xyz="0.0 0.0 0.03"/>
    <dynamics damping="0.1"/>
    <parent link="torsoYawLink"/>
    <child link="torsoPitchLink"/>
    <limit effort="100" lower="-3.14" upper="3.14" velocity="10"/>
    <provide_feedback>true</provide_feedback>
  </joint>
  <link name="torsoPitchLink">
    <inertial>
      <mass value="2"/>
      <origin xyz="0.0 0.0 0.125"/>
      <inertia ixx="0.028125" ixy="0" ixz="0" iyy="0.045" iyz="0" izz="0.028125"/>
    </inertial>
    <visual>
      <origin rpy="0.0 0.0 0.0" xyz="0.0 0.0 0.125"/>
      <geometry name="torsoPitchLink">
        <box size="0.12 0.25 0.25"/>
      </geometry>
      <material name="grey">
        <color rgba="0.627 0.627 0.627 1"/>
      </material>
    </visual>
    <collision>
      <origin rpy="0.0 0.0 0.0" xyz="0.0 0.0 0.125"/>
      <geometry name="torsoPitchLink">
        <box size="0.12 0.25 0.25"/>
      </geometry>
    </collision>
  </link>
  <joint name="torsoRoll" type="revolute">
    <axis xyz="0 1 0"/>
    <origin rpy="0 0 0" xyz="0.0 0.0 0.25"/>
    <dynamics damping="0.1"/>
    <parent link="torsoPitchLink"/>
    <child link="chest"/>
    <limit effort="100" lower="-3.14" upper="3.14" velocity="10"/>
    <provide_feedback>true</provide_feedback>
  </joint>
  <link name="chest">
    <inertial>
      <mass value="2"/>
      <origin xyz="0.0 0.0 0.125"/>
      <inertia ixx="0.028125" ixy="0" ixz="0" iyy="0.045" iyz="0" izz="0.028125"/>
    </inertial>
    <visual>
      <origin rpy="0.0 0.0 0.0" xyz="0.0 0.0 0.125"/>
      <geometry name="chest">
        <box size="0.12 0.25 0.25"/>
      </geometry>
      <material name="grey">
        <color rgba="0.627 0.627 0.627 1"/>
      </material>
    </visual>
    <collision>
      <origin rpy="0.0 0.0 0.0" xyz="0.0 0.0 0.125"/>
      <geometry name="chest">
        <box size="0.12 0.25 0.25"/>
      </geometry>
    </collision>
  </link>
  <joint name="rightShoulderPitch" type="revolute">
    <axis xyz="0 1 0"/>
    <origin rpy="0 0 0" xyz="0.0 -0.125 0.22"/>
    <dynamics damping="0.1"/>
    <parent link="chest"/>
    <child link="rightShoulderPitchLink"/>
    <limit effort="100" lower="-3.14" upper="3.14" velocity="10"/>
    <provide_feedback>true</provide_feedback>
  </joint>
  <link name="rightShoulderPitchLink">
    <inertial>
      <mass value="1"/>
      <origin xyz="0.0 -0.01 0.0"/>
      <inertia ixx="0.028125" ixy="0" ixz="0" iyy="0.045" iyz="0" izz="0.028125"/>
    </inertial>
    <visual>
      <origin rpy="1.57 0.0 0.0" xyz="0.0 -0.01 0.0"/>
      <geometry name="rightShoulderPitchLink">
        <cylinder length="0.02" radius="0.06"/>
      </geometry>
      <material name="grey">
        <color rgba="0.627 0.627 0.627 1"/>
      </material>
    </visual>
    <collision>
      <origin rpy="1.57 0.0 0.0" xyz="0.0 -0.01 0.0"/>
      <geometry name="rightShoulderPitchLink">
        <cylinder length="0.02" radius="0.06"/>
      </geometry>
    </collision>
  </link>
  <joint name="rightShoulderRoll" type="revolute">
    <axis xyz="1 0 0"/>
    <origin rpy="0 0 0" xyz="0.0 -0.04 0.0"/>
    <dynamics damping="0.1"/>
    <parent link="rightShoulderPitchLink"/>
    <child link="rightShoulderRollLink"/>
    <limit effort="100" lower="-3.14" upper="3.14" velocity="10"/>
    <provide_feedback>true</provide_feedback>
  </joint>
  <link name="rightShoulderRollLink">
    <inertial>
      <mass value="1"/>
      <origin xyz="0.0 -0.02 0.0"/>
      <inertia ixx="0.028125" ixy="0" ixz="0" iyy="0.045" iyz="0" izz="0.028125"/>
    </inertial>
    <visual>
      <origin rpy="0.0 1.57 0.0" xyz="0.0 -0.02 0.0"/>
      <geometry name="rightShoulderRollLink">
        <cylinder length="0.1" radius="0.04"/>
      </geometry>
      <material name="grey">
        <color rgba="0.627 0.627 0.627 1"/>
      </material>
    </visual>
    <collision>
      <origin rpy="0.0 1.57 0.0" xyz="0.0 -0.02 0.0"/>
      <geometry name="rightShoulderRollLink">
        <cylinder length="0.1" radius="0.04"/>
      </geometry>
    </collision>
  </link>
  <joint name="rightShoulderYaw" type="revolute">
    <axis xyz="0 0 1"/>
    <origin rpy="0 0 0" xyz="0.0 -0.02 -0.02"/>
    <dynamics damping="0.1"/>
    <parent link="rightShoulderRollLink"/>
    <child link="rightShoulderYawLink"/>
    <limit effort="100" lower="-3.14" upper="3.14" velocity="10"/>
    <provide_feedback>true</provide_feedback>
  </joint>
  <link name="rightShoulderYawLink">
    <inertial>
      <mass value="2"/>
      <origin xyz="0.0 0.0 -0.1"/>
      <inertia ixx="0.028125" ixy="0" ixz="0" iyy="0.045" iyz="0" izz="0.028125"/>
    </inertial>
    <visual>
      <origin rpy="0.0 0.0 0.0" xyz="0.0 0.0 -0.1"/>
      <geometry name="rightShoulderYawLink">
        <cylinder length="0.2" radius="0.03"/>
      </geometry>
      <material name="grey">
        <color rgba="0.627 0.627 0.627 1"/>
      </material>
    </visual>
    <collision>
      <origin rpy="0.0 0.0 0.0" xyz="0.0 0.0 -0.1"/>
      <geometry name="rightShoulderYawLink">
        <cylinder length="0.2" radius="0.03"/>
      </geometry>
    </collision>
  </link>
  <joint name="rightElbowPitch" type="revolute">
    <axis xyz="0 1 0"/>
    <origin rpy="0 0 0" xyz="0.0 -0.0 -0.2"/>
    <dynamics damping="0.1"/>
    <parent link="rightShoulderYawLink"/>
    <child link="rightElbowPitchLink"/>
    <limit effort="100" lower="-3.14" upper="3.14" velocity="10"/>
    <provide_feedback>true</provide_feedback>
  </joint>
  <link name="rightElbowPitchLink">
    <inertial>
      <mass value="2"/>
      <origin xyz="0.0 0.0 -0.1"/>
      <inertia ixx="0.028125" ixy="0" ixz="0" iyy="0.045" iyz="0" izz="0.028125"/>
    </inertial>
    <visual>
      <origin rpy="0.0 0.0 0.0" xyz="0.0 0.0 -0.1"/>
      <geometry name="rightElbowPitchLink">
        <cylinder length="0.2" radius="0.03"/>
      </geometry>
      <material name="grey">
        <color rgba="0.627 0.627 0.627 1"/>
      </material>
    </visual>
    <collision>
      <origin rpy="0.0 0.0 0.0" xyz="0.0 0.0 -0.1"/>
      <geometry name="rightElbowPitchLink">
        <cylinder length="0.2" radius="0.03"/>
      </geometry>
    </collision>
  </link>
  <joint name="rightForearmYaw" type="revolute">
    <axis xyz="0 0 1"/>
    <origin rpy="0 0 0" xyz="0.0 -0.0 -0.2"/>
    <dynamics damping="0.1"/>
    <parent link="rightElbowPitchLink"/>
    <child link="rightForearmYawLink"/>
    <limit effort="100" lower="-3.14" upper="3.14" velocity="10"/>
    <provide_feedback>true</provide_feedback>
  </joint>
  <link name="rightForearmYawLink">
    <inertial>
      <mass value="2"/>
      <origin xyz="0.0 0.0 -0.02"/>
      <inertia ixx="0.028125" ixy="0" ixz="0" iyy="0.045" iyz="0" izz="0.028125"/>
    </inertial>
    <visual>
      <origin rpy="0.0 0.0 0.0" xyz="0.0 0.0 -0.02"/>
      <geometry name="rightForearmYawLink">
        <cylinder length="0.04" radius="0.03"/>
      </geometry>
      <material name="grey">
        <color rgba="0.627 0.627 0.627 1"/>
      </material>
    </visual>
    <collision>
      <origin rpy="0.0 0.0 0.0" xyz="0.0 0.0 -0.02"/>
      <geometry name="rightForearmYawLink">
        <cylinder length="0.04" radius="0.03"/>
      </geometry>
    </collision>
  </link>
  <joint name="rightWristRoll" type="revolute">
    <axis xyz="0 1 0"/>
    <origin rpy="0 0 0" xyz="0.0 -0.0 -0.02"/>
    <dynamics damping="0.1"/>
    <parent link="rightForearmYawLink"/>
    <child link="rightWristRollLink"/>
    <limit effort="100" lower="-3.14" upper="3.14" velocity="10"/>
    <provide_feedback>true</provide_feedback>
  </joint>
  <link name="rightWristRollLink">
    <inertial>
      <mass value="1"/>
      <origin xyz="0.0 0.0 -0.02"/>
      <inertia ixx="0.028125" ixy="0" ixz="0" iyy="0.045" iyz="0" izz="0.028125"/>
    </inertial>
    <visual>
      <origin rpy="1.57 0.0 0.0" xyz="0.0 0.0 -0.02"/>
      <geometry name="rightWristRollLink">
        <cylinder length="0.04" radius="0.03"/>
      </geometry>
      <material name="grey">
        <color rgba="0.627 0.627 0.627 1"/>
      </material>
    </visual>
    <collision>
      <origin rpy="1.57 0.0 0.0" xyz="0.0 0.0 -0.02"/>
      <geometry name="rightWristRollLink">
        <cylinder length="0.04" radius="0.03"/>
      </geometry>
    </collision>
  </link>
  <joint name="rightWristPitch" type="revolute">
    <axis xyz="0 1 0"/>
    <origin rpy="0 0 0" xyz="0.0 -0.0 -0.02"/>
    <dynamics damping="0.1"/>
    <parent link="rightWristRollLink"/>
    <child link="rightPalm"/>
    <limit effort="100" lower="-3.14" upper="3.14" velocity="10"/>
    <provide_feedback>true</provide_feedback>
  </joint>
  <link name="rightPalm">
    <inertial>
      <mass value="1"/>
      <origin xyz="0.0 0.0 -0.06"/>
      <inertia ixx="0.028125" ixy="0" ixz="0" iyy="0.045" iyz="0" izz="0.028125"/>
    </inertial>
    <visual>
      <origin rpy="0.0 0.0 0.0" xyz="0.0 0.0 -0.06"/>
      <geometry name="rightPalm">
        <box size="0.1 0.02 0.12"/>
      </geometry>
      <material name="grey">
        <color rgba="0.627 0.627 0.627 1"/>
      </material>
    </visual>
    <collision>
      <origin rpy="0.0 0.0 0.0" xyz="0.0 0.0 -0.06"/>
      <geometry name="rightPalm">
        <box size="0.1 0.02 0.12"/>
      </geometry>
    </collision>
  </link>
  <joint name="leftShoulderPitch" type="revolute">
    <axis xyz="0 1 0"/>
    <origin rpy="0 0 0" xyz="0.0 0.125 0.22"/>
    <dynamics damping="0.1"/>
    <parent link="chest"/>
    <child link="leftShoulderPitchLink"/>
    <limit effort="100" lower="-3.14" upper="3.14" velocity="10"/>
    <provide_feedback>true</provide_feedback>
  </joint>
  <link name="leftShoulderPitchLink">
    <inertial>
      <mass value="1"/>
      <origin xyz="0.0 0.01 0.0"/>
      <inertia ixx="0.028125" ixy="0" ixz="0" iyy="0.045" iyz="0" izz="0.028125"/>
    </inertial>
    <visual>
      <origin rpy="1.57 0.0 0.0" xyz="0.0 0.01 0.0"/>
      <geometry name="leftShoulderPitchLink">
        <cylinder length="0.02" radius="0.06"/>
      </geometry>
      <material name="grey">
        <color rgba="0.627 0.627 0.627 1"/>
      </material>
    </visual>
    <collision>
      <origin rpy="1.57 0.0 0.0" xyz="0.0 0.01 0.0"/>
      <geometry name="leftShoulderPitchLink">
        <cylinder length="0.02" radius="0.06"/>
      </geometry>
    </collision>
  </link>
  <joint name="leftShoulderRoll" type="revolute">
    <axis xyz="1 0 0"/>
    <origin rpy="0 0 0" xyz="0.0 0.04 0.0"/>
    <dynamics damping="0.1"/>
    <parent link="leftShoulderPitchLink"/>
    <child link="leftShoulderRollLink"/>
    <limit effort="100" lower="-3.14" upper="3.14" velocity="10"/>
    <provide_feedback>true</provide_feedback>
  </joint>
  <link name="leftShoulderRollLink">
    <inertial>
      <mass value="1"/>
      <origin xyz="0.0 0.02 0.0"/>
      <inertia ixx="0.028125" ixy="0" ixz="0" iyy="0.045" iyz="0" izz="0.028125"/>
    </inertial>
    <visual>
      <origin rpy="0.0 1.57 0.0" xyz="0.0 0.02 0.0"/>
      <geometry name="leftShoulderRollLink">
        <cylinder length="0.1" radius="0.04"/>
      </geometry>
      <material name="grey">
        <color rgba="0.627 0.627 0.627 1"/>
      </material>
    </visual>
    <collision>
      <origin rpy="0.0 1.57 0.0" xyz="0.0 0.02 0.0"/>
      <geometry name="leftShoulderRollLink">
        <cylinder length="0.1" radius="0.04"/>
      </geometry>
    </collision>
  </link>
  <joint name="leftShoulderYaw" type="revolute">
    <axis xyz="0 0 1"/>
    <origin rpy="0 0 0" xyz="0.0 0.02 -0.02"/>
    <dynamics damping="0.1"/>
    <parent link="leftShoulderRollLink"/>
    <child link="leftShoulderYawLink"/>
    <limit effort="100" lower="-3.14" upper="3.14" velocity="10"/>
    <provide_feedback>true</provide_feedback>
  </joint>
  <link name="leftShoulderYawLink">
    <inertial>
      <mass value="2"/>
      <origin xyz="0.0 0.0 -0.1"/>
      <inertia ixx="0.028125" ixy="0" ixz="0" iyy="0.045" iyz="0" izz="0.028125"/>
    </inertial>
    <visual>
      <origin rpy="0.0 0.0 0.0" xyz="0.0 0.0 -0.1"/>
      <geometry name="leftShoulderYawLink">
        <cylinder length="0.2" radius="0.03"/>
      </geometry>
      <material name="grey">
        <color rgba="0.627 0.627 0.627 1"/>
      </material>
    </visual>
    <collision>
      <origin rpy="0.0 0.0 0.0" xyz="0.0 0.0 -0.1"/>
      <geometry name="leftShoulderYawLink">
        <cylinder length="0.2" radius="0.03"/>
      </geometry>
    </collision>
  </link>
  <joint name="leftElbowPitch" type="revolute">
    <axis xyz="0 1 0"/>
    <origin rpy="0 0 0" xyz="0.0 -0.0 -0.2"/>
    <dynamics damping="0.1"/>
    <parent link="leftShoulderYawLink"/>
    <child link="leftElbowPitchLink"/>
    <limit effort="100" lower="-3.14" upper="3.14" velocity="10"/>
    <provide_feedback>true</provide_feedback>
  </joint>
  <link name="leftElbowPitchLink">
    <inertial>
      <mass value="2"/>
      <origin xyz="0.0 0.0 -0.1"/>
      <inertia ixx="0.028125" ixy="0" ixz="0" iyy="0.045" iyz="0" izz="0.028125"/>
    </inertial>
    <visual>
      <origin rpy="0.0 0.0 0.0" xyz="0.0 0.0 -0.1"/>
      <geometry name="leftElbowPitchLink">
        <cylinder length="0.2" radius="0.03"/>
      </geometry>
      <material name="grey">
        <color rgba="0.627 0.627 0.627 1"/>
      </material>
    </visual>
    <collision>
      <origin rpy="0.0 0.0 0.0" xyz="0.0 0.0 -0.1"/>
      <geometry name="leftElbowPitchLink">
        <cylinder length="0.2" radius="0.03"/>
      </geometry>
    </collision>
  </link>
  <joint name="leftForearmYaw" type="revolute">
    <axis xyz="0 0 1"/>
    <origin rpy="0 0 0" xyz="0.0 -0.0 -0.2"/>
    <dynamics damping="0.1"/>
    <parent link="leftElbowPitchLink"/>
    <child link="leftForearmYawLink"/>
    <limit effort="100" lower="-3.14" upper="3.14" velocity="10"/>
    <provide_feedback>true</provide_feedback>
  </joint>
  <link name="leftForearmYawLink">
    <inertial>
      <mass value="2"/>
      <origin xyz="0.0 0.0 -0.02"/>
      <inertia ixx="0.028125" ixy="0" ixz="0" iyy="0.045" iyz="0" izz="0.028125"/>
    </inertial>
    <visual>
      <origin rpy="0.0 0.0 0.0" xyz="0.0 0.0 -0.02"/>
      <geometry name="leftForearmYawLink">
        <cylinder length="0.04" radius="0.03"/>
      </geometry>
      <material name="grey">
        <color rgba="0.627 0.627 0.627 1"/>
      </material>
    </visual>
    <collision>
      <origin rpy="0.0 0.0 0.0" xyz="0.0 0.0 -0.02"/>
      <geometry name="leftForearmYawLink">
        <cylinder length="0.04" radius="0.03"/>
      </geometry>
    </collision>
  </link>
  <joint name="leftWristRoll" type="revolute">
    <axis xyz="0 1 0"/>
    <origin rpy="0 0 0" xyz="0.0 -0.0 -0.02"/>
    <dynamics damping="0.1"/>
    <parent link="leftForearmYawLink"/>
    <child link="leftWristRollLink"/>
    <limit effort="100" lower="-3.14" upper="3.14" velocity="10"/>
    <provide_feedback>true</provide_feedback>
  </joint>
  <link name="leftWristRollLink">
    <inertial>
      <mass value="1"/>
      <origin xyz="0.0 0.0 -0.02"/>
      <inertia ixx="0.028125" ixy="0" ixz="0" iyy="0.045" iyz="0" izz="0.028125"/>
    </inertial>
    <visual>
      <origin rpy="1.57 0.0 0.0" xyz="0.0 0.0 -0.02"/>
      <geometry name="leftWristRollLink">
        <cylinder length="0.04" radius="0.03"/>
      </geometry>
      <material name="grey">
        <color rgba="0.627 0.627 0.627 1"/>
      </material>
    </visual>
    <collision>
      <origin rpy="1.57 0.0 0.0" xyz="0.0 0.0 -0.02"/>
      <geometry name="leftWristRollLink">
        <cylinder length="0.04" radius="0.03"/>
      </geometry>
    </collision>
  </link>
  <joint name="leftWristPitch" type="revolute">
    <axis xyz="0 1 0"/>
    <origin rpy="0 0 0" xyz="0.0 -0.0 -0.02"/>
    <dynamics damping="0.1"/>
    <parent link="leftWristRollLink"/>
    <child link="leftPalm"/>
    <limit effort="100" lower="-3.14" upper="3.14" velocity="10"/>
    <provide_feedback>true</provide_feedback>
  </joint>
  <link name="leftPalm">
    <inertial>
      <mass value="1"/>
      <origin xyz="0.0 0.0 -0.06"/>
      <inertia ixx="0.028125" ixy="0" ixz="0" iyy="0.045" iyz="0" izz="0.028125"/>
    </inertial>
    <visual>
      <origin rpy="0.0 0.0 0.0" xyz="0.0 0.0 -0.06"/>
      <geometry name="leftPalm">
        <box size="0.1 0.02 0.12"/>
      </geometry>
      <material name="grey">
        <color rgba="0.627 0.627 0.627 1"/>
      </material>
    </visual>
    <collision>
      <origin rpy="0.0 0.0 0.0" xyz="0.0 0.0 -0.06"/>
      <geometry name="leftPalm">
        <box size="0.1 0.02 0.12"/>
      </geometry>
    </collision>
  </link>
  <joint name="neckYaw" type="revolute">
    <axis xyz="0 0 1"/>
    <origin rpy="0 0 0" xyz="0.0 -0.0 0.25"/>
    <dynamics damping="0.1"/>
    <parent link="chest"/>
    <child link="neckYawLink"/>
    <limit effort="100" lower="-3.14" upper="3.14" velocity="10"/>
    <provide_feedback>true</provide_feedback>
  </joint>
  <link name="neckYawLink">
    <inertial>
      <mass value="0.5"/>
      <origin xyz="0.0 0.0 0.01"/>
      <inertia ixx="0.0028125" ixy="0" ixz="0" iyy="0.0045" iyz="0" izz="0.0028125"/>
    </inertial>
    <visual>
      <origin rpy="0.0 0.0 0.0" xyz="0.0 0.0 0.0"/>
      <geometry name="neckYawLink">
        <cylinder length="0.04" radius="0.03"/>
      </geometry>
      <material name="grey">
        <color rgba="0.627 0.627 0.627 1"/>
      </material>
    </visual>
    <collision>
      <origin rpy="0.0 0.0 0.0" xyz="0.0 0.0 0.0"/>
      <geometry name="neckYawLink">
        <cylinder length="0.04" radius="0.03"/>
      </geometry>
    </collision>
  </link>
  <joint name="neckRoll" type="revolute">
    <axis xyz="0 1 0"/>
    <origin rpy="0 0 0" xyz="0.0 -0.0 0.02"/>
    <dynamics damping="0.1"/>
    <parent link="neckYawLink"/>
    <child link="neckRollLink"/>
    <limit effort="100" lower="-3.14" upper="3.14" velocity="10"/>
    <provide_feedback>true</provide_feedback>
  </joint>
  <link name="neckRollLink">
    <inertial>
      <mass value="0.5"/>
      <origin xyz="0.0 0.0 0.01"/>
      <inertia ixx="0.0028125" ixy="0" ixz="0" iyy="0.0045" iyz="0" izz="0.0028125"/>
    </inertial>
    <visual>
      <origin rpy="1.57 0.0 0.0" xyz="0.0 0.0 0.01"/>
      <geometry name="neckRollLink">
        <cylinder length="0.04" radius="0.03"/>
      </geometry>
      <material name="grey">
        <color rgba="0.627 0.627 0.627 1"/>
      </material>
    </visual>
    <collision>
      <origin rpy="1.57 0.0 0.0" xyz="0.0 0.0 0.01"/>
      <geometry name="neckRollLink">
        <cylinder length="0.04" radius="0.03"/>
      </geometry>
    </collision>
  </link>
  <joint name="neckPitch" type="revolute">
    <axis xyz="1 0 0"/>
    <origin rpy="0 0 0" xyz="0.0 -0.0 0.02"/>
    <dynamics damping="0.1"/>
    <parent link="neckRollLink"/>
    <child link="neckPitchLink"/>
    <limit effort="100" lower="-3.14" upper="3.14" velocity="10"/>
    <provide_feedback>true</provide_feedback>
  </joint>
  <link name="neckPitchLink">
    <inertial>
      <mass value="0.5"/>
      <origin xyz="0.0 0.0 0.01"/>
      <inertia ixx="0.0028125" ixy="0" ixz="0" iyy="0.0045" iyz="0" izz="0.0028125"/>
    </inertial>
    <visual>
      <origin rpy="0.0 1.57 0.0" xyz="0.0 0.0 0.01"/>
      <geometry name="neckPitchLink">
        <cylinder length="0.04" radius="0.03"/>
      </geometry>
      <material name="grey">
        <color rgba="0.627 0.627 0.627 1"/>
      </material>
    </visual>
    <collision>
      <origin rpy="0.0 1.57 0.0" xyz="0.0 0.0 0.01"/>
      <geometry name="neckPitchLink">
        <cylinder length="0.04" radius="0.03"/>
      </geometry>
    </collision>
  </link>
  <gazebo reference="leftHipYaw">
    <provideFeedback value="true"/>
  </gazebo>
  <gazebo reference="leftHipRoll">
    <provideFeedback value="true"/>
  </gazebo>
  <gazebo reference="leftHipPitch">
    <provideFeedback value="true"/>
  </gazebo>
  <gazebo reference="leftKneePitch">
    <provideFeedback value="true"/>
  </gazebo>
  <gazebo reference="leftAnklePitch">
    <provideFeedback value="true"/>
  </gazebo>
  <gazebo reference="leftAnkleRoll">
    <provideFeedback value="true"/>
  </gazebo>
  <gazebo reference="rightHipYaw">
    <provideFeedback value="true"/>
  </gazebo>
  <gazebo reference="rightHipRoll">
    <provideFeedback value="true"/>
  </gazebo>
  <gazebo reference="rightHipPitch">
    <provideFeedback value="true"/>
  </gazebo>
  <gazebo reference="rightKneePitch">
    <provideFeedback value="true"/>
  </gazebo>
  <gazebo reference="rightAnklePitch">
    <provideFeedback value="true"/>
  </gazebo>
  <gazebo reference="rightAnkleRoll">
    <provideFeedback value="true"/>
  </gazebo>
  <gazebo reference="torsoYaw">
    <provideFeedback value="true"/>
  </gazebo>
  <gazebo reference="torsoPitch">
    <provideFeedback value="true"/>
  </gazebo>
  <gazebo reference="torsoRoll">
    <provideFeedback value="true"/>
  </gazebo>
  <gazebo reference="leftShoulderPitch">
    <provideFeedback value="true"/>
  </gazebo>
  <gazebo reference="leftShoulderRoll">
    <provideFeedback value="true"/>
  </gazebo>
  <gazebo reference="leftShoulderYaw">
    <provideFeedback value="true"/>
  </gazebo>
  <gazebo reference="leftElbowPitch">
    <provideFeedback value="true"/>
  </gazebo>
  <gazebo reference="leftForearmYaw">
    <provideFeedback value="true"/>
  </gazebo>
  <gazebo reference="leftWristRoll">
    <provideFeedback value="true"/>
  </gazebo>
  <gazebo reference="leftWristPitch">
    <provideFeedback value="true"/>
  </gazebo>
  <gazebo reference="neckYaw">
    <provideFeedback value="true"/>
  </gazebo>
  <gazebo reference="neckRoll">
    <provideFeedback value="true"/>
  </gazebo>
  <gazebo reference="neckPitch">
    <provideFeedback value="true"/>
  </gazebo>
  <gazebo reference="rightShoulderPitch">
    <provideFeedback value="true"/>
  </gazebo>
  <gazebo reference="rightShoulderRoll">
    <provideFeedback value="true"/>
  </gazebo>
  <gazebo reference="rightShoulderYaw">
    <provideFeedback value="true"/>
  </gazebo>
  <gazebo reference="rightElbowPitch">
    <provideFeedback value="true"/>
  </gazebo>
  <gazebo reference="rightForearmYaw">
    <provideFeedback value="true"/>
  </gazebo>
  <gazebo reference="rightWristRoll">
    <provideFeedback value="true"/>
  </gazebo>
  <gazebo reference="rightWristPitch">
    <provideFeedback value="true"/>
  </gazebo>
  <gazebo reference="leftAnkleRoll">
    <sensor name="leftFootSixAxis" type="force_torque">
      <pose>0.0215646 0.0 -0.051054 3.14 0.0 0.0</pose>
      <!--sensor_number id="FT001SIM"/>
      <node id="/sensors/leftFootSixAxis"/>
      <api name="TurbodriverForceTorqueSensor"/-->
      <always_on>true</always_on>
      <update_rate>1000</update_rate>
      <force_torque>
        <frame>sensor</frame>
      </force_torque>
    </sensor>
  </gazebo>
  <gazebo reference="pelvis">
    <sensor name="pelvisMiddleImu" type="imu">
      <always_on>true</always_on>
      <pose>0 0 0 0 0 0 </pose>
      <!--node name="/sensors/middlePelvisIMU"/>
      <api name="val_imu_gazebo_interface/ImuGazeboInterface"/>
      <port name="none"/-->
      <imu>
        <noise>
          <type>gaussian</type>
          <rate>
            <mean>0</mean>
            <stddev>0.0002</stddev>
            <bias_mean>7.5e-06</bias_mean>
            <bias_stddev>8e-07</bias_stddev>
          </rate>
          <accel>
            <mean>0</mean>
            <stddev>0.017</stddev>
            <bias_mean>0.1</bias_mean>
            <bias_stddev>0.001</bias_stddev>
          </accel>
        </noise>
      </imu>
    </sensor>
  </gazebo>
  <gazebo>
    <plugin filename="libgazebo_ros_imu.so" name="imu_plugin_ros">
      <alwaysOn>true</alwaysOn>
      <bodyName>pelvis</bodyName>
      <topicName>pelvisMiddleImu/imu</topicName>
      <serviceName>pelvisMiddleImu/imu_service</serviceName>
      <gaussianNoise>0.0</gaussianNoise>
      <updateRate>1000.0</updateRate>
    </plugin>
  </gazebo>
  <gazebo reference="rightAnkleRoll">
    <sensor name="rightFootSixAxis" type="force_torque">
      <pose>0.0215646 0.0 -0.051054 3.14 0.0 0.0</pose>
      <!--sensor_number id="FT001SIM"/>
      <node id="/sensors/rightFootSixAxis"/>
      <api name="TurbodriverForceTorqueSensor"/-->
      <always_on>true</always_on>
      <update_rate>1000</update_rate>
      <force_torque>
        <frame>sensor</frame>
      </force_torque>
    </sensor>
  </gazebo>
  <gazebo version="1.2">
    <!-- <plugin filename="libRAPidPlugin.so" name="RAPid_plugin"/> -->
    <plugin filename="libSMControlPlugin.so" name="SMControlPlugin">
      <node>/sm_control_plugin</node>
    </plugin>
    <!-- The following plugin provides ground truth odometry -->
    <!-- <plugin name="pos_plugin_ros" filename="libgazebo_ros_p3d.so">
            <alwaysOn>true</alwaysOn>
            <updateRate>1000.0</updateRate>
            <bodyName>pelvis</bodyName>
            <topicName>/stickbot_humanoid_32dof_controller/pose</topicName>
            <frameName>world</frameName>
            <rpyOffset>0 0 0</rpyOffset>
            <xyzOffset>0 0 0</xyzOffset>
        </plugin> -->
  </gazebo>
</robot>
