<sdf version='1.4'>
  <model name='bono'>
  <pose>0 0 0.94 0 0 0</pose>
    <link name='pelvis'>
      <pose>0 0 0 0 0 0</pose>
<!-- No Hip X Springs
      <inertial>
		<pose>-0.05039 -0.00002 0.11723 0 0 0</pose>
        <mass>12.547</mass>
        <inertia>
          <ixx> 0.15688</ixx>
          <ixy> 0.00002</ixy>
          <ixz>-0.01993</ixz>
          <iyy> 0.11185</iyy>
          <iyz> 0.00005</iyz>
          <izz> 0.16107</izz>
        </inertia>
      </inertial>
 -->
<!-- Includes Hip X Springs  -->
      <inertial>
        <pose>-0.05399 -0.00002 0.11154 0 0 0</pose>
        <mass>13.10583</mass>
        <inertia>
          <ixx> 0.16763</ixx>
          <ixy> 0.00002</ixy>
          <ixz>-0.02529</ixz>
          <iyy> 0.12404</iyy>
          <iyz> 0.00005</iyz>
          <izz> 0.16643</izz>
        </inertia>
      </inertial>

      <collision name='pelvis_collision'>
        <pose>0 0 0 0 -0 0</pose>
        <geometry>
          <mesh>
            <scale>1 1 1</scale>
            <uri>model://bono/meshes/pelvis.STL</uri>
          </mesh>
        </geometry>
      </collision>
      <visual name='pelvis_visual'>
       <material>
        	<lighting>1</lighting>
        	<ambient>0.1 .1 .1 1</ambient>
        	<diffuse>.7 .7 .7 1</diffuse>
        	<specular>1 1 1 1</specular>
        	<emmisive>0 0 1 1</emmisive>
        </material>
        <pose>0 0 0 0 -0 0</pose>
        <geometry>
          <mesh>
            <scale>1 1 1</scale>
            <uri>model://bono/meshes/pelvis.STL</uri>
          </mesh>
        </geometry>
      </visual>
      <velocity_decay>
        <linear>0</linear>
        <angular>0</angular>
      </velocity_decay>
        <sensor name='pelvisIMU' type='imu'>
            <always_on>1</always_on>
            <update_rate>1000</update_rate>
            <imu>
                <noise>
                    <type>gaussian</type>
                    <rate>
                        <mean>0</mean>
                        <stddev>0.0002</stddev>
                        <bias_mean>7.5e-06</bias_mean>
                        <bias_stddev>8e-07</bias_stddev>
                    </rate>
                    <accel>
                        <mean>0</mean>
                        <stddev>0.017</stddev>
                        <bias_mean>0.1</bias_mean>
                        <bias_stddev>0.001</bias_stddev>
                    </accel>
                </noise>
            </imu>
            <pose>-0.0937 0.0 -0.0334 0 0.030 0</pose>
            <!--<pose>0.1330 0.0 0.0478 0 0 0</pose>-->
        </sensor>
    </link>
    <link name='ltorso'>
      <pose>0.018243 0.0 0.188773 0.0 0.0 0.0</pose>
      <inertial>
        <pose>0.00926195 0.00268847 5.32617e-06 0 -0 0</pose>
        <mass>2.24099</mass>
        <inertia>
          <ixx> 0.00408432</ixx>
          <ixy> 5.5226e-05</ixy>
          <ixz>-8.55028e-08</ixz>
          <iyy> 0.00280804</iyy>
          <iyz> 3.96734e-07</iyz>
          <izz> 0.00507952</izz>
        </inertia>
      </inertial>
      <collision name='ltorso_collision'>
        <pose>0 0 0 0 -0 0</pose>
        <geometry>
          <mesh>
            <scale>1 1 1</scale>
            <uri>model://bono/meshes/ltorso.STL</uri>
          </mesh>
        </geometry>
      </collision>
      <visual name='ltorso_visual'>
        <pose>0 0 0 0 -0 0</pose>
                <material>
        	<lighting>1</lighting>
        	<ambient>0.2 0 0 1</ambient>
        	<diffuse>.9 0 0 1</diffuse>
        	<specular>1 1 1 1</specular>
        	<emmisive>0 0 1 1</emmisive>
        </material>
        <geometry>
          <mesh>
            <scale>1 1 1</scale>
            <uri>model://bono/meshes/ltorso.STL</uri>
          </mesh>
        </geometry>
      </visual>
      <velocity_decay>
        <linear>0</linear>
        <angular>0</angular>
      </velocity_decay>
    </link>
    <joint name='back_lbx' type='revolute'>
      <child>ltorso</child>
      <parent>pelvis</parent>
      <axis>
        <xyz>1 0 0</xyz>
        <limit>
          <lower>-0.349</lower>
          <upper>0.349</upper>
          <effort>245</effort>
          <velocity>1.95</velocity>
        </limit>
        <dynamics>
          <damping>0.2</damping>
        </dynamics>
      </axis>
    </joint>
    <link name='mtorso'>
      <pose>0.018243 0.0 0.188773 0.0 0.0 0.0</pose>
      <inertial>
        <pose>0.01217 0.00088 0.10677 0 -0 0</pose>
        <mass>3.79010</mass>
        <inertia>
          <ixx> 0.02319</ixx>
          <ixy>-0.00012</ixy>
          <ixz>-0.00028</ixz>
          <iyy> 0.02609</iyy>
          <iyz> 0.00059</iyz>
          <izz> 0.03551</izz>
        </inertia>
      </inertial>
      <collision name='mtorso_collision'>
        <pose>0 0 0 0 -0 0</pose>
        <geometry>
          <mesh>
            <scale>1 1 1</scale>
            <uri>model://bono/meshes/mtorso.STL</uri>
          </mesh>
        </geometry>
      </collision>
      <visual name='mtorso_visual'>
              <material>
        	<lighting>1</lighting>
        	<ambient>0.2 .1 .1 1</ambient>
        	<diffuse>0.9 0.1 0.1 1</diffuse>
        	<specular>1 1 1 1</specular>
        	<emmisive>0 0 1 1</emmisive>
        </material>
        <pose>0 0 0 0 -0 0</pose>
        <geometry>
          <mesh>
            <scale>1 1 1</scale>
            <uri>model://bono/meshes/mtorso.STL</uri>
          </mesh>
        </geometry>
      </visual>
      <velocity_decay>
        <linear>0</linear>
        <angular>0</angular>
      </velocity_decay>
    </link>
    <joint name='back_mby' type='revolute'>
      <child>mtorso</child>
      <parent>ltorso</parent>
      <axis>
        <xyz>1.56265e-16 1 -6.8231e-17</xyz>
        <limit>
          <lower>-0.5236</lower>
          <upper>0.5236</upper>
          <effort>245</effort>
          <velocity>1.75</velocity>
        </limit>
        <dynamics>
          <damping>0.5</damping>
        </dynamics>
      </axis>
    </joint>
    <link name='utorso'>
      <pose>0.018243 0.0 0.188773 0.0 0.0 0.0</pose>
<!-- Wanderer Style Torso -->
      <inertial>
        <pose> 0.004656 0.003641 0.392397 0 -0 0</pose>
        <mass>26.260992</mass>
        <inertia>
          <ixx> 0.516466</ixx>
          <ixy> 0.003142</ixy>
          <ixz>-0.004028</ixz>
          <iyy> 0.235936</iyy>
          <iyz>-0.003012</iyz>
          <izz> 0.405404</izz>
        </inertia>
      </inertial>
<!-- Inertial pose with mass shifted by 0.02 in Y -->
<!-- With dummy mass  original sdf said 18.9 added 2.2kg to accomodate full robot mass
       <inertial>
        <pose>-0.0195224 0.020144025 0.313439 0 -0 0</pose>
        <mass>21.14268</mass>
        <inertia>
          <ixx> 0.272494</ixx>
          <ixy> 0.000779065</ixy>
          <ixz>-0.00449641</ixz>
          <iyy> 0.208064</iyy>
          <iyz> 0.000902029</iyz>
          <izz> 0.190387</izz>
        </inertia>
      </inertial>
 -->
<!-- without dummy mass original sdf said 7.00027 added 2.2kg to accomodate full robot mass
      <inertial>
        <pose>-0.02033 0.00039 0.35741 0 -0 0</pose>
        <mass>9.20327</mass> 
        <inertia>
          <ixx> 0.18685</ixx>
          <ixy> 0.00078</ixy>
          <ixz>-0.00489</ixz>
          <iyy> 0.14316</iyy>
          <iyz> 0.00102</iyz>
          <izz> 0.12898</izz>
        </inertia>
      </inertial>
-->
      <collision name='utorso_collision'>
        <pose>0 0 0 0 -0 0</pose>
        <geometry>
          <mesh>
            <scale>1 1 1</scale>
            <uri>model://bono/meshes/utorso.STL</uri>
          </mesh>
        </geometry>
      </collision>
      <visual name='utorso_visual'>
              <material>
        	<lighting>1</lighting>
        	<ambient>0.1 .1 .1 1</ambient>
        	<diffuse>.7 .7 .7 1</diffuse>
        	<specular>1 1 1 1</specular>
        	<emmisive>0 0 1 1</emmisive>
        </material>
        <pose>0 0 0 0 -0 0</pose>
        <geometry>
          <mesh>
            <scale>1 1 1</scale>
            <uri>model://bono/meshes/utorso.STL</uri>
          </mesh>
        </geometry>
      </visual>
      <velocity_decay>
        <linear>0</linear>
        <angular>0</angular>
      </velocity_decay>
    </link>
    <joint name='back_ubz' type='revolute'>
      <child>utorso</child>
      <parent>mtorso</parent>
      <axis>
        <xyz>-5.9757e-17 -1.18277e-15 1</xyz>
        <limit>
          <lower>-0.38</lower>
          <upper>0.38</upper>
          <effort>245</effort>
          <velocity>2.45</velocity>
        </limit>
        <dynamics>
          <damping>0.3</damping>
        </dynamics>
      </axis>
    </joint>
   <link name='l_uglut'>
      <pose>0.0 0.13335 0.0 0 0 0</pose>
      <inertial>
        <pose>0.02362 -0.02580 0.05229 0 -0 0</pose>
        <mass>2.98263</mass>
        <inertia>
          <ixx> 0.00823</ixx>
          <ixy> 0.00277</ixy>
          <ixz>-0.00358</ixz>
          <iyy> 0.02049</iyy>
          <iyz> 0.00175</iyz>
          <izz> 0.01812</izz>
        </inertia>
      </inertial>
      <collision name='l_uglut_collision'>
        <pose>0 0 0 0 -0 0</pose>
        <geometry>
          <mesh>
            <scale>1 1 1</scale>
            <uri>model://bono/meshes/l_uglut.STL</uri>
          </mesh>
        </geometry>
      </collision>
      <visual name='l_uglut_visual'>
              <material>
        	<lighting>1</lighting>
        	<ambient>0 0 0.2 1</ambient>
        	<diffuse>0 0.3 1 1</diffuse>
        	<specular>1 1 1 1</specular>
        	<emmisive>0 0 1 1</emmisive>
        </material>
        <pose>0 0 0 0 -0 0</pose>
        <geometry>
          <mesh>
            <scale>1 1 1</scale>
            <uri>model://bono/meshes/l_uglut.STL</uri>
          </mesh>
        </geometry>
      </visual>
      <velocity_decay>
        <linear>0</linear>
        <angular>0</angular>
      </velocity_decay>
    </link>
    <joint name='l_leg_mhx' type='revolute'>
      <child>l_uglut</child>
      <parent>pelvis</parent>
      <axis>
        <xyz>1 0 0</xyz>
        <limit>
          <lower>-0.314</lower>
          <upper>0.384</upper>
          <effort>245</effort>
          <velocity>4</velocity>
        </limit>
        <dynamics>
          <damping>0.18</damping>
        </dynamics>
      </axis>
    </joint>
    <link name='l_lglut'>
      <pose>0.0 0.13335 0.0 0 0 0</pose>
      <inertial>
        <pose>0.04859 0.06369 0.02393 0 -0 0</pose>
        <mass>4.77890</mass>
        <inertia>
          <ixx> 0.02521</ixx>
          <ixy>-0.00416</ixy>
          <ixz>-0.00452</ixz>
          <iyy> 0.02511</iyy>
          <iyz>-0.00551</iyz>
          <izz> 0.01786</izz>
        </inertia>
      </inertial>
      <collision name='l_lglut_collision'>
        <pose>0 0 0 0 -0 0</pose>
        <geometry>
          <mesh>
            <scale>1 1 1</scale>
            <uri>model://bono/meshes/l_lglut.STL</uri>
          </mesh>
        </geometry>
      </collision>
      <visual name='l_lglut_visual'>
              <material>
        	<lighting>1</lighting>
        	<ambient>0 0.2 0.4 1</ambient>
        	<diffuse>0 0.5 1 1</diffuse>
        	<specular>1 1 1 1</specular>
        	<emmisive>0 0 1 1</emmisive>
        </material>
        <pose>0 0 0 0 -0 0</pose>
        <geometry>
          <mesh>
            <scale>1 1 1</scale>
            <uri>model://bono/meshes/l_lglut.STL</uri>
          </mesh>
        </geometry>
      </visual>
      <velocity_decay>
        <linear>0</linear>
        <angular>0</angular>
      </velocity_decay>
    </link>
    <joint name='l_leg_uhz' type='revolute'>
      <child>l_lglut</child>
      <parent>l_uglut</parent>
      <axis>
        <xyz>0 0 1</xyz>
        <limit>
          <lower>-0.262</lower>
          <upper>0.523</upper>
          <effort>63</effort>
          <velocity>26</velocity>
        </limit>
        <dynamics>
          <damping>0.04</damping>
        </dynamics>
      </axis>
    </joint>
    <link name='l_uleg'>
      <pose>0.0 0.146158 -0.085547 0 0 0</pose>
<!-- Original Upper Leg
      <inertial>
        <pose>-0.02 0.0525 -0.218 0 -0 0</pose>
        <mass>7.76096</mass>
        <inertia>
          <ixx> 0.13628</ixx>
          <ixy> 0.00235</ixy>
          <ixz> 0.00075</ixz>
          <iyy> 0.11781</iyy>
          <iyz>-0.02074</iyz>
          <izz> 0.04658</izz>
        </inertia>
      </inertial>
-->
<!-- Four bar Upper Leg -->
      <inertial>
        <pose>-0.00347 0.03300 -0.16049 0 -0 0</pose>
        <mass>9.20765</mass>
        <inertia>
          <ixx> 0.16930</ixx>
          <ixy> 0.00601</ixy>
          <ixz> 0.00367</ixz>
          <iyy> 0.13914</iyy>
          <iyz>-0.03211</iyz>
          <izz> 0.08115</izz>
        </inertia>
      </inertial>
      
      <collision name='l_uleg_collision'>
        <pose>0 0 0 0 -0 0</pose>
        <geometry>
          <mesh>
            <scale>1 1 1</scale>
            <uri>model://bono/meshes/l_uleg.STL</uri>
          </mesh>
        </geometry>
      </collision>
      <visual name='l_uleg_visual'>
        <pose>0 0 0 0 -0 0</pose>
        <material>
        	<lighting>1</lighting>
        	<ambient>0 0 0.2 1</ambient>
        	<diffuse>0 0.3 1 1</diffuse>
        	<specular>1 1 1 1</specular>
        	<emmisive>0 0 1 1</emmisive>
        </material>
        <geometry>
          <mesh>
            <scale>1 1 1</scale>
            <uri>model://bono/meshes/l_uleg.STL</uri>
          </mesh>
        </geometry>
      </visual>
      <velocity_decay>
        <linear>0</linear>
        <angular>0</angular>
      </velocity_decay>
    </link>
    <joint name='l_leg_lhy' type='revolute'>
      <child>l_uleg</child>
      <parent>l_lglut</parent>
      <axis>
        <xyz>0 1 0</xyz>
        <limit>
          <lower>-1.57</lower>
          <upper>0.5236</upper>
          <effort>440</effort>
          <velocity>10</velocity>
        </limit>
        <dynamics>
          <damping>0.11</damping>
        </dynamics>
      </axis>
    </joint>
<!--   <link name='l_lleg'>
      <pose>0.0 0.146158 -0.462483 0 0 0</pose>
      <inertial>
        <pose>0.000904604 0.000444278 -0.0416523 0 -0 0</pose>
        <mass>7.62761</mass>
        <inertia>
          <ixx> 0.0812169</ixx>
          <ixy> 0.000202599</ixy>
          <ixz>-0.000156903</ixz>
          <iyy> 0.0816633</iyy>
          <iyz> 0.000291382</iyz>
          <izz> 0.0199188</izz>
        </inertia>
      </inertial>
      <collision name='l_lleg_collision'>
        <pose>0 0 0 0 -0 0</pose>
        <geometry>
          <mesh>
            <scale>1 1 1</scale>
            <uri>model://bono/meshes/l_lleg.STL</uri>
          </mesh>
        </geometry>
      </collision>
      <visual name='l_lleg_visual'>
        <pose>0 0 0 0 -0 0</pose>
        <geometry>
          <mesh>
            <scale>1 1 1</scale>
            <uri>model://bono/meshes/l_lleg.STL</uri>
          </mesh>
        </geometry>
      </visual>
      <velocity_decay>
        <linear>0</linear>
        <angular>0</angular>
      </velocity_decay>
    </link> 
-->
   <link name='l_lleg'>
      <pose>0.0 0.146158 -0.462483 0 0 0</pose>
<!-- Original Ankle
      <inertial>
        <pose>0.013 -0.02 -0.06 0 -0 0</pose>
        <mass>8.89814</mass>
        <inertia>
          <ixx> 0.11869</ixx>
          <ixy> 0.00024</ixy>
          <ixz> 0.01144</ixz>
          <iyy> 0.11709</iyy>
          <iyz> 0.00037</iyz>
          <izz> 0.03899</izz>
        </inertia>
      </inertial>
-->
<!-- Spring Ankle -->   
	  <inertial>
        <pose>0.00860 0.00029 -0.07339 0 -0 0</pose>
        <mass>9.55521</mass>
        <inertia>
          <ixx> 0.16306</ixx>
          <ixy> 0.00012</ixy>
          <ixz> 0.01196</ixz>
          <iyy> 0.15894</iyy>
          <iyz> 0.00035</iyz>
          <izz> 0.04292</izz>
        </inertia>
      </inertial>

      <collision name='l_lleg_collision'>
        <pose>0 0 0 0 -0 0</pose>
        <geometry>
          <mesh>
            <scale>1 1 1</scale>
            <uri>model://bono/meshes/l_lleg.STL</uri>
          </mesh>
        </geometry>
      </collision>
      <collision name='l_lleg_collision_ll_ankle_pulley'>
        <pose>0 0.099055 -0.0889 -8.6023e-17 0.01726 -8.8988e-17</pose>
        <geometry>
          <mesh>
            <scale>1 1 1</scale>
            <uri>model://bono/meshes/ll_ankle_pulley.STL</uri>
          </mesh>
        </geometry>
      </collision>
<!--
      <collision name='l_lleg_collision_ll_push_rod'>
        <pose>0.12698 0.0990431 -0.0911503 -0.142494 -0.12679 0.00378958</pose>
        <geometry>
          <mesh>
            <scale>1 1 1</scale>
            <uri>model://bono/meshes/ll_push_rod.STL</uri>
          </mesh>
        </geometry>
      </collision>  
-->
      <collision name='l_lleg_collision_lr_ankle_pulley'>
        <pose>0 -0.09876 -0.0889 -8.6154e-17 0.018311 -8.9078e-17</pose>
        <geometry>
          <mesh>
            <scale>1 1 1</scale>
            <uri>model://bono/meshes/lr_ankle_pulley.STL</uri>
          </mesh>
        </geometry>
      </collision>
<!--
      <collision name='l_lleg_collision_lr_push_rod'>
        <pose>0.126978 -0.0987481 -0.0912838 0.165806 -0.0983264 -0.186284</pose>
        <geometry>
          <mesh>
            <scale>1 1 1</scale>
            <uri>model://bono/meshes/lr_push_rod.STL</uri>
          </mesh>
        </geometry>
      </collision>
-->
      <visual name='l_lleg_visual'>
        <pose>0 0 0 0 -0 0</pose>
        <material>
        	<lighting>1</lighting>
        	<ambient>0 0.2 0.4 1</ambient>
        	<diffuse>0 0.5 1 1</diffuse>
        	<specular>1 1 1 1</specular>
        	<emmisive>0 0 1 1</emmisive>
        </material>
        <geometry>
          <mesh>
            <scale>1 1 1</scale>
            <uri>model://bono/meshes/l_lleg.STL</uri>
          </mesh>
        </geometry>
      </visual>
      <visual name='l_lleg_visual_ll_ankle_pulley'>
        <pose>0 0.099055 -0.0889 -8.6023e-17 0.01726 -8.8988e-17</pose>
                <material>
        	<lighting>1</lighting>
        	<ambient>0 0 0.1 1</ambient>
        	<diffuse>0 0 1 1</diffuse>
        	<specular>1 1 1 1</specular>
        	<emmisive>0 0 1 1</emmisive>
        </material>
        <geometry>
          <mesh>
            <scale>1 1 1</scale>
            <uri>model://bono/meshes/ll_ankle_pulley.STL</uri>
          </mesh>
        </geometry>
      </visual>
<!--
      <visual name='l_lleg_visual_ll_push_rod'>
        <pose>0.12698 0.0990431 -0.0911503 -0.142494 -0.12679 0.00378958</pose>
        <geometry>
          <mesh>
            <scale>1 1 1</scale>
            <uri>model://bono/meshes/ll_push_rod.STL</uri>
          </mesh>
        </geometry>
      </visual>
-->
      <visual name='l_lleg_visual_lr_ankle_pulley'>
      
        <pose>0 -0.09876 -0.0889 -8.6154e-17 0.018311 -8.9078e-17</pose>
                <material>
        	<lighting>1</lighting>
        	<ambient>0 0 0.1 1</ambient>
        	<diffuse>0 0 1 1</diffuse>
        	<specular>1 1 1 1</specular>
        	<emmisive>0 0 1 1</emmisive>
        </material>
        <geometry>
          <mesh>
            <scale>1 1 1</scale>
            <uri>model://bono/meshes/lr_ankle_pulley.STL</uri>
          </mesh>
        </geometry>
      </visual>
<!--
      <visual name='l_lleg_visual_lr_push_rod'>
        <pose>0.126978 -0.0987481 -0.0912838 0.165806 -0.0983264 -0.186284</pose>
        <geometry>
          <mesh>
            <scale>1 1 1</scale>
            <uri>model://bono/meshes/lr_push_rod.STL</uri>
          </mesh>
        </geometry>
      </visual>
-->
      <velocity_decay>
        <linear>0</linear>
        <angular>0</angular>
      </velocity_decay>
    </link>
    <joint name='l_leg_kny' type='revolute'>
      <child>l_lleg</child>
      <parent>l_uleg</parent>
      <axis>
        <xyz>0 1 0</xyz>
        <limit>
          <lower>-0.35</lower>
          <upper>1.885</upper>
          <effort>196</effort>
          <velocity>5</velocity>
        </limit>
        <dynamics>
          <damping>0.08</damping>
        </dynamics>
      </axis>
    </joint>
    <link name='l_talus'>    
<!-- Original Talus
      <pose>0.0 0.146158 -0.884123 1.570796 0 0</pose>
      <inertial>
        <pose>0.00030 0.00031 0 0 -0 0</pose>
        <mass>0.08082</mass>
        <inertia>
          <ixx> 0.09289e-04</ixx>
          <ixy> 0.00008e-04</ixy>
          <ixz> 0</ixz>
          <iyy> 0.09290e-04</iyy>
          <iyz> 0</iyz>
          <izz> 0.16488e-04</izz>
        </inertia>
      </inertial>
-->
<!-- Spring Talus -->
      <pose>0.0 0.146158 -0.868883 0 -0 0</pose>
      <inertial>
        <pose>-0.00320 -0.00000 0.00284 0 -0 0</pose>
        <mass>1.05332</mass>
        <inertia>
          <ixx> 0.00239</ixx>
          <ixy> 0.00000</ixy>
          <ixz> 0.00001</ixz>
          <iyy> 0.00055</iyy>
          <iyz> 0.00000</iyz>
          <izz> 0.00236</izz>
        </inertia>
      </inertial>
      
      <collision name='l_talus_collision'>
        <pose>0 0 0 1.5708 -0 0</pose>
        <geometry>
          <mesh>
            <scale>1 1 1</scale>
            <uri>model://bono/meshes/l_talus.STL</uri>
          </mesh>
        </geometry>
      </collision>
      <visual name='l_talus_visual'>
              <material>
        	<lighting>1</lighting>
        	<ambient>0.2 0.2 0.2 1</ambient>
        	<diffuse>0.8 0.8 0.8 1</diffuse>
        	<specular>1 1 1 1</specular>
        	<emmisive>0 0 1 1</emmisive>
        </material>
        <pose>0 0 0 0 -0 0</pose>
        <geometry>
          <mesh>
            <scale>1 1 1</scale>
            <uri>model://bono/meshes/l_talus.STL</uri>
          </mesh>
        </geometry>
      </visual>
      <velocity_decay>
        <linear>0</linear>
        <angular>0</angular>
      </velocity_decay>
    </link>
    <joint name='l_leg_uay' type='revolute'>
      <child>l_talus</child>
      <parent>l_lleg</parent>
      <axis>
        <xyz>0 1 0</xyz>
        <limit>
          <lower>-0.6981</lower>
          <upper>0.611</upper>
          <effort>387</effort>
          <velocity>11</velocity>
        </limit>
        <dynamics>
          <damping>0.07</damping>
        </dynamics>
      </axis>
    </joint>
    <link name='l_foot'>
<!-- Original Foot
      <pose>0.0 0.146158 -0.884123 0 0 0</pose>
      <inertial>
        <pose>0.07958 0.00001 -0.03190 0 -0 0</pose>
        <mass>1.62221</mass>
        <inertia>
          <ixx> 0.00344</ixx>
          <ixy>-0.00001</ixy>
          <ixz>-0.00019</ixz>
          <iyy> 0.00987</iyy>
          <iyz> 0</iyz>
          <izz> 0.01288</izz>
        </inertia>
      </inertial>
-->
<!-- IHMC Edit
      <pose>0.0 0.146158 -0.884123 0 0 0</pose>
      <inertial>
        <pose>0.121 0.0 0.0 0 -0 0</pose>
        <mass>1.62221</mass>
        <inertia>
          <ixx> 0.00344</ixx>
          <ixy>-0.00001</ixy>
          <ixz>-0.00019</ixz>
          <iyy> 0.00987</iyy>
          <iyz> 0</iyz>
          <izz> 0.01288</izz>
        </inertia>
      </inertial>
-->
<!-- Spring Foot -->
      <pose>0.0 0.146158 -0.868883 0 0 0</pose>
      <inertial>
        <pose>0.07332 0.00001 -0.05292 0 -0 0</pose>
        <mass>1.79430</mass>
        <inertia>
          <ixx> 0.00384</ixx>
          <ixy>-0.00001</ixy>
          <ixz> 0.00036</ixz>
          <iyy> 0.01148</iyy>
          <iyz>-0.00000</iyz>
          <izz> 0.01411</izz>
        </inertia>
      </inertial>
      
      <collision name='l_foot_collision'>
        <pose>0 0 0 0 -0 0</pose>
        <geometry>
          <mesh>
            <scale>1 1 1</scale>
            <uri>model://bono/meshes/l_foot.STL</uri>
          </mesh>
        </geometry>
      </collision>
      <visual name='l_foot_visual'>
        <material>
        	<lighting>1</lighting>
        	<ambient>0 0 0.1 1</ambient>
        	<diffuse>0 0 1 1</diffuse>
        	<specular>1 1 1 1</specular>
        	<emmisive>0 0 1 1</emmisive>
        </material>
        <pose>0 0 0 0 -0 0</pose>
        <geometry>
          <mesh>
            <scale>1 1 1</scale>
            <uri>model://bono/meshes/l_foot.STL</uri>
          </mesh>
        </geometry>
      </visual>
      <velocity_decay>
        <linear>0</linear>
        <angular>0</angular>
      </velocity_decay>
    </link>
    <joint name='l_leg_lax' type='revolute'>
      <child>l_foot</child>
      <parent>l_talus</parent>
      <axis>
        <xyz>1 0 0</xyz>
        <limit>
          <lower>-0.265</lower>
          <upper>0.265</upper>
          <effort>138</effort>
          <velocity>32</velocity>
        </limit>
        <dynamics>
          <damping>0.1</damping>
        </dynamics>
      </axis>
    </joint>
<!--    <link name='ll_ankle_pulley'>
      <pose>0.0 0.244939 -0.551383 0.0 0.0 0.0</pose>
      <inertial>
        <pose>0.0258325 -0.000139051 0.0112638 0 -0 0</pose>
        <mass>0.440393</mass>
        <inertia>
          <ixx> 0.000293173</ixx>
          <ixy> 2.58273e-06</ixy>
          <ixz> 0.000136715</ixz>
          <iyy> 0.00134739</iyy>
          <iyz> 1.76496e-07</iyz>
          <izz> 0.00113995</izz>
        </inertia>
      </inertial>
      <collision name='ll_ankle_pulley_collision'>
        <pose>0 0 0 0 -0 0</pose>
        <geometry>
          <mesh>
            <scale>1 1 1</scale>
            <uri>model://bono/meshes/ll_ankle_pulley.STL</uri>
          </mesh>
        </geometry>
      </collision>
      <visual name='ll_ankle_pulley_visual'>
        <pose>0 0 0 0 -0 0</pose>
        <geometry>
          <mesh>
            <scale>1 1 1</scale>
            <uri>model://bono/meshes/ll_ankle_pulley.STL</uri>
          </mesh>
        </geometry>
      </visual>
      <velocity_decay>
        <linear>0</linear>
        <angular>0</angular>
      </velocity_decay>
    </link>
    <joint name='ll_ankle_pulley' type='revolute'>
      <child>ll_ankle_pulley</child>
      <parent>l_lleg</parent>
      <axis>
        <xyz>0 1 0</xyz>
        <limit>
          <lower>-0.7</lower>
          <upper>0.7</upper>
          <effort>238</effort>
          <velocity>10</velocity>
        </limit>
        <dynamics>
          <damping>0.05</damping>
        </dynamics>
      </axis>
    </joint>
    <link name='ll_push_rod'>
      <pose>0.269019 0.244927 0.368583 -0.142494 -0.12679 0.00378958</pose>
      <inertial>
        <pose>-1.86447e-05 -4.48906e-10 -0.20659 0 -0 0</pose>
        <mass>0.177076</mass>
        <inertia>
          <ixx> 0.00156205</ixx>
          <ixy>-5.98197e-13</ixy>
          <ixz>-2.098e-07</ixz>
          <iyy> 0.00156153</iyy>
          <iyz>-4.61663e-13</iyz>
          <izz> 1.48944e-05</izz>
        </inertia>
      </inertial>
      <collision name='ll_push_rod_collision'>
        <pose>0 0 0 0 -0 0</pose>
        <geometry>
          <mesh>
            <scale>1 1 1</scale>
            <uri>model://bono/meshes/ll_push_rod.STL</uri>
          </mesh>
        </geometry>
      </collision>
      <visual name='ll_push_rod_visual'>
        <pose>0 0 0 0 -0 0</pose>
        <geometry>
          <mesh>
            <scale>1 1 1</scale>
            <uri>model://bono/meshes/ll_push_rod.STL</uri>
          </mesh>
        </geometry>
      </visual>
      <velocity_decay>
        <linear>0</linear>
        <angular>0</angular>
      </velocity_decay>
    </link>
    <joint name='ll_push_rod_top' type='revolute'>
      <child>ll_push_rod</child>
      <parent>ll_ankle_pulley</parent>
      <axis>
        <xyz>0.0142062 0.989926 -0.140872</xyz>
        <limit>
          <lower>-0.7</lower>
          <upper>0.7</upper>
          <effort>500</effort>
          <velocity>10</velocity>
        </limit>
        <dynamics>
          <damping>0</damping>
        </dynamics>
      </axis>
    </joint>
-->
<!--    <link name='lr_ankle_pulley'>
      <pose>0.0 0.047124 -0.551383 0.0 0.0 0.0</pose>
      <inertial>
        <pose>0.0258301 4.76736e-05 0.0112642 0 -0 0</pose>
        <mass>0.440377</mass>
        <inertia>
          <ixx> 0.000293173</ixx>
          <ixy>-5.73673e-06</ixy>
          <ixz> 0.000136703</ixz>
          <iyy> 0.00134731</iyy>
          <iyz> 4.76803e-07</iyz>
          <izz> 0.00113989</izz>
        </inertia>
      </inertial>
      <collision name='lr_ankle_pulley_collision'>
        <pose>0 0 0 0 -0 0</pose>
        <geometry>
          <mesh>
            <scale>1 1 1</scale>
            <uri>model://bono/meshes/lr_ankle_pulley.STL</uri>
          </mesh>
        </geometry>
      </collision>
      <visual name='lr_ankle_pulley_visual'>
        <pose>0 0 0 0 -0 0</pose>
        <geometry>
          <mesh>
            <scale>1 1 1</scale>
            <uri>model://bono/meshes/lr_ankle_pulley.STL</uri>
          </mesh>
        </geometry>
      </visual>
      <velocity_decay>
        <linear>0</linear>
        <angular>0</angular>
      </velocity_decay>
    </link>
    <joint name='lr_ankle_pulley' type='revolute'>
      <child>lr_ankle_pulley</child>
      <parent>l_lleg</parent>
      <axis>
        <xyz>0 1 0</xyz>
        <limit>
          <lower>-0.7</lower>
          <upper>0.7</upper>
          <effort>238</effort>
          <velocity>10</velocity>
        </limit>
        <dynamics>
          <damping>0.05</damping>
        </dynamics>
      </axis>
    </joint>
    <link name='lr_push_rod'>
      <pose>0.269017 0.0471359 0.368449 0.165806 -0.0983264 -0.186284</pose>
      <inertial>
        <pose>-1.86447e-05 -4.48906e-10 -0.20659 0 -0 0</pose>
        <mass>0.177076</mass>
        <inertia>
          <ixx> 0.00156205</ixx>
          <ixy>-5.98197e-13</ixy>
          <ixz>-2.098e-07</ixz>
          <iyy> 0.00156153</iyy>
          <iyz>-4.61663e-13</iyz>
          <izz> 1.48944e-05</izz>
        </inertia>
      </inertial>
      <collision name='lr_push_rod_collision'>
        <pose>0 0 0 0 -0 0</pose>
        <geometry>
          <mesh>
            <scale>1 1 1</scale>
            <uri>model://bono/meshes/lr_push_rod.STL</uri>
          </mesh>
        </geometry>
      </collision>
      <visual name='lr_push_rod_visual'>
        <pose>0 0 0 0 -0 0</pose>
        <geometry>
          <mesh>
            <scale>1 1 1</scale>
            <uri>model://bono/meshes/lr_push_rod.STL</uri>
          </mesh>
        </geometry>
      </visual>
      <velocity_decay>
        <linear>0</linear>
        <angular>0</angular>
      </velocity_decay>
    </link>
    <joint name='lr_push_rod_top' type='revolute'>
      <child>lr_push_rod</child>
      <parent>lr_ankle_pulley</parent>
      <axis>
        <xyz>0.166747 0.972223 0.16425</xyz>
        <limit>
          <lower>-0.7</lower>
          <upper>0.7</upper>
          <effort>500</effort>
          <velocity>10</velocity>
        </limit>
        <dynamics>
          <damping>0</damping>
        </dynamics>
      </axis>
    </joint>
 -->
    <link name='r_uglut'>
      <pose>0.0 -0.13335 0.0 0 0 0</pose>
      <inertial>
        <pose>0.02353 0.02583 0.05228 0 -0 0</pose>
        <mass>2.98085</mass>
        <inertia>
          <ixx> 0.00822</ixx>
          <ixy>-0.00281</ixy>
          <ixz>-0.00357</ixz>
          <iyy> 0.02044</iyy>
          <iyz>-0.00175</iyz>
          <izz> 0.01809</izz>
        </inertia>
      </inertial>
      <collision name='r_uglut_collision'>
        <pose>0 0 0 0 -0 0</pose>
        <geometry>
          <mesh>
            <scale>1 1 1</scale>
            <uri>model://bono/meshes/r_uglut.STL</uri>
          </mesh>
        </geometry>
      </collision>
      <visual name='r_uglut_visual'>
              <material>
        	<lighting>1</lighting>
        	<ambient>0 0 0.2 1</ambient>
        	<diffuse>0 0.3 1 1</diffuse>
        	<specular>1 1 1 1</specular>
        	<emmisive>0 0 1 1</emmisive>
        </material>
        <pose>0 0 0 0 -0 0</pose>
        <geometry>
          <mesh>
            <scale>1 1 1</scale>
            <uri>model://bono/meshes/r_uglut.STL</uri>
          </mesh>
        </geometry>
      </visual>
      <velocity_decay>
        <linear>0</linear>
        <angular>0</angular>
      </velocity_decay>
    </link>
    <joint name='r_leg_mhx' type='revolute'>
      <child>r_uglut</child>
      <parent>pelvis</parent>
      <axis>
        <xyz>1 0 0</xyz>
        <limit>
          <lower>-0.384</lower>
          <upper>0.314</upper>
          <effort>245</effort>
          <velocity>4</velocity>
        </limit>
        <dynamics>
          <damping>0.18</damping>
        </dynamics>
      </axis>
    </joint>
    <link name='r_lglut'>
      <pose>0.0 -0.13335 0.0 0 0 0</pose>
      <inertial>
        <pose>0.04856 -0.06373 0.02393 0 -0 0</pose>
        <mass>4.77402</mass>
        <inertia>
          <ixx> 0.02514</ixx>
          <ixy> 0.00411</ixy>
          <ixz>-0.00448</ixz>
          <iyy> 0.02502</iyy>
          <iyz> 0.00554</iyz>
          <izz> 0.01780</izz>
        </inertia>
      </inertial>
      <collision name='r_lglut_collision'>
        <pose>0 0 0 0 -0 0</pose>
        <geometry>
          <mesh>
            <scale>1 1 1</scale>
            <uri>model://bono/meshes/r_lglut.STL</uri>
          </mesh>
        </geometry>
      </collision>
      <visual name='r_lglut_visual'>
              <material>
        	<lighting>1</lighting>
        	<ambient>0 0.2 0.4 1</ambient>
        	<diffuse>0 0.5 1 1</diffuse>
        	<specular>1 1 1 1</specular>
        	<emmisive>0 0 1 1</emmisive>
        </material>
        <pose>0 0 0 0 -0 0</pose>
        <geometry>
          <mesh>
            <scale>1 1 1</scale>
            <uri>model://bono/meshes/r_lglut.STL</uri>
          </mesh>
        </geometry>
      </visual>
      <velocity_decay>
        <linear>0</linear>
        <angular>0</angular>
      </velocity_decay>
    </link>
    <joint name='r_leg_uhz' type='revolute'>
      <child>r_lglut</child>
      <parent>r_uglut</parent>
      <axis>
        <xyz>0 0 1</xyz>
        <limit>
          <lower>-0.523</lower>
          <upper>0.262</upper>
          <effort>63</effort>
          <velocity>26</velocity>
        </limit>
        <dynamics>
          <damping>0.04</damping>
        </dynamics>
      </axis>
    </joint>
    <link name='r_uleg'>
      <pose>0.0 -0.146158 -0.085547 0 0 0</pose>
<!-- Original Upper Leg
      <inertial>
        <pose>-0.02 -0.0525 -0.218 0 -0 0</pose>
        <mass>7.76243</mass>
        <inertia>
          <ixx> 0.13623</ixx>
          <ixy>-0.00240</ixy>
          <ixz> 0.00083</ixz>
          <iyy> 0.11776</iyy>
          <iyz> 0.02081</iyz>
          <izz> 0.04665</izz>
        </inertia>
      </inertial>
-->
<!-- Four bar Upper Leg -->
      <inertial>
        <pose>-0.00347 -0.03300 -0.16049 0 -0 0</pose>
        <mass>9.20765</mass>
        <inertia>
          <ixx> 0.16930</ixx>
          <ixy>-0.00601</ixy>
          <ixz> 0.00367</ixz>
          <iyy> 0.13914</iyy>
          <iyz> 0.03211</iyz>
          <izz> 0.08115</izz>
        </inertia>
      </inertial>

      <collision name='r_uleg_collision'>
        <pose>0 0 0 0 -0 0</pose>
        <geometry>
          <mesh>
            <scale>1 1 1</scale>
            <uri>model://bono/meshes/r_uleg.STL</uri>
          </mesh>
        </geometry>
      </collision>
      <visual name='r_uleg_visual'>
              <material>
        	<lighting>1</lighting>
        	<ambient>0 0 0.2 1</ambient>
        	<diffuse>0 0.3 1 1</diffuse>
        	<specular>1 1 1 1</specular>
        	<emmisive>0 0 1 1</emmisive>
        </material>
        <pose>0 0 0 0 -0 0</pose>
        <geometry>
          <mesh>
            <scale>1 1 1</scale>
            <uri>model://bono/meshes/r_uleg.STL</uri>
          </mesh>
        </geometry>
      </visual>
      <velocity_decay>
        <linear>0</linear>
        <angular>0</angular>
      </velocity_decay>
    </link>
    <joint name='r_leg_lhy' type='revolute'>
      <child>r_uleg</child>
      <parent>r_lglut</parent>
      <axis>
        <xyz>0 1 0</xyz>
        <limit>
          <lower>-1.57</lower>
          <upper>0.5236</upper>
          <effort>440</effort>
          <velocity>10</velocity>
        </limit>
        <dynamics>
          <damping>0.11</damping>
        </dynamics>
      </axis>
    </joint>
<!--    <link name='r_lleg'>
      <pose>0.0 -0.146158 -0.462483 0 0 0</pose>
      <inertial>
        <pose>0.000976513 -0.000162632 -0.0411224 0 -0 0</pose>
        <mass>7.60476</mass>
        <inertia>
          <ixx> 0.0806158</ixx>
          <ixy>-8.1038e-05</ixy>
          <ixz>-3.07137e-05</ixz>
          <iyy> 0.0811019</iyy>
          <iyz> 1.3945e-05</iyz>
          <izz> 0.019801</izz>
        </inertia>
      </inertial>
      <collision name='r_lleg_collision'>
        <pose>0 0 0 0 -0 0</pose>
        <geometry>
          <mesh>
            <scale>1 1 1</scale>
            <uri>model://bono/meshes/r_lleg.STL</uri>
          </mesh>
        </geometry>
      </collision>
      <visual name='r_lleg_visual'>
        <pose>0 0 0 0 -0 0</pose>
        <geometry>
          <mesh>
            <scale>1 1 1</scale>
            <uri>model://bono/meshes/r_lleg.STL</uri>
          </mesh>
        </geometry>
      </visual>
      <velocity_decay>
        <linear>0</linear>
        <angular>0</angular>
      </velocity_decay>
    </link>
-->
  <link name='r_lleg'>
      <pose>0.0 -0.146158 -0.462483 0 0 0</pose>
<!-- Original Ankle 
      <inertial>
        <pose>0.013 0.02 -0.06 0 -0 0</pose>
        <mass>8.87430</mass>
        <inertia>
          <ixx> 0.11823</ixx>
          <ixy>-0.00012</ixy>
          <ixz> 0.01160</ixz>
          <iyy> 0.11665</iyy>
          <iyz>-0.00009</iyz>
          <izz> 0.03882</izz>
        </inertia>
      </inertial>
-->
<!-- Spring Ankle -->
	  <inertial>
        <pose>0.00860 -0.00029 -0.07339 0 -0 0</pose>
        <mass>9.65521</mass>
        <inertia>
          <ixx> 0.16306</ixx>
          <ixy>-0.00012</ixy>
          <ixz> 0.01196</ixz>
          <iyy> 0.15894</iyy>
          <iyz>-0.00035</iyz>
          <izz> 0.04292</izz>
        </inertia>
      </inertial>

      <collision name='r_lleg_collision'>
        <pose>0 0 0 0 -0 0</pose>
        <geometry>
          <mesh>
            <scale>1 1 1</scale>
            <uri>model://bono/meshes/r_lleg.STL</uri>
          </mesh>
        </geometry>
      </collision>
      <collision name='r_lleg_collision_rl_ankle_pulley'>
        <pose>-0.0008366 0.098654 -0.088896 -1.6567e-16 0.026671 9.0419e-17</pose>
        <geometry>
          <mesh>
            <scale>1 1 1</scale>
            <uri>model://bono/meshes/rl_ankle_pulley.STL</uri>
          </mesh>
        </geometry>
      </collision>
<!--
      <collision name='r_lleg_collision_rl_push_rod'>
        <pose>0.126117 0.0986421 -0.0923412 -0.148503 -0.109613 0.0571355</pose>
        <geometry>
          <mesh>
            <scale>1 1 1</scale>
            <uri>model://bono/meshes/rl_push_rod.STL</uri>
          </mesh>
        </geometry>
      </collision>
-->
      <collision name='r_lleg_collision_rr_ankle_pulley'>
        <pose>-0.0008366 -0.099162 -0.088896 -4.859e-17 0.026961 5.7481e-17</pose>
        <geometry>
          <mesh>
            <scale>1 1 1</scale>
            <uri>model://bono/meshes/rr_ankle_pulley.STL</uri>
          </mesh>
        </geometry>
      </collision>
<!--
      <collision name='r_lleg_collision_rr_push_rod'>
        <pose>0.126116 -0.0991501 -0.092378 0.143388 -0.117189 -0.00519735</pose>
        <geometry>
          <mesh>
            <scale>1 1 1</scale>
            <uri>model://bono/meshes/rr_push_rod.STL</uri>
          </mesh>
        </geometry>
      </collision>
-->
      <visual name='r_lleg_visual'>
              <material>
        	<lighting>1</lighting>
		   	<ambient>0 0.2 0.4 1</ambient>
        	<diffuse>0 0.5 1 1</diffuse> 
        	<specular>1 1 1 1</specular>
        	<emmisive>0 0 1 1</emmisive>
        </material>
        <pose>0 0 0 0 -0 0</pose>
        <geometry>
          <mesh>
            <scale>1 1 1</scale>
            <uri>model://bono/meshes/r_lleg.STL</uri>
          </mesh>
        </geometry>
      </visual>
      <visual name='r_lleg_visual_rl_ankle_pulley'>
              <material>
        	<lighting>1</lighting>
        	<ambient>0 0 0.1 1</ambient>
        	<diffuse>0 0 1 1</diffuse>
        	<specular>1 1 1 1</specular>
        	<emmisive>0 0 1 1</emmisive>
        </material>
        <pose>-0.0008366 0.098654 -0.088896 -1.6567e-16 0.026671 9.0419e-17</pose>
        <geometry>
          <mesh>
            <scale>1 1 1</scale>
            <uri>model://bono/meshes/rl_ankle_pulley.STL</uri>
          </mesh>
        </geometry>
      </visual>
<!--
      <visual name='r_lleg_visual_rl_push_rod'>
        <pose>0.126117 0.0986421 -0.0923412 -0.148503 -0.109613 0.0571355</pose>
        <geometry>
          <mesh>
            <scale>1 1 1</scale>
            <uri>model://bono/meshes/rl_push_rod.STL</uri>
          </mesh>
        </geometry>
      </visual>
-->
      <visual name='r_lleg_visual_rr_ankle_pulley'>
              <material>
        	<lighting>1</lighting>
        	<ambient>0 0 0.1 1</ambient>
        	<diffuse>0 0 1 1</diffuse>
        	<specular>1 1 1 1</specular>
        	<emmisive>0 0 1 1</emmisive>
        </material>
        <pose>-0.0008366 -0.099162 -0.088896 -4.859e-17 0.026961 5.7481e-17</pose>
        <geometry>
          <mesh>
            <scale>1 1 1</scale>
            <uri>model://bono/meshes/rr_ankle_pulley.STL</uri>
          </mesh>
        </geometry>
      </visual>
<!--
      <visual name='r_lleg_visual_rr_push_rod'>
        <pose>0.126116 -0.0991501 -0.092378 0.143388 -0.117189 -0.00519735</pose>
        <geometry>
          <mesh>
            <scale>1 1 1</scale>
            <uri>model://bono/meshes/rr_push_rod.STL</uri>
          </mesh>
        </geometry>
      </visual>
-->
      <velocity_decay>
        <linear>0</linear>
        <angular>0</angular>
      </velocity_decay>
    </link>
    <joint name='r_leg_kny' type='revolute'>
      <child>r_lleg</child>
      <parent>r_uleg</parent>
      <axis>
        <xyz>0 1 0</xyz>
        <limit>
          <lower>-0.35</lower>
          <upper>1.885</upper>
          <effort>196</effort>
          <velocity>5</velocity>
        </limit>
        <dynamics>
          <damping>0.08</damping>
        </dynamics>
      </axis>
    </joint>
    <link name='r_talus'>
<!-- Original Talus
      <pose>0.0 -0.146158 -0.884123 1.570796 0 0</pose>
      <inertial>
        <pose>0.00030 -0.00031 0 0 -0 0</pose>
        <mass>0.08082</mass>
        <inertia>
          <ixx> 0.09289e-04</ixx>
          <ixy>-0.00008e-04</ixy>
          <ixz> 0</ixz>
          <iyy> 0.09290e-04</iyy>
          <iyz> 0</iyz>
          <izz> 0.16488e-04</izz>
        </inertia>
      </inertial>
-->
<!-- Spring Talus -->
      <pose>0.0 -0.146158 -0.868883 0 -0 0</pose>
      <inertial>
        <pose>-0.00320 0.00000 0.00284 0 -0 0</pose>
        <mass>1.05332</mass>
        <inertia>
          <ixx> 0.00239</ixx>
          <ixy>-0.00000</ixy>
          <ixz> 0.00001</ixz>
          <iyy> 0.00055</iyy>
          <iyz>-0.00000</iyz>
          <izz> 0.00236</izz>
        </inertia>
      </inertial>

      <collision name='r_talus_collision'>
        <pose>0 0 0 1.5708 -0 0</pose>
        <geometry>
          <mesh>
            <scale>1 1 1</scale>
            <uri>model://bono/meshes/r_talus.STL</uri>
          </mesh>
        </geometry>
      </collision>
      <visual name='r_talus_visual'>
        <pose>0 0 0 0 -0 0</pose>
                <material>
        	<lighting>1</lighting>
        	<ambient>0.2 0.2 0.2 1</ambient>
        	<diffuse>0.8 0.8 0.8 1</diffuse>
        	<specular>1 1 1 1</specular>
        	<emmisive>0 0 1 1</emmisive>
        </material>
        <geometry>
          <mesh>
            <scale>1 1 1</scale>
            <uri>model://bono/meshes/r_talus.STL</uri>
          </mesh>
        </geometry>
      </visual>
      <velocity_decay>
        <linear>0</linear>
        <angular>0</angular>
      </velocity_decay>
    </link>
    <joint name='r_leg_uay' type='revolute'>
      <child>r_talus</child>
      <parent>r_lleg</parent>
      <axis>
        <xyz>0 1 0</xyz>
        <limit>
          <lower>-0.6981</lower>
          <upper>0.611</upper>
          <effort>387</effort>
          <velocity>11</velocity>
        </limit>
        <dynamics>
          <damping>0.07</damping>
        </dynamics>
      </axis>
    </joint>
    <link name='r_foot'>
<!-- Original Foot
      <pose>0.0 -0.146158 -0.884123 0 0 0</pose>
      <inertial>
        <pose>0.07958 0.00001 -0.03190 0 -0 0</pose>
        <mass>1.62221</mass>
        <inertia>
          <ixx> 0.00344</ixx>
          <ixy>-0.00001</ixy>
          <ixz>-0.00019</ixz>
          <iyy> 0.00987</iyy>
          <iyz>-0</iyz>
          <izz> 0.01288</izz>
        </inertia>
      </inertial>
-->
<!-- IHMC Edit
      <pose>0.0 -0.146158 -0.884123 0 0 0</pose>
      <inertial>
        <pose>0.121 0.0 0.0 0 -0 0</pose>
        <mass>1.62221</mass>
        <inertia>
          <ixx> 0.00344</ixx>
          <ixy>-0.00001</ixy>
          <ixz>-0.00019</ixz>
          <iyy> 0.00987</iyy>
          <iyz>-0</iyz>
          <izz> 0.01288</izz>
        </inertia>
      </inertial>
-->
<!-- Spring Foot -->
      <pose>0.0 -0.146158 -0.868883 0 0 0</pose>
      <inertial>
        <pose>0.07332 0.00001 -0.05292 0 -0 0</pose>
        <mass>1.79430</mass>
        <inertia>
          <ixx> 0.00384</ixx>
          <ixy>-0.00001</ixy>
          <ixz> 0.00036</ixz>
          <iyy> 0.01148</iyy>
          <iyz>-0.00000</iyz>
          <izz> 0.01411</izz>
        </inertia>
      </inertial>

      <collision name='r_foot_collision'>
        <pose>0 0 0 0 -0 0</pose>
        <geometry>
          <mesh>
            <scale>1 1 1</scale>
            <uri>model://bono/meshes/r_foot.STL</uri>
          </mesh>
        </geometry>
      </collision>
      <visual name='r_foot_visual'>
        <pose>0 0 0 0 -0 0</pose>
                <material>
        	<lighting>1</lighting>
        	<ambient>0 0 0.1 1</ambient>
        	<diffuse>0 0 1 1</diffuse>
        	<specular>1 1 1 1</specular>
        	<emmisive>0 0 1 1</emmisive>
        </material>
        <geometry>
          <mesh>
            <scale>1 1 1</scale>
            <uri>model://bono/meshes/r_foot.STL</uri>
          </mesh>
        </geometry>
      </visual>
      <velocity_decay>
        <linear>0</linear>
        <angular>0</angular>
      </velocity_decay>
    </link>
    <joint name='r_leg_lax' type='revolute'>
      <child>r_foot</child>
      <parent>r_talus</parent>
      <axis>
        <xyz>1 0 0</xyz>
        <limit>
          <lower>-0.265</lower>
          <upper>0.265</upper>
          <effort>138</effort>
          <velocity>32</velocity>
        </limit>
        <dynamics>
          <damping>0.01</damping>
        </dynamics>
      </axis>
    </joint>
<!--    <link name='rl_ankle_pulley'>
      <pose>0.0 -0.047124 -0.551383 0.0 0.0 0.0</pose>
      <inertial>
        <pose>0.0258325 -0.000139051 0.0112638 0 -0 0</pose>
        <mass>0.440393</mass>
        <inertia>
          <ixx> 0.000293173</ixx>
          <ixy> 2.58273e-06</ixy>
          <ixz> 0.000136715</ixz>
          <iyy> 0.00134739</iyy>
          <iyz> 1.76496e-07</iyz>
          <izz> 0.00113995</izz>
        </inertia>
      </inertial>
      <collision name='rl_ankle_pulley_collision'>
        <pose>0 0 0 0 -0 0</pose>
        <geometry>
          <mesh>
            <scale>1 1 1</scale>
            <uri>model://bono/meshes/rl_ankle_pulley.STL</uri>
          </mesh>
        </geometry>
      </collision>
      <visual name='rl_ankle_pulley_visual'>
              <material>
        	<lighting>1</lighting>
        	<ambient>0 0 0.1 1</ambient>
        	<diffuse>0 0 1 1</diffuse>
        	<specular>1 1 1 1</specular>
        	<emmisive>0 0 1 1</emmisive>
        </material>
        <pose>0 0 0 0 -0 0</pose>
        <geometry>
          <mesh>
            <scale>1 1 1</scale>
            <uri>model://bono/meshes/rl_ankle_pulley.STL</uri>
          </mesh>
        </geometry>
      </visual>
      <velocity_decay>
        <linear>0</linear>
        <angular>0</angular>
      </velocity_decay>
    </link>
    <joint name='rl_ankle_pulley' type='revolute'>
      <child>rl_ankle_pulley</child>
      <parent>r_lleg</parent>
      <axis>
        <xyz>0 1 0</xyz>
        <limit>
          <lower>-0.7</lower>
          <upper>0.7</upper>
          <effort>238</effort>
          <velocity>10</velocity>
        </limit>
        <dynamics>
          <damping>0.05</damping>
        </dynamics>
      </axis>
    </joint>
    <link name='rl_push_rod'>
      <pose>0.269009 -0.0475569 0.368583 -0.149044 -0.119008 0.0571972</pose>
      <inertial>
        <pose>-1.86447e-05 -4.48906e-10 -0.20659 0 -0 0</pose>
        <mass>0.177076</mass>
        <inertia>
          <ixx> 0.00156205</ixx>
          <ixy>-5.98197e-13</ixy>
          <ixz>-2.098e-07</ixz>
          <iyy> 0.00156153</iyy>
          <iyz>-4.61663e-13</iyz>
          <izz> 1.48944e-05</izz>
        </inertia>
      </inertial>
      <collision name='rl_push_rod_collision'>
        <pose>0 0 0 0 -0 0</pose>
        <geometry>
          <mesh>
            <scale>1 1 1</scale>
            <uri>model://bono/meshes/rl_push_rod.STL</uri>
          </mesh>
        </geometry>
      </collision>
      <visual name='rl_push_rod_visual'>
        <pose>0 0 0 0 -0 0</pose>
        <geometry>
          <mesh>
            <scale>1 1 1</scale>
            <uri>model://bono/meshes/rl_push_rod.STL</uri>
          </mesh>
        </geometry>
      </visual>
      <velocity_decay>
        <linear>0</linear>
        <angular>0</angular>
      </velocity_decay>
    </link>
    <joint name='rl_push_rod_top' type='revolute'>
      <child>rl_push_rod</child>
      <parent>rl_ankle_pulley</parent>
      <axis>
        <xyz>-0.038931 0.988304 -0.147443</xyz>
        <limit>
          <lower>-0.7</lower>
          <upper>0.7</upper>
          <effort>500</effort>
          <velocity>10</velocity>
        </limit>
        <dynamics>
          <damping>0</damping>
        </dynamics>
      </axis>
    </joint>
-->
<!--    <link name='rr_ankle_pulley'>
      <pose>0.0 -0.244939 -0.551383 0 0 0</pose>
      <inertial>
        <pose>0.0258301 4.76736e-05 0.0112642 0 -0 0</pose>
        <mass>0.440377</mass>
        <inertia>
          <ixx> 0.000293173</ixx>
          <ixy>-5.73673e-06</ixy>
          <ixz> 0.000136703</ixz>
          <iyy> 0.00134731</iyy>
          <iyz> 4.76803e-07</iyz>
          <izz> 0.00113989</izz>
        </inertia>
      </inertial>
      <collision name='rr_ankle_pulley_collision'>
        <pose>0 0 0 0 -0 0</pose>
        <geometry>
          <mesh>
            <scale>1 1 1</scale>
            <uri>model://bono/meshes/rr_ankle_pulley.STL</uri>
          </mesh>
        </geometry>
      </collision>
      <visual name='rr_ankle_pulley_visual'>
        <pose>0 0 0 0 -0 0</pose>
        <geometry>
          <mesh>
            <scale>1 1 1</scale>
            <uri>model://bono/meshes/rr_ankle_pulley.STL</uri>
          </mesh>
        </geometry>
      </visual>
      <velocity_decay>
        <linear>0</linear>
        <angular>0</angular>
      </velocity_decay>
    </link>
    <joint name='rr_ankle_pulley' type='revolute'>
      <child>rr_ankle_pulley</child>
      <parent>r_lleg</parent>
      <axis>
        <xyz>0 1 0</xyz>
        <limit>
          <lower>-0.7</lower>
          <upper>0.7</upper>
          <effort>238</effort>
          <velocity>10</velocity>
        </limit>
        <dynamics>
          <damping>0.05</damping>
        </dynamics>
      </axis>
    </joint>
    <link name='rr_push_rod'>
      <pose>0.269008 -0.245349 0.368546 0.143438 -0.1266 -0.00520335</pose>
      <inertial>
        <pose>-1.86447e-05 -4.48906e-10 -0.20659 0 -0 0</pose>
        <mass>0.177076</mass>
        <inertia>
          <ixx> 0.00156205</ixx>
          <ixy>-5.98197e-13</ixy>
          <ixz>-2.098e-07</ixz>
          <iyy> 0.00156153</iyy>
          <iyz>-4.61663e-13</iyz>
          <izz> 1.48944e-05</izz>
        </inertia>
      </inertial>
      <collision name='rr_push_rod_collision'>
        <pose>0 0 0 0 -0 0</pose>
        <geometry>
          <mesh>
            <scale>1 1 1</scale>
            <uri>model://bono/meshes/rr_push_rod.STL</uri>
          </mesh>
        </geometry>
      </collision>
      <visual name='rr_push_rod_visual'>
        <pose>0 0 0 0 -0 0</pose>
        <geometry>
          <mesh>
            <scale>1 1 1</scale>
            <uri>model://bono/meshes/rr_push_rod.STL</uri>
          </mesh>
        </geometry>
      </visual>
      <velocity_decay>
        <linear>0</linear>
        <angular>0</angular>
      </velocity_decay>
    </link>
    <joint name='rr_push_rod_top' type='revolute'>
      <child>rr_push_rod</child>
      <parent>rr_ankle_pulley</parent>
      <axis>
        <xyz>-0.0128986 0.989811 0.141802</xyz>
        <limit>
          <lower>-0.7</lower>
          <upper>0.7</upper>
          <effort>500</effort>
          <velocity>10</velocity>
        </limit>
        <dynamics>
          <damping>0</damping>
        </dynamics>
      </axis>
    </joint>
-->
  </model>
</sdf>
