<?xml version="1.0" encoding="UTF-8"?>
<sdf version='1.4'>
  <model name='llaQuadruped'>
    <link name='body'>
      <sensor name='imu' type='imu'>
        <always_on>1</always_on>
        <update_rate>1000</update_rate>
        <imu>
          <noise>
            <type>gaussian</type>
            <rate>
              <mean>0</mean>
              <stddev>0.0002</stddev>
              <bias_mean>7.5e-06</bias_mean>
              <bias_stddev>8e-07</bias_stddev>
            </rate>
            <accel>
              <mean>0</mean>
              <stddev>0.017</stddev>
              <bias_mean>0.1</bias_mean>
              <bias_stddev>0.001</bias_stddev>
            </accel>
          </noise>
        </imu>
        <pose>0.3 0.15 0.05 0 0 0</pose>
      </sensor>
      <inertial>
        <pose>0.3 0.15 0.05 0 0 0</pose>
        <mass>20</mass>
        <inertia>
          <ixx>1</ixx>
          <ixy>0.006</ixy>
          <ixz>0.003</ixz>
          <iyy>2</iyy>
          <iyz>-0.0006</iyz>
          <izz>2</izz>
        </inertia>
      </inertial>
      <visual name='body_visual'>
        <geometry>
          <box>
            <size>0.6 0.2 0.01</size>
          </box>
        </geometry>
      </visual>
    </link>
    <link name='front_left_hip'>
      <pose>0.04 0.2 0 0 0 0</pose>
      <inertial>
        <pose>0.1 0 0 0 0 0</pose>
        <mass>2</mass>
        <inertia>
          <ixx>0.006</ixx>
          <ixy>-4e-05</ixy>
          <ixz>0.004</ixz>
          <iyy>0.025</iyy>
          <iyz>-4e-06</iyz>
          <izz>0.02</izz>
        </inertia>
      </inertial>
      <visual name='front_left_hip_visual'>
        <pose>0 0 0.04 0 1.57075 3.14159</pose>
        <geometry>
          <mesh>
            <scale>1 1 1</scale>
            <uri>model://lla_quadruped_description/model/meshes/lla_5A0-binary.obj</uri>
          </mesh>
        </geometry>
      </visual>
      <velocity_decay>
        <linear>0</linear>
        <angular>0</angular>
      </velocity_decay>
    </link>
    <joint name='front_left_hip_roll' type='revolute'>
      <child>front_left_hip</child>
      <parent>body</parent>
      <axis>
        <xyz>1 0 0</xyz>
        <limit>
          <lower>-3.14159</lower>
          <upper>3.14159</upper>
          <effort>1000</effort>
          <velocity>100</velocity>
        </limit>
        <dynamics/>
      </axis>
    </joint>
    <link name='front_left_thigh'>
      <pose>0.24 0.27 0 0 0 0</pose>
      <inertial>
        <pose>0.1 0 0 0 0 0</pose>
        <mass>2</mass>
        <inertia>
          <ixx>0.006</ixx>
          <ixy>-4e-05</ixy>
          <ixz>0.004</ixz>
          <iyy>0.025</iyy>
          <iyz>-4e-06</iyz>
          <izz>0.02</izz>
        </inertia>
      </inertial>
      <visual name='front_left_thigh_visual'>
        <pose>0 0 0 0 0 0</pose>
        <geometry>
          <mesh>
            <scale>1 1 1</scale>
            <uri>model://lla_quadruped_description/model/meshes/lla_5A0-binary.obj</uri>
          </mesh>
        </geometry>
      </visual>
    </link>
    <joint name='front_left_hip_pitch' type='revolute'>
      <child>front_left_thigh</child>
      <parent>front_left_hip</parent>
      <axis>
        <xyz>0 -1 0</xyz>
        <limit>
          <lower>-3.14159</lower>
          <upper>3.14159</upper>
          <effort>1000</effort>
          <velocity>100</velocity>
        </limit>
        <dynamics/>
      </axis>
    </joint>
    <link name='front_left_shin'>
      <pose>0.24 0.27 -0.2 0 0 0</pose>
      <inertial>
        <pose>0 0 -0.1 0 0 0</pose>
        <mass>0.5</mass>
        <inertia>
          <ixx>0.005</ixx>
          <ixy>-1e-06</ixy>
          <ixz>0.0006</ixz>
          <iyy>0.005</iyy>
          <iyz>-1e-06</iyz>
          <izz>0.0005</izz>
        </inertia>
      </inertial>
      <visual name='front_left_shin_visual'>
        <pose>0 0 -0.1 0 0 0</pose>
        <geometry>
          <box>
            <size>0.01 0.01 0.19</size>
          </box>
        </geometry>
      </visual>
    </link>
    <joint name='front_left_knee_pitch' type='revolute'>
      <child>front_left_shin</child>
      <parent>front_left_thigh</parent>
      <axis>
        <xyz>0 -1 0</xyz>
        <limit>
          <lower>-3.14159</lower>
          <upper>3.14159</upper>
          <effort>1000</effort>
          <velocity>100</velocity>
        </limit>
        <dynamics/>
      </axis>
    </joint>
    <link name='front_right_hip'>
      <pose>0.04 -0.2 0 0 0 0</pose>
      <inertial>
        <pose>0.1 0 0 0 0 0</pose>
        <mass>2</mass>
        <inertia>
          <ixx>0.006</ixx>
          <ixy>-4e-05</ixy>
          <ixz>0.004</ixz>
          <iyy>0.025</iyy>
          <iyz>-4e-06</iyz>
          <izz>0.02</izz>
        </inertia>
      </inertial>
      <visual name='front_right_hip_visual'>
        <pose>0 0 0.04 0 1.57075 3.14159</pose>
        <geometry>
          <mesh>
            <scale>1 1 1</scale>
            <uri>model://lla_quadruped_description/model/meshes/lla_5A0-binary.obj</uri>
          </mesh>
        </geometry>
      </visual>
    </link>
    <joint name='front_right_hip_roll' type='revolute'>
      <child>front_right_hip</child>
      <parent>body</parent>
      <axis>
        <xyz>1 0 0</xyz>
        <limit>
          <lower>-3.14159</lower>
          <upper>3.14159</upper>
          <effort>1000</effort>
          <velocity>100</velocity>
        </limit>
        <dynamics/>
      </axis>
    </joint>
    <link name='front_right_thigh'>
      <pose>0.24 -0.27 0 0 0 0</pose>
      <inertial>
        <pose>0.1 0 0 0 0 0</pose>
        <mass>2</mass>
        <inertia>
          <ixx>0.006</ixx>
          <ixy>-4e-05</ixy>
          <ixz>0.004</ixz>
          <iyy>0.025</iyy>
          <iyz>-4e-06</iyz>
          <izz>0.02</izz>
        </inertia>
      </inertial>
      <visual name='front_right_thigh_visual'>
        <pose>0 0 0 0 0 0</pose>
        <geometry>
          <mesh>
            <scale>1 1 1</scale>
            <uri>model://lla_quadruped_description/model/meshes/lla_5A0-binary.obj</uri>
          </mesh>
        </geometry>
      </visual>
    </link>
    <joint name='front_right_hip_pitch' type='revolute'>
      <child>front_right_thigh</child>
      <parent>front_right_hip</parent>
      <axis>
        <xyz>0 -1 0</xyz>
        <limit>
          <lower>-3.14159</lower>
          <upper>3.14159</upper>
          <effort>1000</effort>
          <velocity>100</velocity>
        </limit>
        <dynamics/>
      </axis>
    </joint>
    <link name='front_right_shin'>
      <pose>0.24 -0.27 -0.2 0 0 0</pose>
      <inertial>
        <pose>0 0 -0.1 0 0 0</pose>
        <mass>0.5</mass>
        <inertia>
          <ixx>0.005</ixx>
          <ixy>-1e-06</ixy>
          <ixz>0.0006</ixz>
          <iyy>0.005</iyy>
          <iyz>-1e-06</iyz>
          <izz>0.0005</izz>
        </inertia>
      </inertial>
      <visual name='front_right_shin_visual'>
        <pose>0 0 -0.1 0 0 0</pose>
        <geometry>
          <box>
            <size>0.01 0.01 0.19</size>
          </box>
        </geometry>
      </visual>
    </link>
    <joint name='front_right_knee_pitch' type='revolute'>
      <child>front_right_shin</child>
      <parent>front_right_thigh</parent>
      <axis>
        <xyz>0 -1 0</xyz>
        <limit>
          <lower>-3.14159</lower>
          <upper>3.14159</upper>
          <effort>1000</effort>
          <velocity>100</velocity>
        </limit>
        <dynamics/>
      </axis>
    </joint>
    <link name='hind_left_hip'>
      <pose>-0.04 0.2 0 0 0 0</pose>
      <inertial>
        <pose>-0.1 0 0 0 0 0</pose>
        <mass>2</mass>
        <inertia>
          <ixx>0.006</ixx>
          <ixy>-4e-05</ixy>
          <ixz>0.004</ixz>
          <iyy>0.025</iyy>
          <iyz>-4e-06</iyz>
          <izz>0.02</izz>
        </inertia>
      </inertial>
      <visual name='hind_left_hip_visual'>
        <pose>0 0 0.04 0 1.57075 0</pose>
        <geometry>
          <mesh>
            <scale>1 1 1</scale>
            <uri>model://lla_quadruped_description/model/meshes/lla_5A0-binary.obj</uri>
          </mesh>
        </geometry>
      </visual>
    </link>
    <joint name='hind_left_hip_roll' type='revolute'>
      <child>hind_left_hip</child>
      <parent>body</parent>
      <axis>
        <xyz>1 0 0</xyz>
        <limit>
          <lower>-3.14159</lower>
          <upper>3.14159</upper>
          <effort>1000</effort>
          <velocity>100</velocity>
        </limit>
        <dynamics/>
      </axis>
    </joint>
    <link name='hind_left_thigh'>
      <pose>-0.24 0.27 0 0 0 0</pose>
      <inertial>
        <pose>0.1 0 0 0 0 0</pose>
        <mass>2</mass>
        <inertia>
          <ixx>0.006</ixx>
          <ixy>-4e-05</ixy>
          <ixz>0.004</ixz>
          <iyy>0.025</iyy>
          <iyz>-4e-06</iyz>
          <izz>0.02</izz>
        </inertia>
      </inertial>
      <visual name='hind_left_thigh_visual'>
        <pose>0 0 0 0 0 3.14159</pose>
        <geometry>
          <mesh>
            <scale>1 1 1</scale>
            <uri>model://lla_quadruped_description/model/meshes/lla_5A0-binary.obj</uri>
          </mesh>
        </geometry>
      </visual>
    </link>
    <joint name='hind_left_hip_pitch' type='revolute'>
      <child>hind_left_thigh</child>
      <parent>hind_left_hip</parent>
      <axis>
        <xyz>0 -1 0</xyz>
        <limit>
          <lower>-3.14159</lower>
          <upper>3.14159</upper>
          <effort>1000</effort>
          <velocity>100</velocity>
        </limit>
        <dynamics/>
      </axis>
    </joint>
    <link name='hind_left_shin'>
      <pose>-0.24 0.27 -0.2 0 0 0</pose>
      <inertial>
        <pose>0 0 -0.1 0 0 0</pose>
        <mass>0.5</mass>
        <inertia>
          <ixx>0.005</ixx>
          <ixy>-1e-06</ixy>
          <ixz>0.0006</ixz>
          <iyy>0.005</iyy>
          <iyz>-1e-06</iyz>
          <izz>0.0005</izz>
        </inertia>
      </inertial>
      <visual name='hind_left_shin_visual'>
        <pose>0 0 -0.1 0 0 0</pose>
        <geometry>
          <box>
            <size>0.01 0.01 0.19</size>
          </box>
        </geometry>
      </visual>
    </link>
    <joint name='hind_left_knee_pitch' type='revolute'>
      <child>hind_left_shin</child>
      <parent>hind_left_thigh</parent>
      <axis>
        <xyz>0 -1 0</xyz>
        <limit>
          <lower>-3.14159</lower>
          <upper>3.14159</upper>
          <effort>1000</effort>
          <velocity>100</velocity>
        </limit>
        <dynamics/>
      </axis>
    </joint>
    <link name='hind_right_hip'>
      <pose>-0.04 -0.2 0 0 0 0</pose>
      <inertial>
        <pose>-0.1 0 0 0 0 0</pose>
        <mass>2</mass>
        <inertia>
          <ixx>0.006</ixx>
          <ixy>-4e-05</ixy>
          <ixz>0.004</ixz>
          <iyy>0.025</iyy>
          <iyz>-4e-06</iyz>
          <izz>0.02</izz>
        </inertia>
      </inertial>
      <visual name='hind_right_hip_visual'>
        <pose>0 0 0.04 0 1.57075 0</pose>
        <geometry>
          <mesh>
            <scale>1 1 1</scale>
            <uri>model://lla_quadruped_description/model/meshes/lla_5A0-binary.obj</uri>
          </mesh>
        </geometry>
      </visual>
    </link>
    <joint name='hind_right_hip_roll' type='revolute'>
      <child>hind_right_hip</child>
      <parent>body</parent>
      <axis>
        <xyz>1 0 0</xyz>
        <limit>
          <lower>-3.14159</lower>
          <upper>3.14159</upper>
          <effort>1000</effort>
          <velocity>100</velocity>
        </limit>
        <dynamics/>
      </axis>
    </joint>
    <link name='hind_right_thigh'>
      <pose>-0.24 -0.27 0 0 0 0</pose>
      <inertial>
        <pose>0.1 0 0 0 0 0</pose>
        <mass>2</mass>
        <inertia>
          <ixx>0.006</ixx>
          <ixy>-4e-05</ixy>
          <ixz>0.004</ixz>
          <iyy>0.025</iyy>
          <iyz>-4e-06</iyz>
          <izz>0.02</izz>
        </inertia>
      </inertial>
      <visual name='hind_right_thigh_visual'>
        <pose>0 0 0 0 0 3.14159</pose>
        <geometry>
          <mesh>
            <scale>1 1 1</scale>
            <uri>model://lla_quadruped_description/model/meshes/lla_5A0-binary.obj</uri>
          </mesh>
        </geometry>
      </visual>
    </link>
    <joint name='hind_right_hip_pitch' type='revolute'>
      <child>hind_right_thigh</child>
      <parent>hind_right_hip</parent>
      <axis>
        <xyz>0 -1 0</xyz>
        <limit>
          <lower>-3.14159</lower>
          <upper>3.14159</upper>
          <effort>1000</effort>
          <velocity>100</velocity>
        </limit>
        <dynamics/>
      </axis>
    </joint>
    <link name='hind_right_shin'>
      <pose>-0.24 -0.27 -0.2 0 0 0</pose>
      <inertial>
        <pose>0 0 -0.1 0 0 0</pose>
        <mass>0.5</mass>
        <inertia>
          <ixx>0.005</ixx>
          <ixy>-1e-06</ixy>
          <ixz>0.0006</ixz>
          <iyy>0.005</iyy>
          <iyz>-1e-06</iyz>
          <izz>0.0005</izz>
        </inertia>
      </inertial>
      <visual name='hind_right_shin_visual'>
        <pose>0 0 -0.1 0 0 0</pose>
        <geometry>
          <box>
            <size>0.01 0.01 0.19</size>
          </box>
        </geometry>
      </visual>
    </link>
    <joint name='hind_right_knee_pitch' type='revolute'>
      <child>hind_right_shin</child>
      <parent>hind_right_thigh</parent>
      <axis>
        <xyz>0 -1 0</xyz>
        <limit>
          <lower>-3.14159</lower>
          <upper>3.14159</upper>
          <effort>1000</effort>
          <velocity>100</velocity>
        </limit>
        <dynamics/>
      </axis>
    </joint>
  </model>
</sdf>