<?xml version="1.0" ?>
<!-- =================================================================================== -->
<!-- |    This document was autogenerated by xacro from robots/drc_no_hands.urdf.xacro | -->
<!-- |    EDITING THIS FILE BY HAND IS NOT RECOMMENDED                                 | -->
<!-- =================================================================================== -->
<robot name="atlas" xmlns:xacro="http://www.ros.org/wiki/xacro">
  <link name="l_clav">
    <inertial>
      <mass value="3.45"/>
      <origin rpy="0 -0 0" xyz="0 0.048 0.084"/>
      <inertia ixx="0.011" ixy="0" ixz="0" iyy="0.009" iyz="-0.004" izz="0.004"/>
    </inertial>
    <visual>
      <origin rpy="0 -0 0" xyz="0 0 0"/>
      <geometry>
        <mesh filename="package://atlas_description/meshes_v3/l_clav.DAE" scale="1 1 1"/>
      </geometry>
    </visual>
    <collision group="default">
      <origin rpy="0 1.5707963267949 0" xyz="0 0.14 0.20"/>
      <geometry>
        <cylinder length="0.1525" radius="0.045"/>
      </geometry>
    </collision>
    <collision group="other">
      <origin rpy="1.0472 0 0" xyz="-0.005 +0.07 +0.15"/>
      <geometry>
        <box size="0.13 0.15 0.1"/>
      </geometry>
    </collision>
  </link>
  <link name="l_farm">
    <inertial>
      <mass value="3.388"/>
      <origin rpy="0 -0 0" xyz="0 -0.065 0"/>
      <inertia ixx="0.00656" ixy="0" ixz="0" iyy="0.00358" iyz="0" izz="0.00656"/>
    </inertial>
    <visual>
      <origin rpy="0 -0 0" xyz="0 0 0"/>
      <geometry>
        <mesh filename="package://atlas_description/meshes_v3/l_farm.DAE" scale="1 1 1"/>
      </geometry>
    </visual>
    <collision group="default">
      <origin rpy="0 1.5708 0" xyz="0.0 0.120 0.004"/>
      <geometry>
        <cylinder length="0.125" radius="0.045"/>
      </geometry>
    </collision>
    <collision group="other">
      <origin rpy="0 0 0" xyz="0.001 0.035 -0.002"/>
      <geometry>
        <box size="0.135 0.1 0.045"/>
      </geometry>
    </collision>
  </link>
  <link name="l_foot">
    <inertial>
      <mass value="2.05"/>
      <origin rpy="0 -0 0" xyz="0.027 0 -0.067"/>
      <inertia ixx="0.002" ixy="0" ixz="0" iyy="0.007" iyz="0" izz="0.008"/>
    </inertial>
    <visual>
      <origin rpy="0 -0 0" xyz="0 0 0"/>
      <geometry>
        <mesh filename="package://atlas_description/meshes_v3/l_foot.DAE" scale="1 1 1"/>
      </geometry>
    </visual>
    <!-- bottom -->
    <collision group="default">
      <origin rpy="0 0 0" xyz="0.048 0 -0.056119"/>
      <geometry>
        <box size="0.26 0.124887 0.05"/>
      </geometry>
    </collision>
    <!-- ankle FIXME: adding this collision body destabilizes robot, shouldn't
        <collision group="other">
          <origin xyz="0.0 0 -0.0528735" rpy="0 0 0"/>
          <geometry>
            <cylinder radius="0.0373" length="0.037827"/>
          </geometry>
        </collision>
        -->
  </link>
  <link name="l_hand">
    <inertial>
      <mass value="2.509"/>
      <origin rpy="0 -0 0" xyz="0 0 0"/>
      <inertia ixx="0.00265" ixy="0" ixz="0" iyy="0.00446" iyz="0" izz="0.00446"/>
    </inertial>
    <visual>
      <origin rpy="3.14159 3.14159 0" xyz="0 0 0"/>
      <geometry>
        <mesh filename="package://atlas_description/meshes_v3/r_hand.DAE" scale="1 1 1"/>
      </geometry>
    </visual>
    <collision group="default">
      <origin rpy="1.5707963267949 0 0" xyz="0.001 0.1 0.01"/>
      <geometry>
        <cylinder length="0.05" radius="0.03"/>
      </geometry>
    </collision>
    <collision group="other">
      <origin rpy="0 0 0" xyz="0.001 0.05 0.01"/>
      <geometry>
        <box size="0.13 0.09 0.07"/>
      </geometry>
    </collision>
    <!-- blob -->
    <collision group="default">
      <origin rpy="1.570795  0 0" xyz="0.00 0.25 0.00"/>
      <geometry>
        <cylinder length="0.30" radius="0.15"/>
      </geometry>
    </collision>

  </link>
  <link name="l_larm">
    <inertial>
      <mass value="2.509"/>
      <origin rpy="0 -0 0" xyz="0 0 0"/>
      <inertia ixx="0.00265" ixy="0" ixz="0" iyy="0.00446" iyz="0" izz="0.00446"/>
    </inertial>
    <visual>
      <origin rpy="0 -0 0" xyz="0 0 0"/>
      <geometry>
        <mesh filename="package://atlas_description/meshes_v3/l_elbow_rx.DAE" scale="1 1 1"/>
      </geometry>
    </visual>
    <collision group="default">
      <origin rpy="1.5707963267949 0 0" xyz="0.001 0.127 -0.005"/>
      <geometry>
        <cylinder length="0.125" radius="0.05"/>
      </geometry>
    </collision>
    <collision group="other">
      <origin rpy="0 0 0" xyz="0.001 0.051 +0.01"/>
      <geometry>
        <box size="0.135 0.16 0.07"/>
      </geometry>
    </collision>
  </link>
  <link name="l_lglut">
    <inertial>
      <mass value="0.866"/>
      <origin rpy="0 -0 0" xyz="0.0133341 0.0170484 -0.0312052"/>
      <inertia ixx="0.000691326" ixy="-2.24344e-05" ixz="2.50508e-06" iyy="0.00126856" iyz="0.000137862" izz="0.00106487"/>
    </inertial>
    <visual>
      <origin rpy="0 -0 0" xyz="0 0 0"/>
      <geometry>
        <mesh filename="package://atlas_description/meshes_v3/l_lglut.DAE" scale="1 1 1"/>
      </geometry>
    </visual>
    <collision group="default">
      <origin rpy="1.5707963267949 0 0" xyz="0.049968 0.022488 -0.0501165"/>
      <geometry>
        <cylinder length="0.060306" radius="0.02009687"/>
      </geometry>
    </collision>
    <collision group="other">
      <origin rpy="0 1.5707963267949 0" xyz="0 0 0"/>
      <geometry>
        <cylinder length="0.12" radius="0.02"/>
      </geometry>
    </collision>
  </link>
  <link name="l_lleg">
    <inertial>
      <mass value="5.479"/>
      <origin rpy="0 -0 0" xyz="0.001 0 -0.187"/>
      <inertia ixx="0.077" ixy="0" ixz="-0.003" iyy="0.076" iyz="0" izz="0.01"/>
    </inertial>
    <visual>
      <origin rpy="0 -0 0" xyz="0 0 0"/>
      <geometry>
        <mesh filename="package://atlas_description/meshes_v3/l_lleg.DAE" scale="1 1 1"/>
      </geometry>
    </visual>
    <collision group="default">
      <origin rpy="0 0.10 0" xyz="0.02 0.00295 -0.22"/>
      <geometry>
        <cylinder length="0.50" radius="0.07"/>
      </geometry>
    </collision>
  </link>
  <link name="l_scap">
    <inertial>
      <mass value="3.012"/>
      <origin rpy="0 -0 0" xyz="0 0 0"/>
      <inertia ixx="0.00319" ixy="0" ixz="0" iyy="0.00583" iyz="0" izz="0.00583"/>
    </inertial>
    <visual>
      <origin rpy="0 -0 0" xyz="0 0 0"/>
      <geometry>
        <mesh filename="package://atlas_description/meshes_v3/l_sh_rx.DAE" scale="1 1 1"/>
      </geometry>
    </visual>
    <collision group="default">
      <origin rpy="1.5707963267949 0 0" xyz="0.001 0.12651 0.01521"/>
      <geometry>
        <cylinder length="0.125" radius="0.045"/>
      </geometry>
    </collision>
    <collision group="other">
      <origin rpy="0 0 0" xyz="0.001 0.05 0.016"/>
      <geometry>
        <box size="0.15 0.15 0.06"/>
      </geometry>
    </collision>
  </link>
  <link name="l_talus">
    <inertial>
      <mass value="0.125"/>
      <origin rpy="0 -0 0" xyz="0 0 0"/>
      <inertia ixx="1.01674e-05" ixy="0" ixz="0" iyy="8.42775e-06" iyz="0" izz="1.30101e-05"/>
    </inertial>
    <visual>
      <origin rpy="0 -0 0" xyz="0 0 0"/>
      <geometry>
        <mesh filename="package://atlas_description/meshes_v3/l_talus.DAE" scale="1 1 1"/>
      </geometry>
    </visual>
    <collision group="default">
      <origin rpy="0 1.5707963267949 0" xyz="0 0 0"/>
      <geometry>
        <cylinder length="0.029542" radius="0.010181"/>
      </geometry>
    </collision>
    <collision group="other">
      <origin rpy="1.5707963267949 0 0" xyz="0 0 0"/>
      <geometry>
        <cylinder length="0.010059" radius="0.010348"/>
      </geometry>
    </collision>
  </link>
  <link name="l_uarm">
    <inertial>
      <mass value="3.388"/>
      <origin rpy="0 -0 0" xyz="0 -0.065 0"/>
      <inertia ixx="0.00656" ixy="0" ixz="0" iyy="0.00358" iyz="0" izz="0.00656"/>
    </inertial>
    <visual>
      <origin rpy="0 -0 0" xyz="0 0 0"/>
      <geometry>
        <mesh filename="package://atlas_description/meshes_v3/l_elbow_ry.DAE" scale="1 1 1"/>
      </geometry>
    </visual>
    <collision group="default">
      <origin rpy="0 1.5708 0" xyz="0.001 0.111 0.0"/>
      <geometry>
        <cylinder length="0.125" radius="0.045"/>
      </geometry>
    </collision>
    <collision group="other">
      <origin rpy="0 1.5707963267949 0" xyz="0.001 0.043 0.01"/>
      <geometry>
        <box size="0.04 0.07 0.13"/>
      </geometry>
    </collision>
  </link>
  <link name="l_uglut">
    <inertial>
      <mass value="0.648"/>
      <origin rpy="0 -0 0" xyz="0.00529262 -0.00344732 0.00313046"/>
      <inertia ixx="0.00074276" ixy="-3.79607e-08" ixz="-2.79549e-05" iyy="0.000688179" iyz="-3.2735e-08" izz="0.00041242"/>
    </inertial>
    <visual>
      <origin rpy="0 -0 0" xyz="0 0 0"/>
      <geometry>
        <mesh filename="package://atlas_description/meshes_v3/l_uglut.DAE" scale="1 1 1"/>
      </geometry>
    </visual>
    <collision group="default">
      <origin rpy="0 1.5707963267949 0" xyz="0 0 0"/>
      <geometry>
        <cylinder length="0.078396" radius="0.019096"/>
      </geometry>
    </collision>
    <collision group="other">
      <origin rpy="0 0 0" xyz="0 0 0"/>
      <geometry>
        <cylinder length="0.080842" radius="0.019841"/>
      </geometry>
    </collision>
  </link>
  <link name="l_uleg">
    <inertial>
      <mass value="9.209"/>
      <origin rpy="0 -0 0" xyz="0 0 -0.21"/>
      <inertia ixx="0.09" ixy="0" ixz="0" iyy="0.09" iyz="0" izz="0.02"/>
    </inertial>
    <visual>
      <origin rpy="0 -0 0" xyz="0 0 0"/>
      <geometry>
        <mesh filename="package://atlas_description/meshes_v3/l_uleg.DAE" scale="1 1 1"/>
      </geometry>
    </visual>
    <collision group="default">
      <origin rpy="0 0 0" xyz="-0.0179 0.02085 -0.10"/>
      <geometry>
        <cylinder length="0.25" radius="0.11"/>
      </geometry>
    </collision>
    <collision group="other">
      <origin rpy="0 -0.3 0" xyz="-0.03 0.01 -0.24"/>
      <geometry>
        <cylinder length="0.20" radius="0.10"/>
      </geometry>
    </collision>
    <collision group="other">
      <origin rpy="0 0.3 0" xyz="-0.005 0.01 -0.24"/>
      <geometry>
        <cylinder length="0.20" radius="0.10"/>
      </geometry>
    </collision>
    <collision group="other">
      <origin rpy="-0.25 0 0" xyz="-0.02 0.03 -0.24"/>
      <geometry>
        <cylinder length="0.20" radius="0.10"/>
      </geometry>
    </collision>
  </link>
  <link name="ltorso">
    <inertial>
      <mass value="2.409"/>
      <origin rpy="0 -0 0" xyz="-0.0112984 -3.15366e-06 0.0746835"/>
      <inertia ixx="0.0039092" ixy="-5.04491e-08" ixz="-0.000342157" iyy="0.00341694" iyz="4.87119e-07" izz="0.00174492"/>
    </inertial>
    <visual>
      <origin rpy="0 -0 0" xyz="0 0 0"/>
      <geometry>
        <mesh filename="package://atlas_description/meshes_v3/ltorso.DAE" scale="1 1 1"/>
      </geometry>
    </visual>
    <!-- this part is completely internal
        <collision group="default">
          <origin rpy="0 0 0" xyz="0 0 0.039762"/>
          <geometry>
            <cylinder radius="0.025918" length="0.076922"/>
          </geometry>
        </collision>
        <collision group="other">
          <origin rpy="1.5707963267949 0 0" xyz="0 0.0250065 0.09025"/>
          <geometry>
            <cylinder radius="0.014828" length="0.020367"/>
          </geometry>
        </collision>
        <collision group="other">
          <origin rpy="1.5707963267949 0 0" xyz="0 -0.0248895 0.09025"/>
          <geometry>
            <cylinder radius="0.014828" length="0.020169"/>
          </geometry>
        </collision>
        -->
  </link>
  <link name="mtorso">
    <inertial>
      <mass value="0.69"/>
      <origin rpy="0 -0 0" xyz="-0.00816266 -0.0131245 0.0305974"/>
      <inertia ixx="0.000454181" ixy="-6.10764e-05" ixz="3.94009e-05" iyy="0.000483282" iyz="5.27463e-05" izz="0.000444215"/>
    </inertial>
    <visual>
      <origin rpy="0 -0 0" xyz="0 0 0"/>
      <geometry>
        <mesh filename="package://atlas_description/meshes_v3/mtorso.DAE" scale="1 1 1"/>
      </geometry>
    </visual>
    <collision group="default">
      <origin rpy="0 0 0" xyz="0 0 0.05"/>
      <geometry>
        <cylinder length="0.15" radius="0.05"/>
      </geometry>
    </collision>
  </link>
  <link name="pelvis">
    <inertial>
      <mass value="17.882"/>
      <origin rpy="0 -0 0" xyz="0.0111 0 0.0271"/>
      <inertia ixx="0.1244" ixy="0.0008" ixz="-0.0007" iyy="0.0958" iyz="-0.0005" izz="0.1167"/>
    </inertial>
    <visual>
      <origin rpy="0 -0 0" xyz="0 0 0"/>
      <geometry>
        <mesh filename="package://atlas_description/meshes_v3/pelvis.DAE" scale="1 1 1"/>
      </geometry>
    </visual>
    <!--butt -->
    <collision group="default">
      <origin rpy="1.5707963267949 0 0" xyz="0.046 0.0 -0.02"/>
      <geometry>
        <cylinder length="0.40" radius="0.13"/>
      </geometry>
    </collision>
    <collision group="other">
      <origin rpy="1.5707963267949 0 0" xyz="-0.03 0.0 -0.02"/>
      <geometry>
        <cylinder length="0.40" radius="0.13"/>
      </geometry>
    </collision>
    <!--vertical cylinders-->
    <collision group="other">
      <origin rpy="0 0 0" xyz="0.01 0.042 0.09"/>
      <geometry>
        <cylinder length="0.15" radius="0.18"/>
      </geometry>
    </collision>
    <collision group="other">
      <origin rpy="0 0 0" xyz="0.01 -0.042 0.09"/>
      <geometry>
        <cylinder length="0.15" radius="0.18"/>
      </geometry>
    </collision>
    <!--butt-->
    <collision group="other">
      <origin rpy="0 0 0" xyz="-0.1 0 -0.05"/>
      <geometry>
        <box size="0.12 0.15 0.2"/>
      </geometry>
    </collision>
  </link>
  <link name="r_clav">
    <inertial>
      <mass value="3.45"/>
      <origin rpy="0 -0 0" xyz="0 -0.048 0.084"/>
      <inertia ixx="0.011" ixy="0" ixz="0" iyy="0.009" iyz="0.004" izz="0.004"/>
    </inertial>
    <visual>
      <origin rpy="0 -0 0" xyz="0 0 0"/>
      <geometry>
        <mesh filename="package://atlas_description/meshes_v3/r_clav.DAE" scale="1 1 1"/>
      </geometry>
    </visual>
    <collision group="default">
      <origin rpy="0 1.5707963267949 0" xyz="0 -0.14 0.20"/>
      <geometry>
        <cylinder length="0.1525" radius="0.045"/>
      </geometry>
    </collision>
    <collision group="other">
      <origin rpy="-1.0472 0 0" xyz="-0.005 -0.07  +0.15"/>
      <geometry>
        <box size="0.13 0.15 0.1 "/>
      </geometry>
    </collision>
  </link>
  <link name="r_farm">
    <inertial>
      <mass value="3.388"/>
      <origin rpy="0 -0 0" xyz="0 0.065 0"/>
      <inertia ixx="0.00656" ixy="0" ixz="0" iyy="0.00358" iyz="0" izz="0.00656"/>
    </inertial>
    <visual>
      <origin rpy="0 -0 0" xyz="0 0 0"/>
      <geometry>
        <mesh filename="package://atlas_description/meshes_v3/r_farm.DAE" scale="1 1 1"/>
      </geometry>
    </visual>
    <collision group="default">
      <origin rpy="0 1.5708 0" xyz="0.0 -0.120 0.004"/>
      <geometry>
        <cylinder length="0.125" radius="0.045"/>
      </geometry>
    </collision>
    <collision group="other">
      <origin rpy="0 0 0" xyz="0.001 -0.035 -0.002"/>
      <geometry>
        <box size="0.135 0.1 0.045"/>
      </geometry>
    </collision>
  </link>
  <link name="r_foot">
    <inertial>
      <mass value="2.05"/>
      <origin rpy="0 -0 0" xyz="0.027 0 -0.067"/>
      <inertia ixx="0.002" ixy="0" ixz="0" iyy="0.007" iyz="0" izz="0.008"/>
    </inertial>
    <visual>
      <origin rpy="0 -0 0" xyz="0 0 0"/>
      <geometry>
        <mesh filename="package://atlas_description/meshes_v3/r_foot.DAE" scale="1 1 1"/>
      </geometry>
    </visual>
    <!-- bottom -->
    <collision group="default">
      <origin rpy="0 0 0" xyz="0.048 0 -0.056119"/>
      <geometry>
        <box size="0.26 0.124887 0.05"/>
      </geometry>
    </collision>
    <!-- ankle FIXME: adding this collision body destabilizes robot, shouldn't
        <collision group="other">
          <origin xyz="0.0 0 -0.0528735" rpy="0 0 0"/>
          <geometry>
            <cylinder radius="0.0373" length="0.037827"/>
          </geometry>
        </collision>
        -->
  </link>
  <link name="r_hand">
    <inertial>
      <mass value="2.509"/>
      <origin rpy="0 -0 0" xyz="0 0 0"/>
      <inertia ixx="0.00265" ixy="0" ixz="0" iyy="0.00446" iyz="0" izz="0.00446"/>
    </inertial>
    <visual>
      <origin rpy="0 3.14159 0" xyz="0 0 0"/>
      <geometry>
        <mesh filename="package://atlas_description/meshes_v3/r_hand.DAE" scale="1 1 1"/>
      </geometry>
    </visual>
    <collision group="default">
      <origin rpy="1.5707963267949 0 0" xyz="0.001 -0.1 -0.01"/>
      <geometry>
        <cylinder length="0.05" radius="0.03"/>
      </geometry>
    </collision>
    <collision group="other">
      <origin rpy="0 0 0" xyz="0.001 -0.05 -0.01"/>
      <geometry>
        <box size="0.13 0.09 0.07"/>
      </geometry>
    </collision>

    <!-- blob -->
    <collision group="default">
      <origin rpy="1.570795  0 0" xyz="0.00 -0.25 0.00"/>
      <geometry>
        <cylinder length="0.30" radius="0.15"/>
      </geometry>
    </collision>
  </link>
  <link name="r_larm">
    <inertial>
      <mass value="2.509"/>
      <origin rpy="0 -0 0" xyz="0 0 0"/>
      <inertia ixx="0.00265" ixy="0" ixz="0" iyy="0.00446" iyz="0" izz="0.00446"/>
    </inertial>
    <visual>
      <origin rpy="0 -0 0" xyz="0 0 0"/>
      <geometry>
        <mesh filename="package://atlas_description/meshes_v3/r_elbow_rx.DAE" scale="1 1 1"/>
      </geometry>
    </visual>
    <collision group="default">
      <origin rpy="1.5707963267949 0 0" xyz="0.001 -0.127 -0.005"/>
      <geometry>
        <cylinder length="0.125" radius="0.05"/>
      </geometry>
    </collision>
    <collision group="other">
      <origin rpy="0 0 0" xyz="0.001 -0.051 -0.01"/>
      <geometry>
        <box size="0.135 0.16 0.07"/>
      </geometry>
    </collision>
  </link>
  <link name="r_lglut">
    <inertial>
      <mass value="0.866"/>
      <origin rpy="0 -0 0" xyz="0.0133341 -0.0170484 -0.0312052"/>
      <inertia ixx="0.000691326" ixy="2.24344e-05" ixz="2.50508e-06" iyy="0.00126856" iyz="-0.000137862" izz="0.00106487"/>
    </inertial>
    <visual>
      <origin rpy="0 -0 0" xyz="0 0 0"/>
      <geometry>
        <mesh filename="package://atlas_description/meshes_v3/r_lglut.DAE" scale="1 1 1"/>
      </geometry>
    </visual>
    <collision group="default">
      <origin rpy="1.5707963267949 0 0" xyz="0.049968 -0.022488 -0.0501165"/>
      <geometry>
        <cylinder length="0.060306" radius="0.02009687"/>
      </geometry>
    </collision>
    <collision group="other">
      <origin rpy="0 1.5707963267949 0" xyz="0 0 0"/>
      <geometry>
        <cylinder length="0.12" radius="0.02"/>
      </geometry>
    </collision>
  </link>
  <link name="r_lleg">
    <inertial>
      <mass value="5.479"/>
      <origin rpy="0 -0 0" xyz="0.001 0 -0.187"/>
      <inertia ixx="0.077" ixy="-0" ixz="-0.003" iyy="0.076" iyz="-0" izz="0.01"/>
    </inertial>
    <visual>
      <origin rpy="0 -0 0" xyz="0 0 0"/>
      <geometry>
        <mesh filename="package://atlas_description/meshes_v3/r_lleg.DAE" scale="1 1 1"/>
      </geometry>
    </visual>
    <collision group="default">
      <origin rpy="0 0.10 0" xyz="0.02 -0.00295 -0.22"/>
      <geometry>
        <cylinder length="0.50" radius="0.07"/>
      </geometry>
    </collision>
  </link>
  <link name="r_scap">
    <inertial>
      <mass value="3.012"/>
      <origin rpy="0 -0 0" xyz="0 0 0"/>
      <inertia ixx="0.00319" ixy="0" ixz="0" iyy="0.00583" iyz="0" izz="0.00583"/>
    </inertial>
    <visual>
      <origin rpy="0 -0 0" xyz="0 0 0"/>
      <geometry>
        <mesh filename="package://atlas_description/meshes_v3/r_sh_rx.DAE" scale="1 1 1"/>
      </geometry>
    </visual>
    <collision group="default">
      <origin rpy="1.5707963267949 0 0" xyz="0.001 -0.12651 0.01521"/>
      <geometry>
        <cylinder length="0.155" radius="0.045"/>
      </geometry>
    </collision>
    <collision group="other">
      <origin rpy="0 0 0" xyz="0.001 -0.05 0.016"/>
      <geometry>
        <box size="0.15 0.15 0.06"/>
      </geometry>
    </collision>
  </link>
  <link name="r_talus">
    <inertial>
      <mass value="0.125"/>
      <origin rpy="0 -0 0" xyz="0 0 0"/>
      <inertia ixx="1.01674e-05" ixy="0" ixz="0" iyy="8.42775e-06" iyz="0" izz="1.30101e-05"/>
    </inertial>
    <visual>
      <origin rpy="0 -0 0" xyz="0 0 0"/>
      <geometry>
        <mesh filename="package://atlas_description/meshes_v3/r_talus.DAE" scale="1 1 1"/>
      </geometry>
    </visual>
    <collision group="default">
      <origin rpy="0 1.5707963267949 0" xyz="0 0 0"/>
      <geometry>
        <cylinder length="0.029542" radius="0.010181"/>
      </geometry>
    </collision>
    <collision group="other">
      <origin rpy="1.5707963267949 0 0" xyz="0 0 0"/>
      <geometry>
        <cylinder length="0.010059" radius="0.010348"/>
      </geometry>
    </collision>
  </link>
  <link name="r_uarm">
    <inertial>
      <mass value="3.388"/>
      <origin rpy="0 -0 0" xyz="0 0.065 0"/>
      <inertia ixx="0.00656" ixy="0" ixz="0" iyy="0.00358" iyz="0" izz="0.00656"/>
    </inertial>
    <visual>
      <origin rpy="0 -0 0" xyz="0 0 0"/>
      <geometry>
        <mesh filename="package://atlas_description/meshes_v3/r_elbow_ry.DAE" scale="1 1 1"/>
      </geometry>
    </visual>
    <collision group="default">
      <origin rpy="0 1.5708 0" xyz="0.001 -0.111 0.0"/>
      <geometry>
        <cylinder length="0.125" radius="0.045"/>
      </geometry>
    </collision>
    <collision group="other">
      <origin rpy="0 1.5707963267949 0" xyz="0.001 -0.043 0.01"/>
      <geometry>
        <box size="0.04 0.07 0.13"/>
      </geometry>
    </collision>
  </link>
  <link name="r_uglut">
    <inertial>
      <mass value="0.648"/>
      <origin rpy="0 -0 0" xyz="0.00529262 0.00344732 0.00313046"/>
      <inertia ixx="0.00074276" ixy="3.79607e-08" ixz="-2.79549e-05" iyy="0.000688179" iyz="3.2735e-08" izz="0.00041242"/>
    </inertial>
    <visual>
      <origin rpy="0 -0 0" xyz="0 0 0"/>
      <geometry>
        <mesh filename="package://atlas_description/meshes_v3/r_uglut.DAE" scale="1 1 1"/>
      </geometry>
    </visual>
    <collision group="default">
      <origin rpy="0 1.5707963267949 0" xyz="0 0 0"/>
      <geometry>
        <cylinder length="0.078396" radius="0.019096"/>
      </geometry>
    </collision>
    <collision group="other">
      <origin rpy="0 0 0" xyz="0 0 0"/>
      <geometry>
        <cylinder length="0.080842" radius="0.019841"/>
      </geometry>
    </collision>
  </link>
  <link name="r_uleg">
    <inertial>
      <mass value="9.209"/>
      <origin rpy="0 -0 0" xyz="0 0 -0.21"/>
      <inertia ixx="0.09" ixy="0" ixz="0" iyy="0.09" iyz="0" izz="0.02"/>
    </inertial>
    <visual>
      <origin rpy="0 -0 0" xyz="0 0 0"/>
      <geometry>
        <mesh filename="package://atlas_description/meshes_v3/r_uleg.DAE" scale="1 1 1"/>
      </geometry>
    </visual>
    <collision group="default">
      <origin rpy="0 0 0" xyz="-0.0179 -0.02085 -0.10"/>
      <geometry>
        <cylinder length="0.25" radius="0.11"/>
      </geometry>
    </collision>
    <collision group="other">
      <origin rpy="0 -0.3 0" xyz="-0.03 -0.01 -0.24"/>
      <geometry>
        <cylinder length="0.20" radius="0.1"/>
      </geometry>
    </collision>
    <collision group="other">
      <origin rpy="0 0.3 0" xyz="-0.005 -0.01 -0.24"/>
      <geometry>
        <cylinder length="0.20" radius="0.1"/>
      </geometry>
    </collision>
    <collision group="other">
      <origin rpy="0.25 0 0" xyz="-0.02 -0.03 -0.24"/>
      <geometry>
        <cylinder length="0.20" radius="0.1"/>
      </geometry>
    </collision>
  </link>
  <link name="utorso">
    <inertial>
      <mass value="66.907"/>
      <origin rpy="0 -0 0" xyz="-0.0923 0 0.3"/>
      <inertia ixx="1.466" ixy="0.00362" ixz="0.336" iyy="1.51" iyz="0.001" izz="1.3"/>
    </inertial>
    <visual>
      <origin rpy="0 -0 0" xyz="0 0 0"/>
      <geometry>
        <mesh filename="package://atlas_description/meshes_v3/utorso.DAE" scale="1 1 1"/>
      </geometry>
    </visual>
    <collision group="default">
      <origin rpy="0 -0 0" xyz="0.06 0 0.1869"/>
      <geometry>
        <box size="0.32 0.35 0.3162"/>
      </geometry>
    </collision>
    <!--backpack-->
    <collision group="default">
      <origin rpy="0 -0 0" xyz="-0.23 0 0.33"/>
      <geometry>
        <box size="0.23 0.39 0.61"/>
      </geometry>
    </collision>
    <!--head-->
    <collision group="default">
      <origin rpy="0 -1.57 0" xyz="0.06 0 0.42"/>
      <geometry>
        <cylinder length="0.40" radius="0.15"/>
      </geometry>
    </collision>
    <collision group="default">
      <origin rpy="0 -1.57 0" xyz="0.07 0 0.56"/>
      <geometry>
        <cylinder length="0.40" radius="0.18"/>
      </geometry>
    </collision>
    <collision group="other">
      <origin rpy="-0.5236 0 0" xyz="0.06 0.16 0.14"/>
      <geometry>
        <cylinder length="0.22375" radius="0.05"/>
      </geometry>
    </collision>
    <collision group="other">
      <origin rpy="0.5236 0 0" xyz="0.06 -0.16 0.14"/>
      <geometry>
        <cylinder length="0.22375" radius="0.05"/>
      </geometry>
    </collision>
    <visual>
      <origin rpy="0 -0 0" xyz="0 0 0"/>
      <geometry>
        <mesh filename="package://atlas_description/meshes_v3/utorso_pack.DAE" scale="1 1 1"/>
      </geometry>
    </visual>
  </link>
  <joint name="back_bkx" type="revolute">
    <origin rpy="0 -0 0" xyz="0 0 0.05"/>
    <axis xyz="1 0 0"/>
    <parent link="mtorso"/>
    <child link="utorso"/>
    <dynamics damping="0.1" friction="0"/>
    <limit effort="200" lower="-0.698132" upper="0.698132" velocity="12"/>
    <safety_controller k_position="100" k_velocity="100" soft_lower_limit="-10.6981" soft_upper_limit="10.6981"/>
  </joint>
  <joint name="back_bky" type="revolute">
    <origin rpy="0 -0 0" xyz="0 0 0.16197"/>
    <axis xyz="0 1 0"/>
    <parent link="ltorso"/>
    <child link="mtorso"/>
    <dynamics damping="0.1" friction="0"/>
    <limit effort="206.843" lower="-0.610691" upper="0.438427" velocity="12"/>
    <safety_controller k_position="100" k_velocity="100" soft_lower_limit="-10.6107" soft_upper_limit="10.4384"/>
  </joint>
  <joint name="back_bkz" type="revolute">
    <origin rpy="0 -0 0" xyz="-0.0125 0 0"/>
    <axis xyz="0 0 1"/>
    <parent link="pelvis"/>
    <child link="ltorso"/>
    <dynamics damping="0.1" friction="0"/>
    <limit effort="124.016" lower="-0.663225" upper="0.663225" velocity="12"/>
    <safety_controller k_position="100" k_velocity="100" soft_lower_limit="-10.6632" soft_upper_limit="10.6632"/>
  </joint>
  <joint name="l_arm_elx" type="revolute">
    <origin rpy="0 -0 0" xyz="0 0.119 0.00921"/>
    <axis xyz="1 0 0"/>
    <parent link="l_uarm"/>
    <child link="l_larm"/>
    <dynamics damping="0.1" friction="0"/>
    <limit effort="114" lower="0" upper="2.35619" velocity="12"/>
    <safety_controller k_position="100" k_velocity="100" soft_lower_limit="-10" soft_upper_limit="12.3562"/>
  </joint>
  <joint name="l_arm_ely" type="revolute">
    <origin rpy="0 -0 0" xyz="0 0.187 0.016"/>
    <axis xyz="0 1 0"/>
    <parent link="l_scap"/>
    <child link="l_uarm"/>
    <dynamics damping="0.1" friction="0"/>
    <limit effort="114" lower="0" upper="3.14159" velocity="12"/>
    <safety_controller k_position="100" k_velocity="100" soft_lower_limit="-10" soft_upper_limit="13.1416"/>
  </joint>
  <joint name="l_arm_shx" type="revolute">
    <origin rpy="0 -0 0" xyz="0 0.14035 0.19609"/>
    <axis xyz="1 0 0"/>
    <parent link="l_clav"/>
    <child link="l_scap"/>
    <dynamics damping="0.1" friction="0"/>
    <limit effort="170" lower="-1.5708" upper="1.5708" velocity="12"/>
    <safety_controller k_position="100" k_velocity="100" soft_lower_limit="-11.5708" soft_upper_limit="11.5708"/>
  </joint>
  <joint name="l_arm_shy" type="revolute">
    <origin rpy="0 -0 0" xyz="0.06441 0.13866 0.10718"/>
    <axis xyz="0 0.5 0.866025"/>
    <parent link="utorso"/>
    <child link="l_clav"/>
    <dynamics damping="0.1" friction="0"/>
    <limit effort="212" lower="-1.5708" upper="0.785398" velocity="12"/>
    <safety_controller k_position="100" k_velocity="100" soft_lower_limit="-11.5708" soft_upper_limit="10.7854"/>
  </joint>
  <joint name="l_arm_wrx" type="revolute">
    <origin rpy="0 -0 0" xyz="0 0.119 -0.00921"/>
    <axis xyz="1 0 0"/>
    <parent link="l_farm"/>
    <child link="l_hand"/>
    <dynamics damping="0.1" friction="0"/>
    <limit effort="60" lower="-1.1781" upper="1.1781" velocity="12"/>
    <safety_controller k_position="100" k_velocity="100" soft_lower_limit="-11.1781" soft_upper_limit="11.1781"/>
  </joint>
  <joint name="l_arm_wry" type="revolute">
    <origin rpy="0 -0 0" xyz="0 0.187 -0.00921"/>
    <axis xyz="0 1 0"/>
    <parent link="l_larm"/>
    <child link="l_farm"/>
    <dynamics damping="0.1" friction="0"/>
    <limit effort="114" lower="0" upper="3.14159" velocity="12"/>
    <safety_controller k_position="100" k_velocity="100" soft_lower_limit="-10" soft_upper_limit="13.1416"/>
  </joint>
  <joint name="l_leg_akx" type="revolute">
    <origin rpy="0 -0 0" xyz="0 0 0"/>
    <axis xyz="1 0 0"/>
    <parent link="l_talus"/>
    <child link="l_foot"/>
    <dynamics damping="0.1" friction="0"/>
    <limit effort="90" lower="-0.8" upper="0.8" velocity="12"/>
    <safety_controller k_position="100" k_velocity="100" soft_lower_limit="-10.8" soft_upper_limit="10.8"/>
  </joint>
  <joint name="l_leg_aky" type="revolute">
    <origin rpy="0 -0 0" xyz="0 0 -0.422"/>
    <axis xyz="0 1 0"/>
    <parent link="l_lleg"/>
    <child link="l_talus"/>
    <dynamics damping="0.1" friction="0"/>
    <limit effort="700" lower="-1" upper="0.7" velocity="12"/>
    <safety_controller k_position="100" k_velocity="100" soft_lower_limit="-11" soft_upper_limit="10.7"/>
  </joint>
  <joint name="l_leg_hpx" type="revolute">
    <origin rpy="0 -0 0" xyz="0 0 0"/>
    <axis xyz="1 0 0"/>
    <parent link="l_uglut"/>
    <child link="l_lglut"/>
    <dynamics damping="0.1" friction="0"/>
    <limit effort="180" lower="-0.523599" upper="0.523599" velocity="12"/>
    <safety_controller k_position="100" k_velocity="100" soft_lower_limit="-10.5236" soft_upper_limit="10.5236"/>
  </joint>
  <joint name="l_leg_hpy" type="revolute">
    <origin rpy="0 -0 0" xyz="0.05 0 -0.05"/>
    <axis xyz="0 1 0"/>
    <parent link="l_lglut"/>
    <child link="l_uleg"/>
    <dynamics damping="0.1" friction="0"/>
    <limit effort="260" lower="-1.72072" upper="0.524821" velocity="12"/>
    <safety_controller k_position="100" k_velocity="100" soft_lower_limit="-11.7207" soft_upper_limit="10.5248"/>
  </joint>
  <joint name="l_leg_hpz" type="revolute">
    <origin rpy="0 -0 0" xyz="0 0.089 0"/>
    <axis xyz="0 0 1"/>
    <parent link="pelvis"/>
    <child link="l_uglut"/>
    <dynamics damping="0.1" friction="0"/>
    <limit effort="110" lower="-0.174533" upper="1.22173" velocity="12"/>
    <safety_controller k_position="100" k_velocity="100" soft_lower_limit="-10.1745" soft_upper_limit="11.2217"/>
  </joint>
  <joint name="l_leg_kny" type="revolute">
    <origin rpy="0 -0 0" xyz="-0.05 0 -0.374"/>
    <axis xyz="0 1 0"/>
    <parent link="l_uleg"/>
    <child link="l_lleg"/>
    <dynamics damping="0.1" friction="0"/>
    <limit effort="220" lower="0" upper="2.38569" velocity="12"/>
    <safety_controller k_position="100" k_velocity="100" soft_lower_limit="-10" soft_upper_limit="12.3857"/>
  </joint>
  <joint name="neck_ry" type="revolute">
    <origin rpy="0 -0 0" xyz="0.21672 0 0.53796"/>
    <axis xyz="0 1 0"/>
    <parent link="utorso"/>
    <child link="head"/>
    <dynamics damping="0.1" friction="0"/>
    <limit effort="5" lower="-0.602139" upper="1.14494" velocity="12"/>
    <safety_controller k_position="100" k_velocity="100" soft_lower_limit="-10.6021" soft_upper_limit="11.1449"/>
  </joint>
  <joint name="r_arm_elx" type="revolute">
    <origin rpy="0 -0 0" xyz="0 -0.119 0.00921"/>
    <axis xyz="1 0 0"/>
    <parent link="r_uarm"/>
    <child link="r_larm"/>
    <dynamics damping="0.1" friction="0"/>
    <limit effort="114" lower="-2.35619" upper="0" velocity="12"/>
    <safety_controller k_position="100" k_velocity="100" soft_lower_limit="-12.3562" soft_upper_limit="10"/>
  </joint>
  <joint name="r_arm_ely" type="revolute">
    <origin rpy="0 -0 0" xyz="0 -0.187 0.016"/>
    <axis xyz="0 1 0"/>
    <parent link="r_scap"/>
    <child link="r_uarm"/>
    <dynamics damping="0.1" friction="0"/>
    <limit effort="114" lower="0" upper="3.14159" velocity="12"/>
    <safety_controller k_position="100" k_velocity="100" soft_lower_limit="-10" soft_upper_limit="13.1416"/>
  </joint>
  <joint name="r_arm_shx" type="revolute">
    <origin rpy="0 -0 0" xyz="0 -0.14035 0.19609"/>
    <axis xyz="1 0 0"/>
    <parent link="r_clav"/>
    <child link="r_scap"/>
    <dynamics damping="0.1" friction="0"/>
    <limit effort="170" lower="-1.5708" upper="1.5708" velocity="12"/>
    <safety_controller k_position="100" k_velocity="100" soft_lower_limit="-11.5708" soft_upper_limit="11.5708"/>
  </joint>
  <joint name="r_arm_shy" type="revolute">
    <origin rpy="0 -0 0" xyz="0.06441 -0.13866 0.10718"/>
    <axis xyz="0 0.5 -0.866025"/>
    <parent link="utorso"/>
    <child link="r_clav"/>
    <dynamics damping="0.1" friction="0"/>
    <limit effort="212" lower="-1.5708" upper="0.785398" velocity="12"/>
    <safety_controller k_position="100" k_velocity="100" soft_lower_limit="-11.5708" soft_upper_limit="10.7854"/>
  </joint>
  <joint name="r_arm_wrx" type="revolute">
    <origin rpy="0 -0 0" xyz="0 -0.119 0.00921"/>
    <axis xyz="1 0 0"/>
    <parent link="r_farm"/>
    <child link="r_hand"/>
    <dynamics damping="0.1" friction="0"/>
    <limit effort="60" lower="-1.1781" upper="1.1781" velocity="12"/>
    <safety_controller k_position="100" k_velocity="100" soft_lower_limit="-11.1781" soft_upper_limit="11.1781"/>
  </joint>
  <joint name="r_arm_wry" type="revolute">
    <origin rpy="0 -0 0" xyz="0 -0.187 -0.00921"/>
    <axis xyz="0 1 0"/>
    <parent link="r_larm"/>
    <child link="r_farm"/>
    <dynamics damping="0.1" friction="0"/>
    <limit effort="114" lower="0" upper="3.14159" velocity="12"/>
    <safety_controller k_position="100" k_velocity="100" soft_lower_limit="-10" soft_upper_limit="13.1416"/>
  </joint>
  <joint name="r_leg_akx" type="revolute">
    <origin rpy="0 -0 0" xyz="0 0 0"/>
    <axis xyz="1 0 0"/>
    <parent link="r_talus"/>
    <child link="r_foot"/>
    <dynamics damping="0.1" friction="0"/>
    <limit effort="90" lower="-0.8" upper="0.8" velocity="12"/>
    <safety_controller k_position="100" k_velocity="100" soft_lower_limit="-10.8" soft_upper_limit="10.8"/>
  </joint>
  <joint name="r_leg_aky" type="revolute">
    <origin rpy="0 -0 0" xyz="0 0 -0.422"/>
    <axis xyz="0 1 0"/>
    <parent link="r_lleg"/>
    <child link="r_talus"/>
    <dynamics damping="0.1" friction="0"/>
    <limit effort="700" lower="-1" upper="0.7" velocity="12"/>
    <safety_controller k_position="100" k_velocity="100" soft_lower_limit="-11" soft_upper_limit="10.7"/>
  </joint>
  <joint name="r_leg_hpx" type="revolute">
    <origin rpy="0 -0 0" xyz="0 0 0"/>
    <axis xyz="1 0 0"/>
    <parent link="r_uglut"/>
    <child link="r_lglut"/>
    <dynamics damping="0.1" friction="0"/>
    <limit effort="180" lower="-0.523599" upper="0.523599" velocity="12"/>
    <safety_controller k_position="100" k_velocity="100" soft_lower_limit="-10.5236" soft_upper_limit="10.5236"/>
  </joint>
  <joint name="r_leg_hpy" type="revolute">
    <origin rpy="0 -0 0" xyz="0.05 0 -0.05"/>
    <axis xyz="0 1 0"/>
    <parent link="r_lglut"/>
    <child link="r_uleg"/>
    <dynamics damping="0.1" friction="0"/>
    <limit effort="260" lower="-1.72072" upper="0.524821" velocity="12"/>
    <safety_controller k_position="100" k_velocity="100" soft_lower_limit="-11.7207" soft_upper_limit="10.5248"/>
  </joint>
  <joint name="r_leg_hpz" type="revolute">
    <origin rpy="0 -0 0" xyz="0 -0.089 0"/>
    <axis xyz="0 0 1"/>
    <parent link="pelvis"/>
    <child link="r_uglut"/>
    <dynamics damping="0.1" friction="0"/>
    <limit effort="110" lower="-1.22173" upper="0.174533" velocity="12"/>
    <safety_controller k_position="100" k_velocity="100" soft_lower_limit="-11.2217" soft_upper_limit="10.1745"/>
  </joint>
  <joint name="r_leg_kny" type="revolute">
    <origin rpy="0 -0 0" xyz="-0.05 0 -0.374"/>
    <axis xyz="0 1 0"/>
    <parent link="r_uleg"/>
    <child link="r_lleg"/>
    <dynamics damping="0.1" friction="0"/>
    <limit effort="220" lower="0" upper="2.38569" velocity="12"/>
    <safety_controller k_position="100" k_velocity="100" soft_lower_limit="-10" soft_upper_limit="12.3857"/>
  </joint>
  <link name="r_situational_awareness_camera_link">
    <inertial>
      <mass value="0.1"/>
      <origin xyz="0 0 0"/>
      <inertia ixx="0.00001" ixy="0" ixz="0" iyy="0.00001" iyz="0" izz="0.00001"/>
    </inertial>
    <visual>
      <origin rpy="0 0 0" xyz="0 0 0"/>
      <geometry>
        <box size="0.01 0.01 0.01"/>
      </geometry>
    </visual>
  </link>
  <joint name="r_situational_awareness_camera_joint" type="fixed">
    <parent link="utorso"/>
    <child link="r_situational_awareness_camera_link"/>
    <!-- if camera points x-forward, bottom towards front of robot, 15 degree yaw forwards from
           lateral (+y) view -->
    <origin rpy="1.57079633 0 -1.30899694" xyz="0.216409 -0.121799 0.406759"/>
  </joint>
  <joint name="r_situational_awareness_camera_optical_frame_joint" type="fixed">
    <origin rpy="-1.5708 0.0 -1.5708" xyz="0 0 0"/>
    <parent link="r_situational_awareness_camera_link"/>
    <child link="r_situational_awareness_camera_optical_frame"/>
  </joint>
  <link name="r_situational_awareness_camera_optical_frame"/>
  <link name="l_situational_awareness_camera_link">
    <inertial>
      <mass value="0.1"/>
      <origin xyz="0 0 0"/>
      <inertia ixx="0.00001" ixy="0" ixz="0" iyy="0.00001" iyz="0" izz="0.00001"/>
    </inertial>
    <visual>
      <origin rpy="0 0 0" xyz="0 0 0"/>
      <geometry>
        <box size="0.01 0.01 0.01"/>
      </geometry>
    </visual>
  </link>
  <joint name="l_situational_awareness_camera_joint" type="fixed">
    <parent link="utorso"/>
    <child link="l_situational_awareness_camera_link"/>
    <!-- if camera points x-forward, bottom towards front of robot, 15 degree yaw forwards from
           lateral (+y) view -->
    <origin rpy="-1.57079633 0 1.30899694" xyz="0.216409 0.121799 0.406759"/>
  </joint>
  <joint name="l_situational_awareness_camera_optical_frame_joint" type="fixed">
    <origin rpy="-1.5708 0.0 -1.5708" xyz="0 0 0"/>
    <parent link="l_situational_awareness_camera_link"/>
    <child link="l_situational_awareness_camera_optical_frame"/>
  </joint>
  <link name="l_situational_awareness_camera_optical_frame"/>
  <link name="rear_situational_awareness_camera_link">
    <inertial>
      <mass value="0.1"/>
      <origin xyz="0 0 0"/>
      <inertia ixx="0.00001" ixy="0" ixz="0" iyy="0.00001" iyz="0" izz="0.00001"/>
    </inertial>
    <visual>
      <origin rpy="0 0 0" xyz="0 0 0"/>
      <geometry>
        <box size="0.01 0.01 0.01"/>
      </geometry>
    </visual>
  </link>
  <joint name="rear_situational_awareness_camera_joint" type="fixed">
    <parent link="utorso"/>
    <child link="rear_situational_awareness_camera_link"/>
    <!-- if camera points towards -X direction of the utorso link frame -->
    <origin rpy="0 0 3.14159" xyz="-0.0026 0.0264 0.6649"/>
  </joint>
  <joint name="rear_situational_awareness_camera_optical_frame_joint" type="fixed">
    <origin rpy="-1.5708 0.0 -1.5708" xyz="0 0 0"/>
    <parent link="rear_situational_awareness_camera_link"/>
    <child link="rear_situational_awareness_camera_optical_frame"/>
  </joint>
  <link name="rear_situational_awareness_camera_optical_frame"/>
  <gazebo>
    <!-- robot model offset -->
    <pose>0 0 0.93 0 0 0</pose>
  </gazebo>
  <gazebo>
    <plugin filename="libAtlasPlugin.so" name="atlas_plugin"/>
    <plugin filename="libgazebo_ros_joint_pose_trajectory.so" name="joint_trajectory_plugin">
      <topicName>joint_trajectory</topicName>
      <updateRate>1000.0</updateRate>
    </plugin>
    <!--
    <plugin filename="libgazebo_ros_controller_manager.so" name="gazebo_ros_controller_manager">
      <alwaysOn>true</alwaysOn>
      <updateRate>1000.0</updateRate>
    </plugin>
    -->
  </gazebo>
  <gazebo reference="l_arm_wrx">
    <provideFeedback>1</provideFeedback>
  </gazebo>
  <gazebo reference="r_arm_wrx">
    <provideFeedback>1</provideFeedback>
  </gazebo>
  <gazebo reference="l_leg_akx">
    <provideFeedback>1</provideFeedback>
    <implicitSpringDamper>1</implicitSpringDamper>
  </gazebo>
  <gazebo reference="r_leg_akx">
    <provideFeedback>1</provideFeedback>
    <implicitSpringDamper>1</implicitSpringDamper>
  </gazebo>
  <gazebo reference="r_foot">
    <!-- kp and kd for rubber -->
    <kp>1000000.0</kp>
    <kd>100.0</kd>
    <mu1>1.5</mu1>
    <mu2>1.5</mu2>
    <fdir1>1 0 0</fdir1>
    <maxVel>1.0</maxVel>
    <minDepth>0.00</minDepth>
  </gazebo>
  <gazebo reference="l_foot">
    <kp>1000000.0</kp>
    <kd>100.0</kd>
    <mu1>1.5</mu1>
    <mu2>1.5</mu2>
    <fdir1>1 0 0</fdir1>
    <maxVel>1.0</maxVel>
    <minDepth>0.00</minDepth>
  </gazebo>
  <gazebo reference="l_clav">
    <mu1>0.9</mu1>
    <mu2>0.9</mu2>
  </gazebo>
  <gazebo reference="l_farm">
    <mu1>0.9</mu1>
    <mu2>0.9</mu2>
  </gazebo>
  <gazebo reference="l_hand">
    <mu1>0.9</mu1>
    <mu2>0.9</mu2>
  </gazebo>
  <gazebo reference="l_larm">
    <mu1>0.9</mu1>
    <mu2>0.9</mu2>
  </gazebo>
  <gazebo reference="l_lglut">
    <mu1>0.9</mu1>
    <mu2>0.9</mu2>
  </gazebo>
  <gazebo reference="l_lleg">
    <mu1>0.9</mu1>
    <mu2>0.9</mu2>
  </gazebo>
  <gazebo reference="l_scap">
    <mu1>0.9</mu1>
    <mu2>0.9</mu2>
  </gazebo>
  <gazebo reference="l_talus">
    <mu1>0.9</mu1>
    <mu2>0.9</mu2>
  </gazebo>
  <gazebo reference="l_uarm">
    <mu1>0.9</mu1>
    <mu2>0.9</mu2>
  </gazebo>
  <gazebo reference="l_uglut">
    <mu1>0.9</mu1>
    <mu2>0.9</mu2>
  </gazebo>
  <gazebo reference="l_uleg">
    <mu1>0.9</mu1>
    <mu2>0.9</mu2>
  </gazebo>
  <gazebo reference="ltorso">
    <mu1>0.9</mu1>
    <mu2>0.9</mu2>
  </gazebo>
  <gazebo reference="mtorso">
    <mu1>0.9</mu1>
    <mu2>0.9</mu2>
  </gazebo>
  <gazebo reference="pelvis">
    <mu1>0.9</mu1>
    <mu2>0.9</mu2>
  </gazebo>
  <gazebo reference="r_clav">
    <mu1>0.9</mu1>
    <mu2>0.9</mu2>
  </gazebo>
  <gazebo reference="r_farm">
    <mu1>0.9</mu1>
    <mu2>0.9</mu2>
  </gazebo>
  <gazebo reference="r_hand">
    <mu1>0.9</mu1>
    <mu2>0.9</mu2>
  </gazebo>
  <gazebo reference="r_larm">
    <mu1>0.9</mu1>
    <mu2>0.9</mu2>
  </gazebo>
  <gazebo reference="r_lglut">
    <mu1>0.9</mu1>
    <mu2>0.9</mu2>
  </gazebo>
  <gazebo reference="r_lleg">
    <mu1>0.9</mu1>
    <mu2>0.9</mu2>
  </gazebo>
  <gazebo reference="r_scap">
    <mu1>0.9</mu1>
    <mu2>0.9</mu2>
  </gazebo>
  <gazebo reference="r_talus">
    <mu1>0.9</mu1>
    <mu2>0.9</mu2>
  </gazebo>
  <gazebo reference="r_uarm">
    <mu1>0.9</mu1>
    <mu2>0.9</mu2>
  </gazebo>
  <gazebo reference="r_uglut">
    <mu1>0.9</mu1>
    <mu2>0.9</mu2>
  </gazebo>
  <gazebo reference="r_uleg">
    <mu1>0.9</mu1>
    <mu2>0.9</mu2>
  </gazebo>
  <gazebo reference="utorso">
    <mu1>0.9</mu1>
    <mu2>0.9</mu2>
  </gazebo>
  <gazebo>
    <plugin filename="libgazebo_ros_p3d.so" name="gazebo_ros_p3d">
      <bodyName>pelvis</bodyName>
      <topicName>/ground_truth_odom</topicName>
      <alwaysOn>true</alwaysOn>
      <updateRate>100.0</updateRate>
    </plugin>
  </gazebo>
  <gazebo reference="r_foot">
    <!-- contact sensor -->
    <sensor name="r_foot_contact_sensor" type="contact">
      <update_rate>1000.0</update_rate>
      <always_on>1</always_on>
      <contact>
        <collision>r_foot_collision</collision>
        <topic>/r_foot_contact</topic>
      </contact>
    </sensor>
  </gazebo>
  <gazebo reference="l_foot">
    <!-- contact sensor -->
    <sensor name="l_foot_contact_sensor" type="contact">
      <update_rate>1000.0</update_rate>
      <always_on>1</always_on>
      <contact>
        <collision>l_foot_collision</collision>
        <topic>/l_foot_contact</topic>
      </contact>
    </sensor>
  </gazebo>
  <gazebo>
    <plugin filename="libgazebo_ros_force.so" name="gazebo_ros_force">
      <bodyName>pelvis</bodyName>
      <topicName>/atlas/apply_pelvis_force</topicName>
    </plugin>
  </gazebo>
  <gazebo reference="back_bkz">
    <implicitSpringDamper>1</implicitSpringDamper>
  </gazebo>
  <gazebo reference="back_bky">
    <implicitSpringDamper>1</implicitSpringDamper>
  </gazebo>
  <gazebo reference="back_bkx">
    <implicitSpringDamper>1</implicitSpringDamper>
  </gazebo>
  <gazebo reference="l_arm_elx">
    <implicitSpringDamper>1</implicitSpringDamper>
  </gazebo>
  <gazebo reference="l_arm_ely">
    <implicitSpringDamper>1</implicitSpringDamper>
  </gazebo>
  <gazebo reference="l_arm_wrx">
    <implicitSpringDamper>1</implicitSpringDamper>
  </gazebo>
  <gazebo reference="l_arm_shx">
    <implicitSpringDamper>1</implicitSpringDamper>
  </gazebo>
  <gazebo reference="l_arm_shy">
    <implicitSpringDamper>1</implicitSpringDamper>
  </gazebo>
  <gazebo reference="l_arm_wry">
    <implicitSpringDamper>1</implicitSpringDamper>
  </gazebo>
  <gazebo reference="l_leg_kny">
    <implicitSpringDamper>1</implicitSpringDamper>
  </gazebo>
  <gazebo reference="l_leg_hpy">
    <implicitSpringDamper>1</implicitSpringDamper>
  </gazebo>
  <gazebo reference="l_leg_hpx">
    <implicitSpringDamper>1</implicitSpringDamper>
  </gazebo>
  <gazebo reference="l_leg_aky">
    <implicitSpringDamper>1</implicitSpringDamper>
  </gazebo>
  <gazebo reference="l_leg_hpz">
    <implicitSpringDamper>1</implicitSpringDamper>
  </gazebo>
  <gazebo reference="neck_ry">
    <implicitSpringDamper>1</implicitSpringDamper>
  </gazebo>
  <gazebo reference="r_arm_elx">
    <implicitSpringDamper>1</implicitSpringDamper>
  </gazebo>
  <gazebo reference="r_arm_ely">
    <implicitSpringDamper>1</implicitSpringDamper>
  </gazebo>
  <gazebo reference="r_arm_wrx">
    <implicitSpringDamper>1</implicitSpringDamper>
  </gazebo>
  <gazebo reference="r_arm_shx">
    <implicitSpringDamper>1</implicitSpringDamper>
  </gazebo>
  <gazebo reference="r_arm_shy">
    <implicitSpringDamper>1</implicitSpringDamper>
  </gazebo>
  <gazebo reference="r_arm_wry">
    <implicitSpringDamper>1</implicitSpringDamper>
  </gazebo>
  <gazebo reference="r_leg_kny">
    <implicitSpringDamper>1</implicitSpringDamper>
  </gazebo>
  <gazebo reference="r_leg_hpy">
    <implicitSpringDamper>1</implicitSpringDamper>
  </gazebo>
  <gazebo reference="r_leg_hpx">
    <implicitSpringDamper>1</implicitSpringDamper>
  </gazebo>
  <gazebo reference="r_leg_aky">
    <implicitSpringDamper>1</implicitSpringDamper>
  </gazebo>
  <gazebo reference="r_leg_hpz">
    <implicitSpringDamper>1</implicitSpringDamper>
  </gazebo>
  <gazebo reference="r_situational_awareness_camera_link">
    <sensor name="r_situational_awareness_camera_sensor" type="camera">
      <update_rate>60.0</update_rate>
      <camera name="r_situational_awareness_camera">
        <pose>0 0 0 0 0 0</pose>
        <!-- Spec sheet says 185deg HFOV @ 1280x1024pi @ 60 hz.
             Don't think most GPU's can achieve this at real-time right now.
        <horizontal_fov>3.22885912</horizontal_fov>
        -->
        <horizontal_fov>2.0</horizontal_fov>
        <image>
          <width>1280</width>
          <height>1024</height>
          <format>R8G8B8</format>
        </image>
        <clip>
          <near>0.02</near>
          <far>300</far>
        </clip>
        <noise>
          <type>gaussian</type>
          <!-- Noise is sampled independently per pixel on each frame.  
               That pixel's noise value is added to each of its color
               channels, which at that point lie in the range [0,1].
               The stddev value of 0.007 is based on experimental data 
               from a camera in a Sandia hand pointed at a static scene
               in a couple of different lighting conditions.  -->
          <mean>0.0</mean>
          <stddev>0.007</stddev>
        </noise>
      </camera>
      <plugin filename="libgazebo_ros_camera.so" name="r_situational_awareness_camera_controller">
        <alwaysOn>true</alwaysOn>
        <updateRate>0.0</updateRate>
        <cameraName>r_situational_awareness_camera</cameraName>
        <imageTopicName>image_raw</imageTopicName>
        <cameraInfoTopicName>camera_info</cameraInfoTopicName>
        <frameName>r_situational_awareness_camera_optical_frame</frameName>
        <hackBaseline>0.0</hackBaseline>
        <distortionK1>0.0</distortionK1>
        <distortionK2>0.0</distortionK2>
        <distortionK3>0.0</distortionK3>
        <distortionT1>0.0</distortionT1>
        <distortionT2>0.0</distortionT2>
      </plugin>
    </sensor>
  </gazebo>
  <gazebo reference="l_situational_awareness_camera_link">
    <sensor name="l_situational_awareness_camera_sensor" type="camera">
      <update_rate>60.0</update_rate>
      <camera name="l_situational_awareness_camera">
        <pose>0 0 0 0 0 0</pose>
        <!-- Spec sheet says 185deg HFOV @ 1280x1024pi @ 60 hz.
             Don't think most GPU's can achieve this at real-time right now.
        <horizontal_fov>3.22885912</horizontal_fov>
        -->
        <horizontal_fov>2.0</horizontal_fov>
        <image>
          <width>1280</width>
          <height>1024</height>
          <format>R8G8B8</format>
        </image>
        <clip>
          <near>0.02</near>
          <far>300</far>
        </clip>
        <noise>
          <type>gaussian</type>
          <!-- Noise is sampled independently per pixel on each frame.  
               That pixel's noise value is added to each of its color
               channels, which at that point lie in the range [0,1].
               The stddev value of 0.007 is based on experimental data 
               from a camera in a Sandia hand pointed at a static scene
               in a couple of different lighting conditions.  -->
          <mean>0.0</mean>
          <stddev>0.007</stddev>
        </noise>
      </camera>
      <plugin filename="libgazebo_ros_camera.so" name="l_situational_awareness_camera_controller">
        <alwaysOn>true</alwaysOn>
        <updateRate>0.0</updateRate>
        <cameraName>l_situational_awareness_camera</cameraName>
        <imageTopicName>image_raw</imageTopicName>
        <cameraInfoTopicName>camera_info</cameraInfoTopicName>
        <frameName>l_situational_awareness_camera_optical_frame</frameName>
        <hackBaseline>0.0</hackBaseline>
        <distortionK1>0.0</distortionK1>
        <distortionK2>0.0</distortionK2>
        <distortionK3>0.0</distortionK3>
        <distortionT1>0.0</distortionT1>
        <distortionT2>0.0</distortionT2>
      </plugin>
    </sensor>
  </gazebo>
  <gazebo reference="rear_situational_awareness_camera_link">
    <!-- Rear situational awareness camera is a D-Link DCS-2310L camera.
         Specs taken from website:
         http://www.dlink.com/us/en/home-solutions/view/network-cameras/dcs-2310l-outdoor-hd-poe-day-night-cloud-camera
         FOV: (H)57.8 deg, (V)37.8 deg, (D)66.0 deg
         Avalilable Resolutions:
           16:9 - 1280 x 800, 1280 x 720, 800 x 450, 640 x 360, 480 x 270, 320 x 176, 176 x 144 up to 30 fps recording1
           4:3 - 1024 x 768, 800 x 600, 640 x 480, 480 x 360, 320 x 240, 176 x 144 up to 30 fps recording1 
        -->
    <sensor name="rear_situational_awareness_camera_sensor" type="camera">
      <update_rate>30.0</update_rate>
      <camera name="rear_situational_awareness_camera">
        <pose>0 0 0 0 0 0</pose>
        <horizontal_fov>1.0</horizontal_fov>
        <image>
          <width>1280</width>
          <height>800</height>
          <format>R8G8B8</format>
        </image>
        <clip>
          <near>0.02</near>
          <far>300</far>
        </clip>
        <noise>
          <type>gaussian</type>
          <!-- Noise is sampled independently per pixel on each frame.  
               That pixel's noise value is added to each of its color
               channels, which at that point lie in the range [0,1].
               The stddev value of 0.007 is based on experimental data 
               from a camera in a Sandia hand pointed at a static scene
               in a couple of different lighting conditions.  -->
          <mean>0.0</mean>
          <stddev>0.007</stddev>
        </noise>
      </camera>
      <plugin filename="libgazebo_ros_camera.so" name="rear_situational_awareness_camera_controller">
        <alwaysOn>true</alwaysOn>
        <updateRate>0.0</updateRate>
        <cameraName>rear_situational_awareness_camera</cameraName>
        <imageTopicName>image_raw</imageTopicName>
        <cameraInfoTopicName>camera_info</cameraInfoTopicName>
        <frameName>rear_situational_awareness_camera_optical_frame</frameName>
        <hackBaseline>0.0</hackBaseline>
        <distortionK1>0.0</distortionK1>
        <distortionK2>0.0</distortionK2>
        <distortionK3>0.0</distortionK3>
        <distortionT1>0.0</distortionT1>
        <distortionT2>0.0</distortionT2>
      </plugin>
    </sensor>
  </gazebo>
  <link name="head">
    <inertial>
      <origin rpy="0 0 0" xyz="-0.075493 3.3383E-05 0.02774"/>
      <mass value="1.41984"/>
      <!--<inertia iyy="0.0041178" ixy="-1.5797E-06" iyz="-6.8415E-07" ixx="0.0039688" ixz="-0.00089293" izz="0.0035243" />-->
      <inertia ixx="0.0036053766" ixy="-1.5797E-06" ixz="-0.00089293" iyy="0.002080106" iyz="-6.8415E-07" izz="0.001782985"/>
    </inertial>
    <visual>
      <origin rpy="0 0 0" xyz="0 0 0"/>
      <geometry>
        <mesh filename="package://multisense_sl_description/meshes/head.dae"/>
      </geometry>
      <material name="">
        <color rgba="0.9098 0.44314 0.031373 1"/>
      </material>
    </visual>
    <collision group="default">
      <origin rpy="0 0 0" xyz="-0.0503 0 -0.00195"/>
      <geometry>
        <box size="0.1311 0.12 0.0591"/>
      </geometry>
    </collision>
    <collision group="other">
      <origin rpy="0 0 0" xyz="-0.093 0 0.0868"/>
      <geometry>
        <box size="0.0468 0.12 0.1184"/>
      </geometry>
    </collision>
  </link>
</robot>

