<?xml version="1.0" ?>
<!-- =================================================================================== -->
<!-- |    This document was autogenerated by xacro from /kinematic_analysis_ws/src/val_description/model/robots/valkyrie_A.urdf.xacro | -->
<!-- |    EDITING THIS FILE BY HAND IS NOT RECOMMENDED                                 | -->
<!-- =================================================================================== -->
<robot name="valkyrie">
  <!-- Forearm dictionary -->
  <!-- Setting the property for the left and right forearm -->
  <!--roll-->
  <!-- Setting the property for the left and right forearm -->
  <!-- <xacro:property name="leftArmJ5SerialNumber" value="v_g_016" />
        <xacro:property name="leftForearmSerialNumber" value="v_h_005"/> -->
  <!-- <xacro:property name="rightArmJ5SerialNumber" value="v_g_012" />
        <xacro:property name="rightForearmSerialNumber" value="v_h_006" /> -->
  <!-- <xacro:include filename="package://val_description/model/robots/common/xacro/head/flir.xacro"/> -->
  <!-- <xacro:macro name="make_arm_no_hands" params="prefix reflect arm_root_link">
    <xacro:make_upper_arm prefix="${prefix}" reflect="${reflect}" upper_arm_root_link="${arm_root_link}" />
    <xacro:make_forearm prefix="${prefix}" reflect="${reflect}" forearm_root_link="${prefix}ElbowPitchLink" />
  </xacro:macro> -->
  <!-- Psyonic INFO -->
  <link name="pelvis">
    <inertial>
      <mass value="8.22"/>
      <origin rpy="0 0 0" xyz="-0.00532 -0.003512 -0.0036"/>
      <inertia ixx="0.11866378" ixy="-0.000143482" ixz="0.003271293" iyy="0.097963425" iyz="0.002159545" izz="0.083854638"/>
    </inertial>
    <visual>
      <geometry>
        <mesh filename="package://val_description/model/meshes/pelvis/pelvis.dae"/>
      </geometry>
      <origin rpy="0.0 0.0 0.0" xyz="0.0 0.0 0.0"/>
    </visual>
    <collision>
      <geometry>
        <mesh filename="package://val_description/model/meshes/pelvis/pelvis.dae"/>
      </geometry>
      <origin rpy="0 0 0" xyz="0 0 0"/>
    </collision>
  </link>
  <link name="pelvisRearImu_Frame">
    <!-- Virtual Link -->
    <inertial>
      <mass value="1e-07"/>
      <origin rpy="0 0 0" xyz="0 0 0"/>
      <inertia ixx="3.3333333333333322e-22" ixy="0.0" ixz="0.0" iyy="3.3333333333333322e-22" iyz="0.0" izz="4.999999999999999e-22"/>
    </inertial>
  </link>
  <joint name="pelvisRearImu_Offset" type="fixed">
    <origin rpy="-3.14159 0.476467 -3.14159" xyz="-0.075844901 0.0 -0.111056426"/>
    <axis xyz="0 0 1"/>
    <parent link="pelvis"/>
    <child link="pelvisRearImu_Frame"/>
  </joint>
  <gazebo reference="pelvisRearImu_Offset">
    <implicitSpringDamper>1</implicitSpringDamper>
  </gazebo>
  <gazebo>
    <plugin filename="libgazebo_ros_imu.so" name="imu_plugin_ros">
      <alwaysOn>true</alwaysOn>
      <bodyName>pelvisRearImu_Frame</bodyName>
      <topicName>pelvisRearImu/imu</topicName>
      <serviceName>pelvisRearImu/imu_service</serviceName>
      <gaussianNoise>0.0</gaussianNoise>
      <updateRate>1000.0</updateRate>
    </plugin>
  </gazebo>
  <gazebo reference="pelvisRearImu_Frame">
    <sensor name="pelvisRearImu" type="imu">
      <imuTransform>-0.075844901 0.0 -0.111056426 -3.14159 0.476467 -3.14159</imuTransform>
      <always_on>true</always_on>
      <pose>0 0 0 0 0 0 </pose>
      <node name="/sensors/rearPelvisIMU"/>
      <api name="imu_3dm_gx4_15_sensor::Imu3DmGx415Sensor"/>
      <port name="/dev/ttyS4"/>
      <imu>
        <noise>
          <type>gaussian</type>
          <rate>
            <mean>0</mean>
            <stddev>0.0002</stddev>
            <bias_mean>7.5e-06</bias_mean>
            <bias_stddev>8e-07</bias_stddev>
          </rate>
          <accel>
            <mean>0</mean>
            <stddev>0.017</stddev>
            <bias_mean>0.1</bias_mean>
            <bias_stddev>0.001</bias_stddev>
          </accel>
        </noise>
      </imu>
    </sensor>
  </gazebo>
  <link name="pelvisMiddleImu_Frame">
    <!-- Virtual Link -->
    <inertial>
      <mass value="1e-07"/>
      <origin rpy="0 0 0" xyz="0 0 0"/>
      <inertia ixx="3.3333333333333322e-22" ixy="0.0" ixz="0.0" iyy="3.3333333333333322e-22" iyz="0.0" izz="4.999999999999999e-22"/>
    </inertial>
  </link>
  <joint name="pelvisMiddleImu_Offset" type="fixed">
    <origin rpy="3.14159 0.0 0.0" xyz="0.0 0.0 -0.10819638"/>
    <axis xyz="0 0 1"/>
    <parent link="pelvis"/>
    <child link="pelvisMiddleImu_Frame"/>
  </joint>
  <gazebo reference="pelvisMiddleImu_Offset">
    <implicitSpringDamper>1</implicitSpringDamper>
  </gazebo>
  <gazebo>
    <plugin filename="libgazebo_ros_imu.so" name="imu_plugin_ros">
      <alwaysOn>true</alwaysOn>
      <bodyName>pelvisMiddleImu_Frame</bodyName>
      <topicName>pelvisMiddleImu/imu</topicName>
      <serviceName>pelvisMiddleImu/imu_service</serviceName>
      <gaussianNoise>0.0</gaussianNoise>
      <updateRate>500.0</updateRate>
    </plugin>
  </gazebo>
  <gazebo reference="pelvisMiddleImu_Frame">
    <sensor name="pelvisMiddleImu" type="imu">
      <imuTransform>0.0 0.0 -0.10819638 3.14159 0.0 0.0</imuTransform>
      <always_on>true</always_on>
      <pose>0 0 0 0 0 0 </pose>
      <imu>
        <noise>
          <type>gaussian</type>
          <rate>
            <mean>0</mean>
            <stddev>0.0002</stddev>
            <bias_mean>7.5e-06</bias_mean>
            <bias_stddev>8e-07</bias_stddev>
          </rate>
          <accel>
            <mean>0</mean>
            <stddev>0.017</stddev>
            <bias_mean>0.1</bias_mean>
            <bias_stddev>0.001</bias_stddev>
          </accel>
        </noise>
      </imu>
    </sensor>
  </gazebo>
  <link name="zedm_mount">
    <!-- Virtual Link -->
    <inertial>
      <mass value="1e-07"/>
      <origin rpy="0 0 0" xyz="0 0 0"/>
      <inertia ixx="3.3333333333333322e-22" ixy="0.0" ixz="0.0" iyy="3.3333333333333322e-22" iyz="0.0" izz="4.999999999999999e-22"/>
    </inertial>
  </link>
  <joint name="zedm_head_root_joint" type="fixed">
    <origin rpy="0.0 0.1309 0.0" xyz="0.192184 0.0 -0.096498"/>
    <axis xyz="0 0 1"/>
    <parent link="upperNeckPitchLink"/>
    <child link="zedm_mount"/>
  </joint>
  <gazebo reference="zedm_head_root_joint">
    <implicitSpringDamper>1</implicitSpringDamper>
  </gazebo>
  <link name="torsoYawLink">
    <inertial>
      <mass value="0.5"/>
      <origin rpy="0 0 0" xyz="0.000000 0.000000 -0.010000"/>
      <inertia ixx="0.000608427" ixy="-1.172e-06" ixz="1.647e-06" iyy="0.000620328" iyz="-2.33e-07" izz="0.001078108"/>
    </inertial>
    <visual>
      <geometry>
        <mesh filename="package://val_description/model/meshes/torso/torsoyaw.dae"/>
      </geometry>
      <origin rpy="0.0 0.0 0.0" xyz="0.0 0.0 0.0"/>
    </visual>
    <collision>
      <geometry>
        <mesh filename="package://val_description/model/meshes/torso/torsoyaw.dae"/>
      </geometry>
      <origin rpy="0 0 0" xyz="0 0 0"/>
    </collision>
  </link>
  <link name="torsoPitchLink">
    <inertial>
      <mass value="0.1"/>
      <origin rpy="0 0 0" xyz="0.000000 0.000000  0.005000"/>
      <inertia ixx="3.032e-05" ixy="0.0" ixz="-1.145e-06" iyy="2.1274e-05" iyz="0.0" izz="2.8285e-05"/>
    </inertial>
    <visual>
      <geometry>
        <mesh filename="package://val_description/model/meshes/torso/torsopitch.dae"/>
      </geometry>
      <origin rpy="0.0 0.0 0.0" xyz="0.0 0.0 0.0"/>
    </visual>
    <collision>
      <geometry>
        <mesh filename="package://val_description/model/meshes/torso/torsopitch.dae"/>
      </geometry>
      <origin rpy="0 0 0" xyz="0 0 0"/>
    </collision>
  </link>
  <link name="torso">
    <inertial>
      <mass value="30.87"/>
      <origin rpy="0 0 0" xyz="-0.095548 -0.003337 0.243098"/>
      <inertia ixx="0.858969" ixy="9.9563e-05" ixz="0.061345211" iyy="0.99655" iyz="0.00181849" izz="0.764098"/>
    </inertial>
    <visual>
      <geometry>
        <mesh filename="package://val_description/model/meshes/torso/torso.dae"/>
      </geometry>
      <origin rpy="0.0 0.0 0.0" xyz="0.0 0.0 0.0"/>
    </visual>
    <collision>
      <geometry>
        <mesh filename="package://val_description/model/meshes/torso/torso.dae"/>
      </geometry>
      <origin rpy="0 0 0" xyz="0 0 0"/>
    </collision>
  </link>
  <joint name="torsoYaw" type="revolute">
    <origin rpy="0.0 0.0 0.0" xyz="0.0 0.0 0.0"/>
    <axis xyz="0 0 1"/>
    <parent link="pelvis"/>
    <child link="torsoYawLink"/>
    <limit effort="190" lower="-1.259" upper="1.111" velocity="5.89"/>
    <controller_gains Kd="0.0" Ki="0.0" Kp="0.0"/>
    <dynamics damping="0.1" friction="0.0"/>
  </joint>
  <gazebo reference="torsoYaw">
    <provideFeedback>1</provideFeedback>
    <implicitSpringDamper>1</implicitSpringDamper>
  </gazebo>
  <joint name="torsoPitch" type="revolute">
    <origin rpy="0.0 0.0 0.0" xyz="0.04191 0.0 0.0"/>
    <axis xyz="0 1 0"/>
    <parent link="torsoYawLink"/>
    <child link="torsoPitchLink"/>
    <limit effort="150" lower="-0.13" upper="0.666" velocity="9"/>
    <controller_gains Kd="0.0" Ki="0.0" Kp="0.0"/>
    <dynamics damping="0.1" friction="0.0"/>
  </joint>
  <gazebo reference="torsoPitch">
    <provideFeedback>1</provideFeedback>
    <implicitSpringDamper>1</implicitSpringDamper>
  </gazebo>
  <joint name="torsoRoll" type="revolute">
    <origin rpy="0.0 0.0 0.0" xyz="0.0 0.0 0.0203"/>
    <axis xyz="1 0 0"/>
    <parent link="torsoPitchLink"/>
    <child link="torso"/>
    <limit effort="150" lower="-0.23" upper="0.255" velocity="9"/>
    <controller_gains Kd="0.0" Ki="0.0" Kp="0.0"/>
    <dynamics damping="0.1" friction="0.0"/>
  </joint>
  <gazebo reference="torsoRoll">
    <provideFeedback>1</provideFeedback>
    <implicitSpringDamper>1</implicitSpringDamper>
  </gazebo>
  <transmission name="torsoYawTransmission">
    <type>transmission_interface/SimpleTransmission</type>
    <joint name="torsoYaw">
      <hardwareInterface>EffortJointInterface</hardwareInterface>
    </joint>
    <actuator name="torsoYaw">
      <node name="/pelvis/waist"/>
      <mechanicalReduction>1</mechanicalReduction>
      <api name="robot_hardware_interface/TurbodriverAPI"/>
    </actuator>
  </transmission>
  <transmission name="waistTransmission">
    <type>robot_transmission_interface::TorsoPushrodTransmissionLoader</type>
    <joint name="torsoPitch">
      <role>pitch</role>
      <hardwareInterface>EffortJointInterface</hardwareInterface>
    </joint>
    <joint name="torsoRoll">
      <role>roll</role>
      <hardwareInterface>EffortJointInterface</hardwareInterface>
    </joint>
    <actuator name="waistRightActuator">
      <node name="/trunk/right_actuator"/>
      <role>right</role>
      <mechanicalReduction>1</mechanicalReduction>
      <api name="robot_hardware_interface/TurbodriverAPI_linear_Renishaw"/>
    </actuator>
    <actuator name="waistLeftActuator">
      <node name="/trunk/left_actuator"/>
      <role>left</role>
      <mechanicalReduction>1</mechanicalReduction>
      <api name="robot_hardware_interface/TurbodriverAPI_linear_Renishaw"/>
    </actuator>
  </transmission>
  <link name="leftTorsoImu_Frame">
    <!-- Virtual Link -->
    <inertial>
      <mass value="1e-07"/>
      <origin rpy="0 0 0" xyz="0 0 0"/>
      <inertia ixx="3.3333333333333322e-22" ixy="0.0" ixz="0.0" iyy="3.3333333333333322e-22" iyz="0.0" izz="4.999999999999999e-22"/>
    </inertial>
  </link>
  <joint name="leftTorsoImu_Offset" type="fixed">
    <origin rpy="-1.5707 0.0 0.0" xyz="-0.0627634 0.134239 0.3630676"/>
    <axis xyz="0 0 1"/>
    <parent link="torso"/>
    <child link="leftTorsoImu_Frame"/>
  </joint>
  <gazebo reference="leftTorsoImu_Offset">
    <implicitSpringDamper>1</implicitSpringDamper>
  </gazebo>
  <gazebo>
    <plugin filename="libgazebo_ros_imu.so" name="imu_plugin_ros">
      <alwaysOn>true</alwaysOn>
      <bodyName>leftTorsoImu_Frame</bodyName>
      <topicName>leftTorsoImu/imu</topicName>
      <serviceName>leftTorsoImu/imu_service</serviceName>
      <gaussianNoise>0.0</gaussianNoise>
      <updateRate>1000.0</updateRate>
    </plugin>
  </gazebo>
  <gazebo reference="leftTorsoImu_Frame">
    <sensor name="leftTorsoImu" type="imu">
      <imuTransform>-0.0627634 0.134239 0.3630676 -1.5707 0.0 0.0</imuTransform>
      <always_on>true</always_on>
      <pose>0 0 0 0 0 0 </pose>
      <node name="/sensors/leftTorsoIMU"/>
      <api name="imu_3dm_gx4_15_sensor::Imu3DmGx415Sensor"/>
      <port name="/dev/ttyS5"/>
      <imu>
        <noise>
          <type>gaussian</type>
          <rate>
            <mean>0</mean>
            <stddev>0.0002</stddev>
            <bias_mean>7.5e-06</bias_mean>
            <bias_stddev>8e-07</bias_stddev>
          </rate>
          <accel>
            <mean>0</mean>
            <stddev>0.017</stddev>
            <bias_mean>0.1</bias_mean>
            <bias_stddev>0.001</bias_stddev>
          </accel>
        </noise>
      </imu>
    </sensor>
  </gazebo>
  <link name="rightHazardCamera_Frame">
    <!-- Virtual Link -->
    <inertial>
      <mass value="1e-07"/>
      <origin rpy="0 0 0" xyz="0 0 0"/>
      <inertia ixx="3.3333333333333322e-22" ixy="0.0" ixz="0.0" iyy="3.3333333333333322e-22" iyz="0.0" izz="4.999999999999999e-22"/>
    </inertial>
  </link>
  <gazebo reference="rightHazardCamera_Frame">
    <sensor name="rightHazardCamera" type="camera">
      <camera>
        <image>
          <width>1280</width>
          <height>1024</height>
          <format>R8G8B8</format>
        </image>
        <horizontal_fov>1.378</horizontal_fov>
        <clip>
          <near>0.1</near>
          <far>100</far>
        </clip>
      </camera>
      <update_rate>60</update_rate>
    </sensor>
  </gazebo>
  <joint name="rightHazardCamera_Offset" type="fixed">
    <origin rpy="1.57 0.0 1.57" xyz="0.0345 -0.0406 0.1135"/>
    <axis xyz="0 0 1"/>
    <parent link="torso"/>
    <child link="rightHazardCamera_Frame"/>
  </joint>
  <gazebo reference="rightHazardCamera_Offset">
    <implicitSpringDamper>1</implicitSpringDamper>
  </gazebo>
  <link name="leftHazardCamera_Frame">
    <!-- Virtual Link -->
    <inertial>
      <mass value="1e-07"/>
      <origin rpy="0 0 0" xyz="0 0 0"/>
      <inertia ixx="3.3333333333333322e-22" ixy="0.0" ixz="0.0" iyy="3.3333333333333322e-22" iyz="0.0" izz="4.999999999999999e-22"/>
    </inertial>
  </link>
  <gazebo reference="leftHazardCamera_Frame">
    <sensor name="leftHazardCamera" type="camera">
      <camera>
        <image>
          <width>1280</width>
          <height>1024</height>
          <format>R8G8B8</format>
        </image>
        <horizontal_fov>1.378</horizontal_fov>
        <clip>
          <near>0.1</near>
          <far>100</far>
        </clip>
      </camera>
      <update_rate>60</update_rate>
    </sensor>
  </gazebo>
  <joint name="leftHazardCamera_Offset" type="fixed">
    <origin rpy="1.57 0.0 1.57" xyz="0.0345 0.0406 0.1135"/>
    <axis xyz="0 0 1"/>
    <parent link="torso"/>
    <child link="leftHazardCamera_Frame"/>
  </joint>
  <gazebo reference="leftHazardCamera_Offset">
    <implicitSpringDamper>1</implicitSpringDamper>
  </gazebo>
  <link name="lowerNeckPitchLink">
    <inertial>
      <mass value="1.05"/>
      <origin rpy="0 0 0" xyz="-0.020000 0.000000  0.040000"/>
      <inertia ixx="0.001470716" ixy="-0.000126021" ixz="0.000632521" iyy="0.001851919" iyz="0.000243012" izz="0.000832117"/>
    </inertial>
    <visual>
      <geometry>
        <mesh filename="package://val_description/model/meshes/head/neckj1.dae"/>
      </geometry>
      <origin rpy="0.0 0.0 0.0" xyz="0.0 0.0 0.0"/>
    </visual>
    <collision>
      <geometry>
        <mesh filename="package://val_description/model/meshes/head/neckj1.dae"/>
      </geometry>
      <origin rpy="0 0 0" xyz="0 0 0"/>
    </collision>
  </link>
  <link name="neckYawLink">
    <inertial>
      <mass value="1.4"/>
      <origin rpy="0 0 0" xyz="-0.030000  -0.010000 0.150000"/>
      <inertia ixx="0.001997698" ixy="-0.000180062" ixz="0.000723677" iyy="0.002919928" iyz="0.000246467" izz="0.002119751"/>
    </inertial>
    <visual>
      <geometry>
        <mesh filename="package://val_description/model/meshes/head/neckj2.dae"/>
      </geometry>
      <origin rpy="0.0 0.0 0.0" xyz="0.0 0.0 0.0"/>
    </visual>
    <collision>
      <geometry>
        <mesh filename="package://val_description/model/meshes/head/neckj2.dae"/>
      </geometry>
      <origin rpy="0 0 0" xyz="0 0 0"/>
    </collision>
  </link>
  <link name="upperNeckPitchLink">
    <inertial>
      <mass value="3.89"/>
      <origin rpy="0 0 0" xyz="0.100912 0.005783 0.034787"/>
      <inertia ixx="0.039847525" ixy="-0.000470418" ixz="-0.002829842" iyy="0.041418564" iyz="-0.000782564" izz="0.036841236"/>
    </inertial>
    <visual>
      <geometry>
        <mesh filename="package://val_description/model/meshes/head/head_multisense_no_visor.dae"/>
      </geometry>
      <origin rpy="0.0 0.0 0.0" xyz="0.0 0.0 0.0"/>
    </visual>
    <collision>
      <geometry>
        <mesh filename="package://val_description/model/meshes/head/head_multisense_no_visor.dae"/>
      </geometry>
      <origin rpy="0 0 0" xyz="0 0 0"/>
    </collision>
  </link>
  <joint name="lowerNeckPitch" type="revolute">
    <origin rpy="0.0 0.0 0.0" xyz="0.0203518 0.0 0.33845"/>
    <axis xyz="0 1 0"/>
    <parent link="torso"/>
    <child link="lowerNeckPitchLink"/>
    <limit effort="26" lower="0" upper="1.162" velocity="5"/>
    <controller_gains Kd="3" Ki="3" Kp="50"/>
    <dynamics damping="0.1" friction="0.0"/>
  </joint>
  <gazebo reference="lowerNeckPitch">
    <provideFeedback>1</provideFeedback>
    <implicitSpringDamper>1</implicitSpringDamper>
  </gazebo>
  <joint name="neckYaw" type="revolute">
    <origin rpy="0.0 0.0 0.0" xyz="-0.051924 0.0 0.0"/>
    <axis xyz="0 0 1"/>
    <parent link="lowerNeckPitchLink"/>
    <child link="neckYawLink"/>
    <limit effort="26" lower="-1.04719755" upper="1.04719755" velocity="5"/>
    <controller_gains Kd="3" Ki="0.0" Kp="50"/>
    <dynamics damping="0.1" friction="0.0"/>
  </joint>
  <gazebo reference="neckYaw">
    <provideFeedback>1</provideFeedback>
    <implicitSpringDamper>1</implicitSpringDamper>
  </gazebo>
  <joint name="upperNeckPitch" type="revolute">
    <origin rpy="0.0 0.0 0.0" xyz="-0.06 0 0.195997"/>
    <axis xyz="0 1 0"/>
    <parent link="neckYawLink"/>
    <child link="upperNeckPitchLink"/>
    <limit effort="26" lower="-0.872" upper="0.0" velocity="5"/>
    <controller_gains Kd="3" Ki="0.0" Kp="50"/>
    <dynamics damping="0.1" friction="0.0"/>
  </joint>
  <gazebo reference="upperNeckPitch">
    <provideFeedback>1</provideFeedback>
    <implicitSpringDamper>1</implicitSpringDamper>
  </gazebo>
  <link name="multisense/head">
    <!-- Virtual Link -->
    <inertial>
      <mass value="1e-07"/>
      <origin rpy="0 0 0" xyz="0 0 0"/>
      <inertia ixx="3.3333333333333322e-22" ixy="0.0" ixz="0.0" iyy="3.3333333333333322e-22" iyz="0.0" izz="4.999999999999999e-22"/>
    </inertial>
  </link>
  <joint name="multisense_head_root_joint" type="fixed">
    <origin rpy="-3.14159 0.130899694 0.0" xyz="0.183585961 0.0 0.075353826"/>
    <axis xyz="0 0 1"/>
    <parent link="upperNeckPitchLink"/>
    <child link="multisense/head"/>
  </joint>
  <gazebo reference="multisense_head_root_joint">
    <implicitSpringDamper>1</implicitSpringDamper>
  </gazebo>
  <transmission name="lowerNeckPitchTransmission">
    <type>transmission_interface/SimpleTransmission</type>
    <joint name="lowerNeckPitch">
      <hardwareInterface>PositionJointInterface</hardwareInterface>
    </joint>
    <actuator name="lowerNeckPitch">
      <node name="/neck/j1"/>
      <mechanicalReduction>1</mechanicalReduction>
      <api name="robot_hardware_interface/TurbodriverAPI"/>
    </actuator>
  </transmission>
  <transmission name="neckYawTransmission">
    <type>transmission_interface/SimpleTransmission</type>
    <joint name="neckYaw">
      <hardwareInterface>PositionJointInterface</hardwareInterface>
    </joint>
    <actuator name="neckYaw">
      <node name="/neck/j2"/>
      <mechanicalReduction>1</mechanicalReduction>
      <api name="robot_hardware_interface/TurbodriverAPI"/>
    </actuator>
  </transmission>
  <transmission name="upperNeckPitchTransmission">
    <type>transmission_interface/SimpleTransmission</type>
    <joint name="upperNeckPitch">
      <hardwareInterface>PositionJointInterface</hardwareInterface>
    </joint>
    <actuator name="upperNeckPitch">
      <node name="/neck/j3"/>
      <mechanicalReduction>1</mechanicalReduction>
      <api name="robot_hardware_interface/TurbodriverAPI"/>
    </actuator>
  </transmission>
  <link name="rightHipYawLink">
    <inertial>
      <mass value="2.39"/>
      <origin rpy="0 0 0" xyz="0.02176 0.00131 0.03867"/>
      <inertia ixx="0.017260978" ixy="0.0" ixz="0.0" iyy="0.014866198" iyz="0.0" izz="0.011238178"/>
    </inertial>
    <visual>
      <geometry>
        <mesh filename="package://val_description/model/meshes/legs/lj1_right.dae"/>
      </geometry>
      <origin rpy="0.0 0.0 0.0" xyz="0.0 0.0 0.0"/>
    </visual>
    <collision>
      <geometry>
        <mesh filename="package://val_description/model/meshes/legs/lj1_right.dae"/>
      </geometry>
      <origin rpy="0 0 0" xyz="0 0 0"/>
    </collision>
  </link>
  <link name="rightHipRollLink">
    <inertial>
      <mass value="3.665"/>
      <origin rpy="0 0 0" xyz="0.012959 -0.00755 -0.015950"/>
      <inertia ixx="0.005978962" ixy="0.000234823" ixz="0.000553962" iyy="0.009372646" iyz="-0.000778956" izz="0.008193117"/>
    </inertial>
  </link>
  <link name="rightHipPitchLink">
    <inertial>
      <mass value="10.2"/>
      <origin rpy="0 0 0" xyz="0.016691 -0.091397 -0.207875"/>
      <inertia ixx="0.24083413" ixy="-3.5915e-05" ixz="0.003699383" iyy="0.25689705" iyz="0.001333005" izz="0.023276352"/>
    </inertial>
    <visual>
      <geometry>
        <mesh filename="package://val_description/model/meshes/legs/lj3_right.dae"/>
      </geometry>
      <origin rpy="0.0 0.0 0.0" xyz="0.0 0.0 0.0"/>
    </visual>
    <collision>
      <geometry>
        <mesh filename="package://val_description/model/meshes/legs/lj3_right.dae"/>
      </geometry>
      <origin rpy="0 0 0" xyz="0 0 0"/>
    </collision>
  </link>
  <link name="rightKneePitchLink">
    <inertial>
      <mass value="6.2"/>
      <origin rpy="0 0 0" xyz="-0.022183  0.001703  -0.189418"/>
      <inertia ixx="0.086935683" ixy="9.929e-05" ixz="0.000573207" iyy="0.091584066" iyz="0.000313745" izz="0.014017272"/>
    </inertial>
    <visual>
      <geometry>
        <mesh filename="package://val_description/model/meshes/legs/lj4_right.dae"/>
      </geometry>
      <origin rpy="0.0 0.0 0.0" xyz="0.0 0.0 0.0"/>
    </visual>
    <collision>
      <geometry>
        <mesh filename="package://val_description/model/meshes/legs/lj4_right.dae"/>
      </geometry>
      <origin rpy="0 0 0" xyz="0 0 0"/>
    </collision>
  </link>
  <link name="rightAnklePitchLink">
    <inertial>
      <mass value="0.03"/>
      <origin rpy="0 0 0" xyz="0.0 0.0 0.0"/>
      <inertia ixx="4.377e-06" ixy="0.0" ixz="0.0" iyy="4.322e-06" iyz="0.0" izz="7.015e-06"/>
    </inertial>
    <visual>
      <geometry>
        <mesh filename="package://val_description/model/meshes/legs/lj5.dae"/>
      </geometry>
      <origin rpy="0.0 0.0 0.0" xyz="0.0 0.0 0.0"/>
    </visual>
    <collision>
      <geometry>
        <mesh filename="package://val_description/model/meshes/legs/lj5.dae"/>
      </geometry>
      <origin rpy="0 0 0" xyz="0 0 0"/>
    </collision>
  </link>
  <link name="rightFoot">
    <inertial>
      <mass value="2.27"/>
      <origin rpy="0 0 0" xyz="0.037702  0.005161  -0.047634"/>
      <inertia ixx="0.00623936" ixy="0.000217174" ixz="0.001340587" iyy="0.017786991" iyz="-0.000187749" izz="0.020774433"/>
    </inertial>
    <visual>
      <geometry>
        <mesh filename="package://val_description/model/meshes/legs/foot.dae"/>
      </geometry>
      <origin rpy="0 0 0" xyz="0 0 0"/>
    </visual>
    <collision>
      <geometry>
        <box size="0.27 0.16 0.064"/>
      </geometry>
      <origin rpy="0.0 0.0 0.0" xyz="0.045 0.0 -0.056"/>
    </collision>
  </link>
  <!-- foot contact parameters copied from atlas_description in drcsim -->
  <gazebo reference="rightFoot">
    <!-- kp and kd for rubber -->
    <kp>1000000.0</kp>
    <kd>100.0</kd>
    <mu1>1.5</mu1>
    <mu2>1.5</mu2>
    <fdir1>1 0 0</fdir1>
    <maxVel>1.0</maxVel>
    <minDepth>0.00</minDepth>
  </gazebo>
  <joint name="rightHipYaw" type="revolute">
    <origin rpy="0.0 0.0 0.0" xyz="0.0 -0.1016 -0.1853"/>
    <axis xyz="0 0 1"/>
    <parent link="pelvis"/>
    <child link="rightHipYawLink"/>
    <limit effort="190" lower="-1.03" upper="0.38" velocity="5.89"/>
    <controller_gains Kd="0.0" Ki="0.0" Kp="0.0"/>
    <dynamics damping="0.1" friction="0.0"/>
  </joint>
  <gazebo reference="rightHipYaw">
    <provideFeedback>1</provideFeedback>
    <implicitSpringDamper>1</implicitSpringDamper>
  </gazebo>
  <joint name="rightHipRoll" type="revolute">
    <origin rpy="0.0 0.0 0.0" xyz="0.0 0.0 0.0"/>
    <axis xyz="1 0 0"/>
    <parent link="rightHipYawLink"/>
    <child link="rightHipRollLink"/>
    <limit effort="350" lower="-0.4815" upper="0.45" velocity="7"/>
    <controller_gains Kd="0.0" Ki="0.0" Kp="0.0"/>
    <dynamics damping="0.1" friction="0.0"/>
  </joint>
  <gazebo reference="rightHipRoll">
    <provideFeedback>1</provideFeedback>
    <implicitSpringDamper>1</implicitSpringDamper>
  </gazebo>
  <joint name="rightHipPitch" type="revolute">
    <origin rpy="0.0 0.0 0.0" xyz="0.0 0.0 -0.0609"/>
    <axis xyz="0 1 0"/>
    <parent link="rightHipRollLink"/>
    <child link="rightHipPitchLink"/>
    <limit effort="350" lower="-1.63" upper="1.549" velocity="6.11"/>
    <controller_gains Kd="0.0" Ki="0.0" Kp="0.0"/>
    <dynamics damping="0.1" friction="0.0"/>
  </joint>
  <gazebo reference="rightHipPitch">
    <provideFeedback>1</provideFeedback>
    <implicitSpringDamper>1</implicitSpringDamper>
  </gazebo>
  <joint name="rightKneePitch" type="revolute">
    <origin rpy="0.0 0.0 0.0" xyz="0.000112225 -0.0361046 -0.430959"/>
    <axis xyz="0 1 0"/>
    <parent link="rightHipPitchLink"/>
    <child link="rightKneePitchLink"/>
    <limit effort="350" lower="-0.055" upper="1.95" velocity="6.11"/>
    <controller_gains Kd="0.0" Ki="0.0" Kp="0.0"/>
    <dynamics damping="0.1" friction="0.0"/>
  </joint>
  <gazebo reference="rightKneePitch">
    <provideFeedback>1</provideFeedback>
    <implicitSpringDamper>1</implicitSpringDamper>
  </gazebo>
  <joint name="rightAnklePitch" type="revolute">
    <origin rpy="0.0 0.0 0.0" xyz="-0.0102381 0.0 -0.40627"/>
    <axis xyz="0 1 0"/>
    <parent link="rightKneePitchLink"/>
    <child link="rightAnklePitchLink"/>
    <limit effort="205" lower="-0.93" upper="0.65" velocity="11"/>
    <controller_gains Kd="0.0" Ki="0.0" Kp="0.0"/>
    <dynamics damping="0.1" friction="0.0"/>
  </joint>
  <gazebo reference="rightAnklePitch">
    <provideFeedback>1</provideFeedback>
    <implicitSpringDamper>1</implicitSpringDamper>
  </gazebo>
  <joint name="rightAnkleRoll" type="revolute">
    <origin rpy="0.0 0.0 0.0" xyz="0.0 0.0 0.0"/>
    <axis xyz="1 0 0"/>
    <parent link="rightAnklePitchLink"/>
    <child link="rightFoot"/>
    <limit effort="205" lower="-0.4" upper="0.4" velocity="11"/>
    <controller_gains Kd="0.0" Ki="0.0" Kp="0.0"/>
    <dynamics damping="0.3" friction="0.0"/>
  </joint>
  <gazebo reference="rightAnkleRoll">
    <provideFeedback>1</provideFeedback>
    <implicitSpringDamper>1</implicitSpringDamper>
  </gazebo>
  <link name="rightCOP_Frame">
    <inertial>
      <mass value="0.1"/>
      <origin rpy="0 0 0" xyz="0 0 0"/>
      <inertia ixx="8.333333333333336e-05" ixy="0.0" ixz="0.0" iyy="8.333333333333336e-05" iyz="0.0" izz="0.00012500000000000003"/>
    </inertial>
  </link>
  <joint name="rightCOP_Offset" type="fixed">
    <origin rpy="0.0 0.0 0.0" xyz="0.0189 0.0 -0.0783"/>
    <axis xyz="0 0 1"/>
    <parent link="rightFoot"/>
    <child link="rightCOP_Frame"/>
  </joint>
  <gazebo reference="rightCOP_Offset">
    <implicitSpringDamper>1</implicitSpringDamper>
  </gazebo>
  <link name="rightFootSixAxis_Frame">
    <!-- Virtual Link -->
    <inertial>
      <mass value="1e-07"/>
      <origin rpy="0 0 0" xyz="0 0 0"/>
      <inertia ixx="3.3333333333333322e-22" ixy="0.0" ixz="0.0" iyy="3.3333333333333322e-22" iyz="0.0" izz="4.999999999999999e-22"/>
    </inertial>
  </link>
  <joint name="rightFootSixAxis_Offset" type="fixed">
    <origin rpy="3.14 0.0 0.0" xyz="0.0215646 0.0 -0.051054"/>
    <axis xyz="0 0 1"/>
    <parent link="rightFoot"/>
    <child link="rightFootSixAxis_Frame"/>
  </joint>
  <gazebo reference="rightFootSixAxis_Offset">
    <implicitSpringDamper>1</implicitSpringDamper>
  </gazebo>
  <gazebo reference="rightAnkleRoll">
    <sensor name="rightFootSixAxis" type="force_torque">
      <pose>0.0215646 0.0 -0.051054 3.14 0.0 0.0</pose>
      <sensor_number id="FT14018"/>
      <node id="/right_leg/ankle/left_actuator"/>
      <api name="ati_sensor_interface::ATISensorInterface"/>
      <always_on>true</always_on>
      <update_rate>500.0</update_rate>
      <force_torque>
        <frame>sensor</frame>
        <measure_direction>parent_to_child</measure_direction>
      </force_torque>
    </sensor>
  </gazebo>
  <transmission name="rightHipYawTransmission">
    <type>transmission_interface/SimpleTransmission</type>
    <joint name="rightHipYaw">
      <hardwareInterface>EffortJointInterface</hardwareInterface>
    </joint>
    <actuator name="rightHipYaw">
      <node name="/pelvis/right_leg_j1"/>
      <mechanicalReduction>1</mechanicalReduction>
      <api name="robot_hardware_interface/TurbodriverAPI"/>
    </actuator>
  </transmission>
  <transmission name="rightHipRollTransmission">
    <type>transmission_interface/SimpleTransmission</type>
    <joint name="rightHipRoll">
      <hardwareInterface>EffortJointInterface</hardwareInterface>
    </joint>
    <actuator name="rightHipRoll">
      <node name="/right_leg/j2"/>
      <mechanicalReduction>1</mechanicalReduction>
      <api name="robot_hardware_interface/TurbodriverAPI"/>
    </actuator>
  </transmission>
  <transmission name="rightHipPitchTransmission">
    <type>transmission_interface/SimpleTransmission</type>
    <joint name="rightHipPitch">
      <hardwareInterface>EffortJointInterface</hardwareInterface>
    </joint>
    <actuator name="rightHipPitch">
      <node name="/right_leg/j3"/>
      <mechanicalReduction>1</mechanicalReduction>
      <api name="robot_hardware_interface/TurbodriverAPI"/>
    </actuator>
  </transmission>
  <transmission name="rightKneePitchTransmission">
    <type>transmission_interface/SimpleTransmission</type>
    <joint name="rightKneePitch">
      <hardwareInterface>EffortJointInterface</hardwareInterface>
    </joint>
    <actuator name="rightKneePitch">
      <node name="/right_leg/j4"/>
      <mechanicalReduction>1</mechanicalReduction>
      <api name="robot_hardware_interface/TurbodriverAPI"/>
    </actuator>
  </transmission>
  <transmission name="rightAnkleTransmission">
    <type>robot_transmission_interface::AnklePushrodTransmissionLoader</type>
    <joint name="rightAnklePitch">
      <role>pitch</role>
      <hardwareInterface>EffortJointInterface</hardwareInterface>
    </joint>
    <joint name="rightAnkleRoll">
      <role>roll</role>
      <hardwareInterface>EffortJointInterface</hardwareInterface>
    </joint>
    <actuator name="rightAnkleRightActuator">
      <node name="/right_leg/ankle/right_actuator"/>
      <role>right</role>
      <mechanicalReduction>1</mechanicalReduction>
      <api name="robot_hardware_interface/TurbodriverAPI_linear_futek"/>
    </actuator>
    <actuator name="rightAnkleLeftActuator">
      <node name="/right_leg/ankle/left_actuator"/>
      <role>left</role>
      <mechanicalReduction>1</mechanicalReduction>
      <api name="robot_hardware_interface/TurbodriverAPI_linear_futek"/>
    </actuator>
  </transmission>
  <link name="leftHipYawLink">
    <inertial>
      <mass value="2.39"/>
      <origin rpy="0 0 0" xyz="0.02176 -0.00131 0.03867"/>
      <inertia ixx="0.017260978" ixy="0.0" ixz="0.0" iyy="0.014866198" iyz="0.0" izz="0.011238178"/>
    </inertial>
    <visual>
      <geometry>
        <mesh filename="package://val_description/model/meshes/legs/lj1_left.dae"/>
      </geometry>
      <origin rpy="0.0 0.0 0.0" xyz="0.0 0.0 0.0"/>
    </visual>
    <collision>
      <geometry>
        <mesh filename="package://val_description/model/meshes/legs/lj1_left.dae"/>
      </geometry>
      <origin rpy="0 0 0" xyz="0 0 0"/>
    </collision>
  </link>
  <link name="leftHipRollLink">
    <inertial>
      <mass value="3.665"/>
      <origin rpy="0 0 0" xyz="0.012959 0.00755 -0.015950"/>
      <inertia ixx="0.005978962" ixy="-0.000234823" ixz="0.000553962" iyy="0.009372646" iyz="0.000778956" izz="0.008193117"/>
    </inertial>
  </link>
  <link name="leftHipPitchLink">
    <inertial>
      <mass value="10.2"/>
      <origin rpy="0 0 0" xyz="0.016691 0.091397 -0.207875"/>
      <inertia ixx="0.24083413" ixy="3.5915e-05" ixz="0.003699383" iyy="0.25689705" iyz="-0.001333005" izz="0.023276352"/>
    </inertial>
    <visual>
      <geometry>
        <mesh filename="package://val_description/model/meshes/legs/lj3_left.dae"/>
      </geometry>
      <origin rpy="0.0 0.0 0.0" xyz="0.0 0.0 0.0"/>
    </visual>
    <collision>
      <geometry>
        <mesh filename="package://val_description/model/meshes/legs/lj3_left.dae"/>
      </geometry>
      <origin rpy="0 0 0" xyz="0 0 0"/>
    </collision>
  </link>
  <link name="leftKneePitchLink">
    <inertial>
      <mass value="6.2"/>
      <origin rpy="0 0 0" xyz="-0.022183  0.001703  -0.189418"/>
      <inertia ixx="0.086935683" ixy="9.929e-05" ixz="0.000573207" iyy="0.091584066" iyz="0.000313745" izz="0.014017272"/>
    </inertial>
    <visual>
      <geometry>
        <mesh filename="package://val_description/model/meshes/legs/lj4_left.dae"/>
      </geometry>
      <origin rpy="0.0 0.0 0.0" xyz="0.0 0.0 0.0"/>
    </visual>
    <collision>
      <geometry>
        <mesh filename="package://val_description/model/meshes/legs/lj4_left.dae"/>
      </geometry>
      <origin rpy="0 0 0" xyz="0 0 0"/>
    </collision>
  </link>
  <link name="leftAnklePitchLink">
    <inertial>
      <mass value="0.03"/>
      <origin rpy="0 0 0" xyz="0.0 0.0 0.0"/>
      <inertia ixx="4.377e-06" ixy="0.0" ixz="0.0" iyy="4.322e-06" iyz="0.0" izz="7.015e-06"/>
    </inertial>
    <visual>
      <geometry>
        <mesh filename="package://val_description/model/meshes/legs/lj5.dae"/>
      </geometry>
      <origin rpy="0.0 0.0 0.0" xyz="0.0 0.0 0.0"/>
    </visual>
    <collision>
      <geometry>
        <mesh filename="package://val_description/model/meshes/legs/lj5.dae"/>
      </geometry>
      <origin rpy="0 0 0" xyz="0 0 0"/>
    </collision>
  </link>
  <link name="leftFoot">
    <inertial>
      <mass value="2.27"/>
      <origin rpy="0 0 0" xyz="0.037702  0.005161  -0.047634"/>
      <inertia ixx="0.00623936" ixy="0.000217174" ixz="0.001340587" iyy="0.017786991" iyz="-0.000187749" izz="0.020774433"/>
    </inertial>
    <visual>
      <geometry>
        <mesh filename="package://val_description/model/meshes/legs/foot.dae"/>
      </geometry>
      <origin rpy="0 0 0" xyz="0 0 0"/>
    </visual>
    <collision>
      <geometry>
        <box size="0.27 0.16 0.064"/>
      </geometry>
      <origin rpy="0.0 0.0 0.0" xyz="0.045 0.0 -0.056"/>
    </collision>
  </link>
  <!-- foot contact parameters copied from atlas_description in drcsim -->
  <gazebo reference="leftFoot">
    <!-- kp and kd for rubber -->
    <kp>1000000.0</kp>
    <kd>100.0</kd>
    <mu1>1.5</mu1>
    <mu2>1.5</mu2>
    <fdir1>1 0 0</fdir1>
    <maxVel>1.0</maxVel>
    <minDepth>0.00</minDepth>
  </gazebo>
  <joint name="leftHipYaw" type="revolute">
    <origin rpy="0.0 0.0 0.0" xyz="0.0 0.1016 -0.1853"/>
    <axis xyz="0 0 1"/>
    <parent link="pelvis"/>
    <child link="leftHipYawLink"/>
    <limit effort="190" lower="-0.38" upper="1.03" velocity="5.89"/>
    <controller_gains Kd="0.0" Ki="0.0" Kp="0.0"/>
    <dynamics damping="0.1" friction="0.0"/>
  </joint>
  <gazebo reference="leftHipYaw">
    <provideFeedback>1</provideFeedback>
    <implicitSpringDamper>1</implicitSpringDamper>
  </gazebo>
  <joint name="leftHipRoll" type="revolute">
    <origin rpy="0.0 0.0 0.0" xyz="0.0 0.0 0.0"/>
    <axis xyz="1 0 0"/>
    <parent link="leftHipYawLink"/>
    <child link="leftHipRollLink"/>
    <limit effort="350" lower="-0.45" upper="0.4815" velocity="7"/>
    <controller_gains Kd="0.0" Ki="0.0" Kp="0.0"/>
    <dynamics damping="0.1" friction="0.0"/>
  </joint>
  <gazebo reference="leftHipRoll">
    <provideFeedback>1</provideFeedback>
    <implicitSpringDamper>1</implicitSpringDamper>
  </gazebo>
  <joint name="leftHipPitch" type="revolute">
    <origin rpy="0.0 0.0 0.0" xyz="0.0 0.0 -0.0609"/>
    <axis xyz="0 1 0"/>
    <parent link="leftHipRollLink"/>
    <child link="leftHipPitchLink"/>
    <limit effort="350" lower="-1.63" upper="1.549" velocity="6.11"/>
    <controller_gains Kd="0.0" Ki="0.0" Kp="0.0"/>
    <dynamics damping="0.1" friction="0.0"/>
  </joint>
  <gazebo reference="leftHipPitch">
    <provideFeedback>1</provideFeedback>
    <implicitSpringDamper>1</implicitSpringDamper>
  </gazebo>
  <joint name="leftKneePitch" type="revolute">
    <origin rpy="0.0 0.0 0.0" xyz="0.000112225 0.0361046 -0.430959"/>
    <axis xyz="0 1 0"/>
    <parent link="leftHipPitchLink"/>
    <child link="leftKneePitchLink"/>
    <limit effort="350" lower="-0.055" upper="1.95" velocity="6.11"/>
    <controller_gains Kd="0.0" Ki="0.0" Kp="0.0"/>
    <dynamics damping="0.1" friction="0.0"/>
  </joint>
  <gazebo reference="leftKneePitch">
    <provideFeedback>1</provideFeedback>
    <implicitSpringDamper>1</implicitSpringDamper>
  </gazebo>
  <joint name="leftAnklePitch" type="revolute">
    <origin rpy="0.0 0.0 0.0" xyz="-0.0102381 0.0 -0.40627"/>
    <axis xyz="0 1 0"/>
    <parent link="leftKneePitchLink"/>
    <child link="leftAnklePitchLink"/>
    <limit effort="205" lower="-0.93" upper="0.65" velocity="11"/>
    <controller_gains Kd="0.0" Ki="0.0" Kp="0.0"/>
    <dynamics damping="0.1" friction="0.0"/>
  </joint>
  <gazebo reference="leftAnklePitch">
    <provideFeedback>1</provideFeedback>
    <implicitSpringDamper>1</implicitSpringDamper>
  </gazebo>
  <joint name="leftAnkleRoll" type="revolute">
    <origin rpy="0.0 0.0 0.0" xyz="0.0 0.0 0.0"/>
    <axis xyz="1 0 0"/>
    <parent link="leftAnklePitchLink"/>
    <child link="leftFoot"/>
    <limit effort="205" lower="-0.4" upper="0.4" velocity="11"/>
    <controller_gains Kd="0.0" Ki="0.0" Kp="0.0"/>
    <dynamics damping="0.3" friction="0.0"/>
  </joint>
  <gazebo reference="leftAnkleRoll">
    <provideFeedback>1</provideFeedback>
    <implicitSpringDamper>1</implicitSpringDamper>
  </gazebo>
  <link name="leftCOP_Frame">
    <inertial>
      <mass value="0.1"/>
      <origin rpy="0 0 0" xyz="0 0 0"/>
      <inertia ixx="8.333333333333336e-05" ixy="0.0" ixz="0.0" iyy="8.333333333333336e-05" iyz="0.0" izz="0.00012500000000000003"/>
    </inertial>
  </link>
  <joint name="leftCOP_Offset" type="fixed">
    <origin rpy="0.0 0.0 0.0" xyz="0.0189 0.0 -0.0783"/>
    <axis xyz="0 0 1"/>
    <parent link="leftFoot"/>
    <child link="leftCOP_Frame"/>
  </joint>
  <gazebo reference="leftCOP_Offset">
    <implicitSpringDamper>1</implicitSpringDamper>
  </gazebo>
  <link name="leftFootSixAxis_Frame">
    <!-- Virtual Link -->
    <inertial>
      <mass value="1e-07"/>
      <origin rpy="0 0 0" xyz="0 0 0"/>
      <inertia ixx="3.3333333333333322e-22" ixy="0.0" ixz="0.0" iyy="3.3333333333333322e-22" iyz="0.0" izz="4.999999999999999e-22"/>
    </inertial>
  </link>
  <joint name="leftFootSixAxis_Offset" type="fixed">
    <origin rpy="3.14 0.0 0.0" xyz="0.0215646 0.0 -0.051054"/>
    <axis xyz="0 0 1"/>
    <parent link="leftFoot"/>
    <child link="leftFootSixAxis_Frame"/>
  </joint>
  <gazebo reference="leftFootSixAxis_Offset">
    <implicitSpringDamper>1</implicitSpringDamper>
  </gazebo>
  <gazebo reference="leftAnkleRoll">
    <sensor name="leftFootSixAxis" type="force_torque">
      <pose>0.0215646 0.0 -0.051054 3.14 0.0 0.0</pose>
      <sensor_number id="FT17218"/>
      <node id="/left_leg/ankle/left_actuator"/>
      <api name="ati_sensor_interface::ATISensorInterface"/>
      <always_on>true</always_on>
      <update_rate>500.0</update_rate>
      <force_torque>
        <frame>sensor</frame>
        <measure_direction>parent_to_child</measure_direction>
      </force_torque>
    </sensor>
  </gazebo>
  <transmission name="leftHipYawTransmission">
    <type>transmission_interface/SimpleTransmission</type>
    <joint name="leftHipYaw">
      <hardwareInterface>EffortJointInterface</hardwareInterface>
    </joint>
    <actuator name="leftHipYaw">
      <node name="/pelvis/left_leg_j1"/>
      <mechanicalReduction>1</mechanicalReduction>
      <api name="robot_hardware_interface/TurbodriverAPI"/>
    </actuator>
  </transmission>
  <transmission name="leftHipRollTransmission">
    <type>transmission_interface/SimpleTransmission</type>
    <joint name="leftHipRoll">
      <hardwareInterface>EffortJointInterface</hardwareInterface>
    </joint>
    <actuator name="leftHipRoll">
      <node name="/left_leg/j2"/>
      <mechanicalReduction>1</mechanicalReduction>
      <api name="robot_hardware_interface/TurbodriverAPI"/>
    </actuator>
  </transmission>
  <transmission name="leftHipPitchTransmission">
    <type>transmission_interface/SimpleTransmission</type>
    <joint name="leftHipPitch">
      <hardwareInterface>EffortJointInterface</hardwareInterface>
    </joint>
    <actuator name="leftHipPitch">
      <node name="/left_leg/j3"/>
      <mechanicalReduction>1</mechanicalReduction>
      <api name="robot_hardware_interface/TurbodriverAPI"/>
    </actuator>
  </transmission>
  <transmission name="leftKneePitchTransmission">
    <type>transmission_interface/SimpleTransmission</type>
    <joint name="leftKneePitch">
      <hardwareInterface>EffortJointInterface</hardwareInterface>
    </joint>
    <actuator name="leftKneePitch">
      <node name="/left_leg/j4"/>
      <mechanicalReduction>1</mechanicalReduction>
      <api name="robot_hardware_interface/TurbodriverAPI"/>
    </actuator>
  </transmission>
  <transmission name="leftAnkleTransmission">
    <type>robot_transmission_interface::AnklePushrodTransmissionLoader</type>
    <joint name="leftAnklePitch">
      <role>pitch</role>
      <hardwareInterface>EffortJointInterface</hardwareInterface>
    </joint>
    <joint name="leftAnkleRoll">
      <role>roll</role>
      <hardwareInterface>EffortJointInterface</hardwareInterface>
    </joint>
    <actuator name="leftAnkleRightActuator">
      <node name="/left_leg/ankle/right_actuator"/>
      <role>right</role>
      <mechanicalReduction>1</mechanicalReduction>
      <api name="robot_hardware_interface/TurbodriverAPI_linear_futek"/>
    </actuator>
    <actuator name="leftAnkleLeftActuator">
      <node name="/left_leg/ankle/left_actuator"/>
      <role>left</role>
      <mechanicalReduction>1</mechanicalReduction>
      <api name="robot_hardware_interface/TurbodriverAPI_linear_futek"/>
    </actuator>
  </transmission>
  <link name="rightShoulderPitchLink">
    <inertial>
      <mass value="2.65"/>
      <origin rpy="0 0 0" xyz="0.012 -0.251 0.000000"/>
      <inertia ixx="0.013718167" ixy="0.0" ixz="0.0" iyy="0.010502833" iyz="0.0" izz="0.014806433"/>
    </inertial>
    <visual>
      <geometry>
        <mesh filename="package://val_description/model/meshes/arms/aj1_right.dae"/>
      </geometry>
      <origin rpy="0.0 0.0 0.0" xyz="0.0 0.0 0.0"/>
    </visual>
    <collision>
      <geometry>
        <mesh filename="package://val_description/model/meshes/arms/aj1_right.dae"/>
      </geometry>
      <origin rpy="0 0 0" xyz="0 0 0"/>
    </collision>
  </link>
  <link name="rightShoulderRollLink">
    <inertial>
      <mass value="3.97"/>
      <origin rpy="0 0 0" xyz="0.008513 -0.02068 -0.001088"/>
      <inertia ixx="0.014598842" ixy="-0.00066764" ixz="3.629e-05" iyy="0.006452136" iyz="8.283e-05" izz="0.016848319"/>
    </inertial>
    <visual>
      <geometry>
        <mesh filename="package://val_description/model/meshes/arms/aj2_right.dae"/>
      </geometry>
      <origin rpy="0.0 0.0 0.0" xyz="0.0 0.0 0.0"/>
    </visual>
    <collision>
      <geometry>
        <mesh filename="package://val_description/model/meshes/arms/aj2_right.dae"/>
      </geometry>
      <origin rpy="0 0 0" xyz="0 0 0"/>
    </collision>
  </link>
  <link name="rightShoulderYawLink">
    <inertial>
      <mass value="3.085"/>
      <origin rpy="0 0 0" xyz="-0.004304 -0.209832 -0.007295"/>
      <inertia ixx="0.039355177" ixy="0.007827077" ixz="0.000753947" iyy="0.004905765" iyz="-0.002723873" izz="0.041879481"/>
    </inertial>
    <visual>
      <geometry>
        <mesh filename="package://val_description/model/meshes/arms/aj3_right.dae"/>
      </geometry>
      <origin rpy="0.0 0.0 0.0" xyz="0.0 0.0 0.0"/>
    </visual>
    <collision>
      <geometry>
        <mesh filename="package://val_description/model/meshes/arms/aj3_right.dae"/>
      </geometry>
      <origin rpy="0 0 0" xyz="0 0 0"/>
    </collision>
  </link>
  <link name="rightElbowPitchLink">
    <inertial>
      <mass value="1.83"/>
      <origin rpy="0 0 0" xyz="-0.020344 -0.014722 -0.0223"/>
      <inertia ixx="0.003314516" ixy="-0.000535099" ixz="-0.000728077" iyy="0.003505669" iyz="-0.000423865" izz="0.003011283"/>
    </inertial>
    <visual>
      <geometry>
        <mesh filename="package://val_description/model/meshes/arms/aj4_right.dae"/>
      </geometry>
      <origin rpy="0.0 0.0 0.0" xyz="0.0 0.0 0.0"/>
    </visual>
    <collision>
      <geometry>
        <mesh filename="package://val_description/model/meshes/arms/aj4_right.dae"/>
      </geometry>
      <origin rpy="0 0 0" xyz="0 0 0"/>
    </collision>
  </link>
  <joint name="rightShoulderPitch" type="revolute">
    <origin rpy="0.0 0.0 0.0" xyz="-0.0316 0.0 0.2984"/>
    <axis xyz="0 1 0"/>
    <parent link="torso"/>
    <child link="rightShoulderPitchLink"/>
    <limit effort="190" lower="-2.78" upper="1.93" velocity="5.89"/>
    <controller_gains Kd="0.0" Ki="0.0" Kp="0.0"/>
    <dynamics damping="0.1" friction="0.0"/>
  </joint>
  <gazebo reference="rightShoulderPitch">
    <provideFeedback>1</provideFeedback>
    <implicitSpringDamper>1</implicitSpringDamper>
  </gazebo>
  <joint name="rightShoulderRoll" type="revolute">
    <origin rpy="0.0 0.0 0.0" xyz="0.0 -0.2499 0.0"/>
    <axis xyz="1 0 0"/>
    <parent link="rightShoulderPitchLink"/>
    <child link="rightShoulderRollLink"/>
    <limit effort="190" lower="-1.196" upper="1.449" velocity="5.89"/>
    <controller_gains Kd="0.0" Ki="0.0" Kp="0.0"/>
    <dynamics damping="0.1" friction="0.0"/>
  </joint>
  <gazebo reference="rightShoulderRoll">
    <provideFeedback>1</provideFeedback>
    <implicitSpringDamper>1</implicitSpringDamper>
  </gazebo>
  <joint name="rightShoulderYaw" type="revolute">
    <origin rpy="0.0 0.0 0.0" xyz="0.0 0.0 0.0"/>
    <axis xyz="0 1 0"/>
    <parent link="rightShoulderRollLink"/>
    <child link="rightShoulderYawLink"/>
    <limit effort="65" lower="-3.03" upper="3.03" velocity="11.5"/>
    <controller_gains Kd="0.0" Ki="0.0" Kp="0.0"/>
    <dynamics damping="0.1" friction="0.0"/>
  </joint>
  <gazebo reference="rightShoulderYaw">
    <provideFeedback>1</provideFeedback>
    <implicitSpringDamper>1</implicitSpringDamper>
  </gazebo>
  <joint name="rightElbowPitch" type="revolute">
    <origin rpy="0.0 0.0 0.0" xyz="0.0254 -0.33 0.0"/>
    <axis xyz="0 0 1"/>
    <parent link="rightShoulderYawLink"/>
    <child link="rightElbowPitchLink"/>
    <limit effort="65" lower="-0.04" upper="2.13" velocity="11.5"/>
    <controller_gains Kd="0.0" Ki="0.0" Kp="0.0"/>
    <dynamics damping="0.1" friction="0.0"/>
  </joint>
  <gazebo reference="rightElbowPitch">
    <provideFeedback>1</provideFeedback>
    <implicitSpringDamper>1</implicitSpringDamper>
  </gazebo>
  <!--                 LINK DEFINITIONS                 -->
  <link name="rightForearmLink">
    <inertial>
      <mass value="2.476"/>
      <origin rpy="0 0 0" xyz="0.015000 -0.13 0.019564"/>
      <inertia ixx="0.01175543" ixy="-0.001300853" ixz="-0.000727141" iyy="0.005071567" iyz="-0.001695416" izz="0.011365657"/>
    </inertial>
    <visual>
      <geometry>
        <mesh filename="package://val_description/model/meshes/arms/aj5_right.dae"/>
      </geometry>
      <origin rpy="0.0 0.0 0.0" xyz="0.0 0.0 0.0"/>
    </visual>
    <collision>
      <geometry>
        <mesh filename="package://val_description/model/meshes/arms/aj5_right.dae"/>
      </geometry>
      <origin rpy="0 0 0" xyz="0 0 0"/>
    </collision>
  </link>
  <link name="rightWristRollLink">
    <inertial>
      <mass value="0.14"/>
      <origin rpy="0 0 0" xyz="0 0 0"/>
      <inertia ixx="3.0251e-05" ixy="-1.25e-07" ixz="-3.6e-08" iyy="3.772e-05" iyz="0.0" izz="9.395e-06"/>
    </inertial>
    <visual>
      <geometry>
        <mesh filename="package://val_description/model/meshes/arms/aj6_right.dae"/>
      </geometry>
      <origin rpy="0.0 0.0 0.0" xyz="0.0 0.0 0.0"/>
    </visual>
    <collision>
      <geometry>
        <mesh filename="package://val_description/model/meshes/arms/aj6_right.dae"/>
      </geometry>
      <origin rpy="0 0 0" xyz="0 0 0"/>
    </collision>
  </link>
  <link name="rightWristPitchFrame">
    <!-- Virtual Link -->
    <inertial>
      <mass value="1e-07"/>
      <origin rpy="0 0 0" xyz="0 0 0"/>
      <inertia ixx="3.3333333333333322e-22" ixy="0.0" ixz="0.0" iyy="3.3333333333333322e-22" iyz="0.0" izz="4.999999999999999e-22"/>
    </inertial>
  </link>
  <!--                 JOINT DEFINITIONS                 -->
  <joint name="rightForearmYaw" type="revolute">
    <origin rpy="0.0 0.0 0.0" xyz="-0.0254 0 0"/>
    <axis xyz="0 1 0"/>
    <parent link="rightElbowPitchLink"/>
    <child link="rightForearmLink"/>
    <limit effort="26" lower="-2.019" upper="3.14" velocity="5"/>
    <controller_gains Kd="0.0" Ki="0.0" Kp="1000"/>
    <dynamics damping="0.1" friction="0.0"/>
  </joint>
  <gazebo reference="rightForearmYaw">
    <provideFeedback>1</provideFeedback>
    <implicitSpringDamper>1</implicitSpringDamper>
  </gazebo>
  <joint name="rightWristRoll" type="revolute">
    <origin rpy="0.0 0.0 0.0" xyz="0.0 -0.2871 0.0"/>
    <axis xyz="1 0 0"/>
    <parent link="rightForearmLink"/>
    <child link="rightWristRollLink"/>
    <limit effort="14" lower="-0.35" upper="0.35" velocity="1"/>
    <controller_gains Kd="0" Ki="0.0" Kp="500"/>
    <dynamics damping="0.1" friction="0.0"/>
  </joint>
  <gazebo reference="rightWristRoll">
    <provideFeedback>1</provideFeedback>
    <implicitSpringDamper>1</implicitSpringDamper>
  </gazebo>
  <joint name="rightWristPitch" type="revolute">
    <origin rpy="0.0 0.0 0.0" xyz="0.0 0.0 0.0"/>
    <axis xyz="0 0 1"/>
    <parent link="rightWristRollLink"/>
    <child link="rightWristPitchFrame"/>
    <limit effort="14" lower="-0.6" upper="0.6" velocity="1"/>
    <controller_gains Kd="0" Ki="0.0" Kp="500"/>
    <dynamics damping="0.1" friction="0.0"/>
  </joint>
  <gazebo reference="rightWristPitch">
    <provideFeedback>1</provideFeedback>
    <implicitSpringDamper>1</implicitSpringDamper>
  </gazebo>
  <transmission name="rightShoulderPitchTransmission">
    <type>transmission_interface/SimpleTransmission</type>
    <joint name="rightShoulderPitch">
      <hardwareInterface>EffortJointInterface</hardwareInterface>
    </joint>
    <actuator name="rightShoulderPitch">
      <node name="/trunk/right_arm_j1"/>
      <mechanicalReduction>1</mechanicalReduction>
      <api name="robot_hardware_interface/TurbodriverAPI"/>
    </actuator>
  </transmission>
  <transmission name="rightShoulderRollTransmission">
    <type>transmission_interface/SimpleTransmission</type>
    <joint name="rightShoulderRoll">
      <hardwareInterface>EffortJointInterface</hardwareInterface>
    </joint>
    <actuator name="rightShoulderRoll">
      <node name="/right_arm/j2"/>
      <mechanicalReduction>1</mechanicalReduction>
      <api name="robot_hardware_interface/TurbodriverAPI"/>
    </actuator>
  </transmission>
  <transmission name="rightShoulderYawTransmission">
    <type>transmission_interface/SimpleTransmission</type>
    <joint name="rightShoulderYaw">
      <hardwareInterface>EffortJointInterface</hardwareInterface>
    </joint>
    <actuator name="rightShoulderYaw">
      <node name="/right_arm/j3"/>
      <mechanicalReduction>1</mechanicalReduction>
      <api name="robot_hardware_interface/TurbodriverAPI"/>
    </actuator>
  </transmission>
  <transmission name="rightElbowPitchTransmission">
    <type>transmission_interface/SimpleTransmission</type>
    <joint name="rightElbowPitch">
      <hardwareInterface>EffortJointInterface</hardwareInterface>
    </joint>
    <actuator name="rightElbowPitch">
      <node name="/right_arm/j4"/>
      <mechanicalReduction>1</mechanicalReduction>
      <api name="robot_hardware_interface/TurbodriverAPI"/>
    </actuator>
  </transmission>
  <transmission name="rightForearmYawTransmission">
    <type>transmission_interface/SimpleTransmission</type>
    <joint name="rightForearmYaw">
      <hardwareInterface>EffortJointInterface</hardwareInterface>
    </joint>
    <actuator name="rightForearmYaw">
      <node name="/right_arm/j5"/>
      <mechanicalReduction>1</mechanicalReduction>
      <api name="robot_hardware_interface/TurbodriverAPI"/>
    </actuator>
  </transmission>
  <transmission name="rightWristTransmission">
    <type>robot_transmission_interface/WristPushrodTransmission</type>
    <joint name="rightWristPitch">
      <role>pitch</role>
      <hardwareInterface>EffortJointInterface</hardwareInterface>
    </joint>
    <joint name="rightWristRoll">
      <role>roll</role>
      <hardwareInterface>EffortJointInterface</hardwareInterface>
    </joint>
    <actuator name="rightWristRightActuator">
      <node name="/right_arm/wrist/right_actuator"/>
      <role>bottom</role>
      <mechanicalReduction>1</mechanicalReduction>
      <api name="robot_hardware_interface/TurbodriverAPI_linear_futek"/>
    </actuator>
    <actuator name="rightWristLeftActuator">
      <node name="/right_arm/wrist/left_actuator"/>
      <role>top</role>
      <mechanicalReduction>1</mechanicalReduction>
      <api name="robot_hardware_interface/TurbodriverAPI_linear_futek"/>
    </actuator>
  </transmission>
  <transmission name="rightIndexFingerMotorPitch1Transmission">
    <type>transmission_interface/SimpleTransmission</type>
    <joint name="rightIndexFingerMotorPitch1">
      <hardwareInterface>EffortJointInterface</hardwareInterface>
    </joint>
    <actuator name="rightIndexFingerMotorPitch1">
      <node name="/right_arm/hand/index"/>
      <mechanicalReduction>1</mechanicalReduction>
      <api name="robot_hardware_interface/TurbodriverAPI"/>
    </actuator>
  </transmission>
  <transmission name="rightMiddleFingerMotorPitch1Transmission">
    <type>transmission_interface/SimpleTransmission</type>
    <joint name="rightMiddleFingerMotorPitch1">
      <hardwareInterface>EffortJointInterface</hardwareInterface>
    </joint>
    <actuator name="rightMiddleFingerMotorPitch1">
      <node name="/right_arm/hand/middle"/>
      <mechanicalReduction>1</mechanicalReduction>
      <api name="robot_hardware_interface/TurbodriverAPI"/>
    </actuator>
  </transmission>
  <transmission name="rightPinkyMotorPitch1Transmission">
    <type>transmission_interface/SimpleTransmission</type>
    <joint name="rightPinkyMotorPitch1">
      <hardwareInterface>EffortJointInterface</hardwareInterface>
    </joint>
    <actuator name="rightPinkyMotorPitch1">
      <node name="/right_arm/hand/pinky"/>
      <mechanicalReduction>1</mechanicalReduction>
      <api name="robot_hardware_interface/TurbodriverAPI"/>
    </actuator>
  </transmission>
  <transmission name="rightThumbMotorRollTransmission">
    <type>transmission_interface/SimpleTransmission</type>
    <joint name="rightThumbMotorRoll">
      <hardwareInterface>EffortJointInterface</hardwareInterface>
    </joint>
    <actuator name="rightThumbMotorRoll">
      <node name="/right_arm/hand/thumb_roll"/>
      <mechanicalReduction>1</mechanicalReduction>
      <api name="robot_hardware_interface/TurbodriverAPI"/>
    </actuator>
  </transmission>
  <transmission name="rightThumbMotorPitch1Transmission">
    <type>transmission_interface/SimpleTransmission</type>
    <joint name="rightThumbMotorPitch1">
      <hardwareInterface>EffortJointInterface</hardwareInterface>
    </joint>
    <actuator name="rightThumbMotorPitch1">
      <node name="/right_arm/hand/thumb_proximal"/>
      <mechanicalReduction>1</mechanicalReduction>
      <api name="robot_hardware_interface/TurbodriverAPI"/>
    </actuator>
  </transmission>
  <transmission name="rightThumbMotorPitch2Transmission">
    <type>transmission_interface/SimpleTransmission</type>
    <joint name="rightThumbMotorPitch2">
      <hardwareInterface>EffortJointInterface</hardwareInterface>
    </joint>
    <actuator name="rightThumbMotorPitch2">
      <node name="/right_arm/hand/thumb_distal"/>
      <mechanicalReduction>1</mechanicalReduction>
      <api name="robot_hardware_interface/TurbodriverAPI"/>
    </actuator>
  </transmission>
  <!-- if val hand -->
  <!-- if zimmer gripper -->
  <link name="rightPsyonicAdapter">
    <inertial>
      <mass value="0.1"/>
      <origin rpy="0 0 0" xyz="0 0 0"/>
      <inertia ixx="1e-06" ixy="1e-06" ixz="1e-06" iyy="1e-06" iyz="1e-06" izz="1e-06"/>
    </inertial>
    <visual>
      <geometry>
        <mesh filename="package://val_description/model/meshes/psyonic/psyonic_adapter_right.dae"/>
      </geometry>
      <origin rpy="0.0 0.0 0.0" xyz="0.0 0.0 0.0"/>
    </visual>
    <collision>
      <geometry>
        <mesh filename="package://val_description/model/meshes/psyonic/psyonic_adapter_right.dae"/>
      </geometry>
      <origin rpy="0 0 0" xyz="0 0 0"/>
    </collision>
  </link>
  <material name="right_psyonic_black">
    <color rgba="0.2 0.2 0.2 1"/>
  </material>
  <joint name="psyonic_base_joint_right" type="fixed">
    <parent link="rightPsyonicAdapter"/>
    <child link="base_right"/>
    <origin rpy="1.57079632679 1.57079632679 0.0" xyz="-0.0 -0.01 0.0"/>
  </joint>
  <link name="base_right">
    <visual name="wrist_mesh_right">
      <material name="right_psyonic_black"/>
      <origin rpy="0 0 0" xyz="0 0 0"/>
      <geometry>
        <mesh filename="package://psyonic_hand_description/urdf/models/wristmesh.STL"/>
      </geometry>
    </visual>
    <inertial>
      <!-- the mass and inertia here are NOT correct -->
      <mass value="0.200"/>
      <inertia ixx="978.26e-6" ixy="87.34e-6" ixz="322.99e-6" iyy="1244.78e-6" iyz="244.74e-6" izz="456.22e-6"/>
      <origin rpy="0 0 0" xyz="22.41911e-3 -0.15798201e-3 -0.01319866e-3"/>
    </inertial>
  </link>
  <joint name="wrist2thumb_right" type="fixed">
    <parent link="base_right"/>
    <child link="thumb_base_right"/>
    <origin rpy="3.14148426 -0.08848813 -3.14036612" xyz="-24.0476665e-3 3.78124745e-3 32.32964923e-3"/>
  </joint>
  <link name="thumb_base_right">
    <inertial>
      <mass value="0.200"/>
      <inertia ixx="978.26e-6" ixy="87.34e-6" ixz="322.99e-6" iyy="1244.78e-6" iyz="244.74e-6" izz="456.22e-6"/>
      <origin rpy="0 0 0" xyz="22.41911e-3 -0.15798201e-3 -0.01319866e-3"/>
    </inertial>
    <visual name="palm_mesh_right">
      <material name="right_psyonic_black"/>
      <origin rpy="0 0 0" xyz="0 0 0"/>
      <geometry>
        <mesh filename="package://psyonic_hand_description/urdf/models/FB_palm_ref_MIR.STL"/>
      </geometry>
    </visual>
  </link>
  <link name="index_L1_right">
    <inertial>
      <mass value="0.00635888"/>
      <inertia ixx="0.29766e-6" ixy="-0.06447133e-6" ixz="-0.00423315e-6" iyy="3.6947967e-6" iyz="0.00083028e-6" izz="3.8176336e-6"/>
      <origin rpy="0 0 0" xyz="22.41911e-3 -0.15798201e-3 -0.01319866e-3"/>
    </inertial>
    <visual name="index_mesh_1_right">
      <material name="right_psyonic_black"/>
      <origin rpy="0 0 0.084474" xyz="38.472723e-3 3.257695e-3 0.000000"/>
      <geometry>
        <mesh filename="package://psyonic_hand_description/urdf/models/idx-F1.STL"/>
      </geometry>
    </visual>
  </link>
  <link name="index_L2_right">
    <inertial>
      <mass value="0.00645"/>
      <inertia ixx="0.82671e-6" ixy="-1.08876e-6" ixz="-0.00037e-6" iyy="1.98028e-6" iyz="0.00081e-6" izz="2.64638e-6"/>
      <origin rpy="0 0 0" xyz="13.36818e-3 -8.75392e-3 -0.02886e-3"/>
    </inertial>
    <visual name="index_mesh_2_right">
      <material name="right_psyonic_black"/>
      <origin rpy="0 0 0" xyz="9.1241e-3 0 0"/>
      <geometry>
        <mesh filename="package://psyonic_hand_description/urdf/models/idx-F2.STL"/>
      </geometry>
    </visual>
  </link>
  <joint name="index_q1_right" type="revolute">
    <parent link="thumb_base_right"/>
    <child link="index_L1_right"/>
    <origin rpy=" -1.1595426535897932 1.284473 -1.0510016535897932 " xyz=" 9.49e-3 -13.04e-3 -62.95e-3 "/>
    <axis xyz="0 0 1"/>
    <limit effort="0.20" lower="0" upper="2.0943951" velocity="8.0677777442"/>
    <!-- angles in rad, efforts in N-m, velocity in rad/s -->
    <dynamics damping="0.001" friction="0.001"/>
    <!-- Friction coefficient is not from quantitative measurement -->
  </joint>
  <joint name="index_q2_right" type="revolute">
    <parent link="index_L1_right"/>
    <child link="index_L2_right"/>
    <origin rpy="0 0 0.084474" xyz="38.472723e-3 3.257695e-3 0.000000e-3"/>
    <axis xyz="0 0 1"/>
    <limit effort="0.20" lower="0.0" upper="2.6586" velocity="8.0677777442"/>
    <!-- angles in rad, efforts in N-m, velocity in rad/s -->
    <dynamics damping="0.001" friction="0.001"/>
    <!-- Friction coefficient is not from quantitative measurement -->
    <mimic joint="index_q1_right" multiplier="1.05851325" offset="0.72349796"/>
  </joint>
  <link name="index_anchor_right"/>
  <joint name="idx_anchor_right" type="fixed">
    <parent link="index_L2_right"/>
    <child link="index_anchor_right"/>
    <origin rpy="0 0 0" xyz="31.5541e-3  -10.44e-3 0.14e-3"/>
  </joint>
  <link name="middle_L1_right">
    <inertial>
      <mass value="0.00635888"/>
      <inertia ixx="0.29766e-6" ixy="-0.06447133e-6" ixz="-0.00423315e-6" iyy="3.6947967e-6" iyz="0.00083028e-6" izz="3.8176336e-6"/>
      <origin rpy="0 0 0" xyz="22.41911e-3 -0.15798201e-3 -0.01319866e-3"/>
    </inertial>
    <visual name="middle_mesh_1_right">
      <material name="right_psyonic_black"/>
      <origin rpy="0 0 0.084474" xyz="38.472723e-3 3.257695e-3 0.000000"/>
      <geometry>
        <mesh filename="package://psyonic_hand_description/urdf/models/idx-F1.STL"/>
      </geometry>
    </visual>
  </link>
  <link name="middle_L2_right">
    <inertial>
      <mass value="0.00645"/>
      <inertia ixx="0.82671e-6" ixy="-1.08876e-6" ixz="-0.00037e-6" iyy="1.98028e-6" iyz="0.00081e-6" izz="2.64638e-6"/>
      <origin rpy="0 0 0" xyz="13.36818e-3 -8.75392e-3 -0.02886e-3"/>
    </inertial>
    <visual name="middle_mesh_2_right">
      <material name="right_psyonic_black"/>
      <origin rpy="0 0 0" xyz="9.1241e-3 0 0"/>
      <geometry>
        <mesh filename="package://psyonic_hand_description/urdf/models/idx-F2.STL"/>
      </geometry>
    </visual>
  </link>
  <joint name="middle_q1_right" type="revolute">
    <parent link="thumb_base_right"/>
    <child link="middle_L1_right"/>
    <origin rpy=" -1.2810616535897934 1.308458 -1.2453756535897933 " xyz=" -9.653191e-3 -15.310271e-3 -67.853949e-3 "/>
    <limit effort="0.20" lower="0" upper="2.0943951" velocity="8.0677777442"/>
    <!-- angles in rad, efforts in N-m, velocity in rad/s -->
    <dynamics damping="0.001" friction="0.001"/>
    <!-- Friction coefficient is not from quantitative measurement -->
    <axis xyz="0 0 1"/>
  </joint>
  <joint name="middle_q2_right" type="revolute">
    <parent link="middle_L1_right"/>
    <child link="middle_L2_right"/>
    <origin rpy="0 0 0.084474" xyz="38.472723e-3 3.257695e-3 0.000000"/>
    <axis xyz="0 0 1"/>
    <limit effort="0.20" lower="0.0" upper="2.6586" velocity="8.0677777442"/>
    <!-- angles in rad, efforts in N-m, velocity in rad/s -->
    <dynamics damping="0.001" friction="0.001"/>
    <!-- Friction coefficient is not from quantitative measurement -->
    <mimic joint="middle_q1_right" multiplier="1.05851325" offset="0.72349796"/>
  </joint>
  <link name="middle_anchor_right"/>
  <joint name="mid_anchor_right" type="fixed">
    <parent link="middle_L2_right"/>
    <child link="middle_anchor_right"/>
    <origin rpy="0 0 0" xyz="31.5541e-3  -10.44e-3 0.14e-3"/>
  </joint>
  <link name="ring_L1_right">
    <inertial>
      <mass value="0.00635888"/>
      <inertia ixx="0.29766e-6" ixy="-0.06447133e-6" ixz="-0.00423315e-6" iyy="3.6947967e-6" iyz="0.00083028e-6" izz="3.8176336e-6"/>
      <origin rpy="0 0 0" xyz="22.41911e-3 -0.15798201e-3 -0.01319866e-3"/>
    </inertial>
    <visual name="ring_mesh_1_right">
      <material name="right_psyonic_black"/>
      <origin rpy="0 0 0.084474" xyz="38.472723e-3 3.257695e-3 0.000000"/>
      <geometry>
        <mesh filename="package://psyonic_hand_description/urdf/models/idx-F1.STL"/>
      </geometry>
    </visual>
  </link>
  <link name="ring_L2_right">
    <inertial>
      <mass value="0.00645"/>
      <inertia ixx="0.82671e-6" ixy="-1.08876e-6" ixz="-0.00037e-6" iyy="1.98028e-6" iyz="0.00081e-6" izz="2.64638e-6"/>
      <origin rpy="0 0 0" xyz="13.36818e-3 -8.75392e-3 -0.02886e-3"/>
    </inertial>
    <visual name="ring_mesh_2_right">
      <material name="right_psyonic_black"/>
      <origin rpy="0 0 0" xyz="9.1241e-3 0 0"/>
      <geometry>
        <mesh filename="package://psyonic_hand_description/urdf/models/idx-F2.STL"/>
      </geometry>
    </visual>
  </link>
  <joint name="ring_q1_right" type="revolute">
    <parent link="thumb_base_right"/>
    <child link="ring_L1_right"/>
    <origin rpy=" -1.424994653589793 1.321452 -1.4657306535897934 " xyz=" -29.95426e-3 -14.212492e-3 -67.286105e-3 "/>
    <limit effort="0.20" lower="0" upper="2.0943951" velocity="8.0677777442"/>
    <!-- angles in rad, efforts in N-m, velocity in rad/s -->
    <dynamics damping="0.001" friction="0.001"/>
    <!-- Friction coefficient is not from quantitative measurement -->
    <axis xyz="0 0 1"/>
  </joint>
  <joint name="ring_q2_right" type="revolute">
    <parent link="ring_L1_right"/>
    <child link="ring_L2_right"/>
    <origin rpy="0 0 0.084474" xyz="38.472723e-3 3.257695e-3 0.000000"/>
    <axis xyz="0 0 1"/>
    <limit effort="0.20" lower="0.0" upper="2.6586" velocity="8.0677777442"/>
    <!-- angles in rad, efforts in N-m, velocity in rad/s -->
    <dynamics damping="0.001" friction="0.001"/>
    <!-- Friction coefficient is not from quantitative measurement -->
    <mimic joint="ring_q1_right" multiplier="1.05851325" offset="0.72349796"/>
  </joint>
  <link name="ring_anchor_right"/>
  <joint name="rng_anchor_right" type="fixed">
    <parent link="ring_L2_right"/>
    <child link="ring_anchor_right"/>
    <origin rpy="0 0 0" xyz="31.5541e-3  -10.44e-3 0.14e-3"/>
  </joint>
  <link name="pinky_L1_right">
    <inertial>
      <mass value="0.00635888"/>
      <inertia ixx="0.29766e-6" ixy="-0.06447133e-6" ixz="-0.00423315e-6" iyy="3.6947967e-6" iyz="0.00083028e-6" izz="3.8176336e-6"/>
      <origin rpy="0 0 0" xyz="22.41911e-3 -0.15798201e-3 -0.01319866e-3"/>
    </inertial>
    <visual name="pinky_mesh_1_right">
      <material name="right_psyonic_black"/>
      <origin rpy="0 0 0.084474" xyz="38.472723e-3 3.257695e-3 0.000000"/>
      <geometry>
        <mesh filename="package://psyonic_hand_description/urdf/models/idx-F1.STL"/>
      </geometry>
    </visual>
  </link>
  <link name="pinky_L2_right">
    <inertial>
      <mass value="0.00645"/>
      <inertia ixx="0.82671e-6" ixy="-1.08876e-6" ixz="-0.00037e-6" iyy="1.98028e-6" iyz="0.00081e-6" izz="2.64638e-6"/>
      <origin rpy="0 0 0" xyz="13.36818e-3 -8.75392e-3 -0.02886e-3"/>
    </inertial>
    <visual name="pinky_mesh_2_right">
      <material name="right_psyonic_black"/>
      <origin rpy="0 0 0" xyz="9.1241e-3 0 0"/>
      <geometry>
        <mesh filename="package://psyonic_hand_description/urdf/models/idx-F2.STL"/>
      </geometry>
    </visual>
  </link>
  <joint name="pinky_q1_right" type="revolute">
    <parent link="thumb_base_right"/>
    <child link="pinky_L1_right"/>
    <origin rpy=" -1.3764826535897934 1.32222 -1.4832096535897932 " xyz=" -49.521293e-3 -11.004583e-3 -63.029065e-3 "/>
    <limit effort="0.20" lower="0" upper="2.0943951" velocity="8.0677777442"/>
    <!-- angles in rad, efforts in N-m, velocity in rad/s -->
    <dynamics damping="0.001" friction="0.001"/>
    <!-- Friction coefficient is not from quantitative measurement -->
    <axis xyz="0 0 1"/>
  </joint>
  <joint name="pinky_q2_right" type="revolute">
    <parent link="pinky_L1_right"/>
    <child link="pinky_L2_right"/>
    <origin rpy="0 0 0.084474" xyz="38.472723e-3 3.257695e-3 0.000000"/>
    <limit effort="0.20" lower="0.0" upper="2.6586" velocity="8.0677777442"/>
    <!-- angles in rad, efforts in N-m, velocity in rad/s -->
    <dynamics damping="0.001" friction="0.001"/>
    <!-- Friction coefficient is not from quantitative measurement -->
    <axis xyz="0 0 1"/>
    <mimic joint="pinky_q1_right" multiplier="1.05851325" offset="0.72349796"/>
  </joint>
  <link name="pinky_anchor_right"/>
  <joint name="pnky_anchor_right" type="fixed">
    <parent link="pinky_L2_right"/>
    <child link="pinky_anchor_right"/>
    <origin rpy="0 0 0" xyz="31.5541e-3  -10.44e-3 0.14e-3"/>
  </joint>
  <link name="thumb_L1_right">
    <inertial>
      <mass value="0.00268342"/>
      <inertia ixx="0.16931e-6" ixy="-0.076214e-6" ixz="-0.16959148e-6" iyy="0.77769934e-6" iyz="0.0156622e-6" izz="0.7249122e-6"/>
      <origin rpy="0 0 0" xyz="14.606e-3 -1.890854e-3 -3.1155356e-3"/>
    </inertial>
    <visual name="thumb_mesh_1_right">
      <material name="right_psyonic_black"/>
      <origin rpy=" 1.832595714594045 -0.0 5.366520605522463e-18 " xyz=" 27.8283501e-3 1.7436510745838653e-19 14.7507e-3 "/>
      <geometry>
        <mesh filename="package://psyonic_hand_description/urdf/models/thumb-F1-MIR.STL"/>
      </geometry>
    </visual>
  </link>
  <link name="thumb_L2_right">
    <inertial>
      <mass value="0.0055"/>
      <inertia ixx="4.4789082e-6" ixy="4.4789082e-6" ixz="-0.62144934e-6" iyy="15.600996e-6" iyz="-0.07466143e-6" izz="17.908554e-6"/>
      <origin rpy="0 0 0" xyz="30.020522e-3 5.59476e-3 -4.1504356e-3"/>
    </inertial>
    <visual name="thumb_mesh_2_right">
      <material name="right_psyonic_black"/>
      <origin rpy="-3.141592 0 0.343830" xyz="65.18669e-3 23.34021e-3 3.93483e-3"/>
      <geometry>
        <mesh filename="package://psyonic_hand_description/urdf/models/thumb-F2.STL"/>
      </geometry>
    </visual>
  </link>
  <joint name="thumb_q1_right" type="revolute">
    <parent link="thumb_base_right"/>
    <child link="thumb_L1_right"/>
    <origin rpy=" 3.141592653589793 -0.0 -0.18884434641020664 " xyz=" 0.0 0.0 0.0 "/>
    <axis xyz="0 0 1"/>
    <limit effort="0.20" lower="-2.0943951" upper="0" velocity="8.0677777442"/>
    <!-- angles in rad, efforts in N-m, velocity in rad/s -->
    <dynamics damping="0.001" friction="0.001"/>
    <!-- Friction coefficient is not from quantitative measurement -->
  </joint>
  <joint name="thumb_q2_right" type="revolute">
    <parent link="thumb_L1_right"/>
    <child link="thumb_L2_right"/>
    <origin rpy=" 1.832595714594045 -0.0 5.366520605522463e-18 " xyz=" 27.8283501e-3 1.7436510745838653e-19 14.7507e-3 "/>
    <axis xyz="0 0 1"/>
    <limit effort="0.20" lower="0" upper="2.0943951" velocity="8.0677777442"/>
    <!-- angles in rad, efforts in N-m, velocity in rad/s -->
    <dynamics damping="0.001" friction="0.001"/>
    <!-- Friction coefficient is not from quantitative measurement -->
  </joint>
  <link name="thumb_anchor_right"/>
  <joint name="thmb_anchor_right" type="fixed">
    <parent link="thumb_L2_right"/>
    <child link="thumb_anchor_right"/>
    <origin rpy="0 0 0" xyz="52.00122724e-3 28.00869333e-3 6.98483578e-3"/>
  </joint>
  <!-- if prefix == right -->
  <!-- if prefix == left -->
  <joint name="rightFixedPsyonic" type="fixed">
    <origin rpy="0.0 0.0 0.0" xyz="0.0 -0.05 0.0"/>
    <axis xyz="0 0 1"/>
    <parent link="rightWristPitchFrame"/>
    <child link="rightPsyonicAdapter"/>
  </joint>
  <gazebo reference="rightFixedPsyonic">
    <implicitSpringDamper>1</implicitSpringDamper>
  </gazebo>
  <!-- if psyonic gripper -->
  <link name="leftShoulderPitchLink">
    <inertial>
      <mass value="2.65"/>
      <origin rpy="0 0 0" xyz="-0.012 0.251 0.000000"/>
      <inertia ixx="0.013718167" ixy="0.0" ixz="0.0" iyy="0.010502833" iyz="0.0" izz="0.014806433"/>
    </inertial>
    <visual>
      <geometry>
        <mesh filename="package://val_description/model/meshes/arms/aj1_left.dae"/>
      </geometry>
      <origin rpy="0.0 0.0 0.0" xyz="0.0 0.0 0.0"/>
    </visual>
    <collision>
      <geometry>
        <mesh filename="package://val_description/model/meshes/arms/aj1_left.dae"/>
      </geometry>
      <origin rpy="0 0 0" xyz="0 0 0"/>
    </collision>
  </link>
  <link name="leftShoulderRollLink">
    <inertial>
      <mass value="3.97"/>
      <origin rpy="0 0 0" xyz="-0.008513 0.02068 -0.001088"/>
      <inertia ixx="0.014598842" ixy="-0.00066764" ixz="-3.629e-05" iyy="0.006452136" iyz="-8.283e-05" izz="0.016848319"/>
    </inertial>
    <visual>
      <geometry>
        <mesh filename="package://val_description/model/meshes/arms/aj2_left.dae"/>
      </geometry>
      <origin rpy="0.0 0.0 0.0" xyz="0.0 0.0 0.0"/>
    </visual>
    <collision>
      <geometry>
        <mesh filename="package://val_description/model/meshes/arms/aj2_left.dae"/>
      </geometry>
      <origin rpy="0 0 0" xyz="0 0 0"/>
    </collision>
  </link>
  <link name="leftShoulderYawLink">
    <inertial>
      <mass value="3.085"/>
      <origin rpy="0 0 0" xyz="-0.004304 0.209832 0.007295"/>
      <inertia ixx="0.039355177" ixy="-0.007827077" ixz="-0.000753947" iyy="0.004905765" iyz="0.002723873" izz="0.041879481"/>
    </inertial>
    <visual>
      <geometry>
        <mesh filename="package://val_description/model/meshes/arms/aj3_left.dae"/>
      </geometry>
      <origin rpy="0.0 0.0 0.0" xyz="0.0 0.0 0.0"/>
    </visual>
    <collision>
      <geometry>
        <mesh filename="package://val_description/model/meshes/arms/aj3_left.dae"/>
      </geometry>
      <origin rpy="0 0 0" xyz="0 0 0"/>
    </collision>
  </link>
  <link name="leftElbowPitchLink">
    <inertial>
      <mass value="1.83"/>
      <origin rpy="0 0 0" xyz="-0.020344 0.014722 0.0223"/>
      <inertia ixx="0.003314516" ixy="0.000535099" ixz="0.000728077" iyy="0.003505669" iyz="-0.000423865" izz="0.003011283"/>
    </inertial>
    <visual>
      <geometry>
        <mesh filename="package://val_description/model/meshes/arms/aj4_left.dae"/>
      </geometry>
      <origin rpy="0.0 0.0 0.0" xyz="0.0 0.0 0.0"/>
    </visual>
    <collision>
      <geometry>
        <mesh filename="package://val_description/model/meshes/arms/aj4_left.dae"/>
      </geometry>
      <origin rpy="0 0 0" xyz="0 0 0"/>
    </collision>
  </link>
  <joint name="leftShoulderPitch" type="revolute">
    <origin rpy="0.0 0.0 0.0" xyz="-0.0316 0.0 0.2984"/>
    <axis xyz="0 1 0"/>
    <parent link="torso"/>
    <child link="leftShoulderPitchLink"/>
    <limit effort="190" lower="-2.78" upper="1.93" velocity="5.89"/>
    <controller_gains Kd="0.0" Ki="0.0" Kp="0.0"/>
    <dynamics damping="0.1" friction="0.0"/>
  </joint>
  <gazebo reference="leftShoulderPitch">
    <provideFeedback>1</provideFeedback>
    <implicitSpringDamper>1</implicitSpringDamper>
  </gazebo>
  <joint name="leftShoulderRoll" type="revolute">
    <origin rpy="0.0 0.0 0.0" xyz="0.0 0.2499 0.0"/>
    <axis xyz="1 0 0"/>
    <parent link="leftShoulderPitchLink"/>
    <child link="leftShoulderRollLink"/>
    <limit effort="190" lower="-1.449" upper="1.196" velocity="5.89"/>
    <controller_gains Kd="0.0" Ki="0.0" Kp="0.0"/>
    <dynamics damping="0.1" friction="0.0"/>
  </joint>
  <gazebo reference="leftShoulderRoll">
    <provideFeedback>1</provideFeedback>
    <implicitSpringDamper>1</implicitSpringDamper>
  </gazebo>
  <joint name="leftShoulderYaw" type="revolute">
    <origin rpy="0.0 0.0 0.0" xyz="0.0 0.0 0.0"/>
    <axis xyz="0 1 0"/>
    <parent link="leftShoulderRollLink"/>
    <child link="leftShoulderYawLink"/>
    <limit effort="65" lower="-3.03" upper="3.03" velocity="11.5"/>
    <controller_gains Kd="0.0" Ki="0.0" Kp="0.0"/>
    <dynamics damping="0.1" friction="0.0"/>
  </joint>
  <gazebo reference="leftShoulderYaw">
    <provideFeedback>1</provideFeedback>
    <implicitSpringDamper>1</implicitSpringDamper>
  </gazebo>
  <joint name="leftElbowPitch" type="revolute">
    <origin rpy="0.0 0.0 0.0" xyz="0.0254 0.33 0.0"/>
    <axis xyz="0 0 1"/>
    <parent link="leftShoulderYawLink"/>
    <child link="leftElbowPitchLink"/>
    <limit effort="65" lower="-2.13" upper="0.04" velocity="11.5"/>
    <controller_gains Kd="0.0" Ki="0.0" Kp="0.0"/>
    <dynamics damping="0.1" friction="0.0"/>
  </joint>
  <gazebo reference="leftElbowPitch">
    <provideFeedback>1</provideFeedback>
    <implicitSpringDamper>1</implicitSpringDamper>
  </gazebo>
  <!--                 LINK DEFINITIONS                 -->
  <link name="leftForearmLink">
    <inertial>
      <mass value="2.476"/>
      <origin rpy="0 0 0" xyz="0.015000 0.13 0.019564"/>
      <inertia ixx="0.01175543" ixy="0.001300853" ixz="-0.000727141" iyy="0.005071567" iyz="0.001695416" izz="0.011365657"/>
    </inertial>
    <visual>
      <geometry>
        <mesh filename="package://val_description/model/meshes/arms/aj5_left.dae"/>
      </geometry>
      <origin rpy="0.0 0.0 0.0" xyz="0.0 0.0 0.0"/>
    </visual>
    <collision>
      <geometry>
        <mesh filename="package://val_description/model/meshes/arms/aj5_left.dae"/>
      </geometry>
      <origin rpy="0 0 0" xyz="0 0 0"/>
    </collision>
  </link>
  <link name="leftWristRollLink">
    <inertial>
      <mass value="0.14"/>
      <origin rpy="0 0 0" xyz="0 0 0"/>
      <inertia ixx="3.0251e-05" ixy="1.25e-07" ixz="3.6e-08" iyy="3.772e-05" iyz="0.0" izz="9.395e-06"/>
    </inertial>
    <visual>
      <geometry>
        <mesh filename="package://val_description/model/meshes/arms/aj6_left.dae"/>
      </geometry>
      <origin rpy="0.0 0.0 0.0" xyz="0.0 0.0 0.0"/>
    </visual>
    <collision>
      <geometry>
        <mesh filename="package://val_description/model/meshes/arms/aj6_left.dae"/>
      </geometry>
      <origin rpy="0 0 0" xyz="0 0 0"/>
    </collision>
  </link>
  <link name="leftWristPitchFrame">
    <!-- Virtual Link -->
    <inertial>
      <mass value="1e-07"/>
      <origin rpy="0 0 0" xyz="0 0 0"/>
      <inertia ixx="3.3333333333333322e-22" ixy="0.0" ixz="0.0" iyy="3.3333333333333322e-22" iyz="0.0" izz="4.999999999999999e-22"/>
    </inertial>
  </link>
  <!--                 JOINT DEFINITIONS                 -->
  <joint name="leftForearmYaw" type="revolute">
    <origin rpy="0.0 0.0 0.0" xyz="-0.0254 0 0"/>
    <axis xyz="0 1 0"/>
    <parent link="leftElbowPitchLink"/>
    <child link="leftForearmLink"/>
    <limit effort="26" lower="-2.019" upper="3.14" velocity="5"/>
    <controller_gains Kd="0.0" Ki="0.0" Kp="1000"/>
    <dynamics damping="0.1" friction="0.0"/>
  </joint>
  <gazebo reference="leftForearmYaw">
    <provideFeedback>1</provideFeedback>
    <implicitSpringDamper>1</implicitSpringDamper>
  </gazebo>
  <joint name="leftWristRoll" type="revolute">
    <origin rpy="0.0 0.0 0.0" xyz="0.0 0.2871 0.0"/>
    <axis xyz="1 0 0"/>
    <parent link="leftForearmLink"/>
    <child link="leftWristRollLink"/>
    <limit effort="14" lower="-0.35" upper="0.35" velocity="1"/>
    <controller_gains Kd="0" Ki="0.0" Kp="500"/>
    <dynamics damping="0.1" friction="0.0"/>
  </joint>
  <gazebo reference="leftWristRoll">
    <provideFeedback>1</provideFeedback>
    <implicitSpringDamper>1</implicitSpringDamper>
  </gazebo>
  <joint name="leftWristPitch" type="revolute">
    <origin rpy="0.0 0.0 0.0" xyz="0.0 0.0 0.0"/>
    <axis xyz="0 0 1"/>
    <parent link="leftWristRollLink"/>
    <child link="leftWristPitchFrame"/>
    <limit effort="14" lower="-0.6" upper="0.6" velocity="1"/>
    <controller_gains Kd="0" Ki="0.0" Kp="500"/>
    <dynamics damping="0.1" friction="0.0"/>
  </joint>
  <gazebo reference="leftWristPitch">
    <provideFeedback>1</provideFeedback>
    <implicitSpringDamper>1</implicitSpringDamper>
  </gazebo>
  <transmission name="leftShoulderPitchTransmission">
    <type>transmission_interface/SimpleTransmission</type>
    <joint name="leftShoulderPitch">
      <hardwareInterface>EffortJointInterface</hardwareInterface>
    </joint>
    <actuator name="leftShoulderPitch">
      <node name="/trunk/left_arm_j1"/>
      <mechanicalReduction>1</mechanicalReduction>
      <api name="robot_hardware_interface/TurbodriverAPI"/>
    </actuator>
  </transmission>
  <transmission name="leftShoulderRollTransmission">
    <type>transmission_interface/SimpleTransmission</type>
    <joint name="leftShoulderRoll">
      <hardwareInterface>EffortJointInterface</hardwareInterface>
    </joint>
    <actuator name="leftShoulderRoll">
      <node name="/left_arm/j2"/>
      <mechanicalReduction>1</mechanicalReduction>
      <api name="robot_hardware_interface/TurbodriverAPI"/>
    </actuator>
  </transmission>
  <transmission name="leftShoulderYawTransmission">
    <type>transmission_interface/SimpleTransmission</type>
    <joint name="leftShoulderYaw">
      <hardwareInterface>EffortJointInterface</hardwareInterface>
    </joint>
    <actuator name="leftShoulderYaw">
      <node name="/left_arm/j3"/>
      <mechanicalReduction>1</mechanicalReduction>
      <api name="robot_hardware_interface/TurbodriverAPI"/>
    </actuator>
  </transmission>
  <transmission name="leftElbowPitchTransmission">
    <type>transmission_interface/SimpleTransmission</type>
    <joint name="leftElbowPitch">
      <hardwareInterface>EffortJointInterface</hardwareInterface>
    </joint>
    <actuator name="leftElbowPitch">
      <node name="/left_arm/j4"/>
      <mechanicalReduction>1</mechanicalReduction>
      <api name="robot_hardware_interface/TurbodriverAPI"/>
    </actuator>
  </transmission>
  <transmission name="leftForearmYawTransmission">
    <type>transmission_interface/SimpleTransmission</type>
    <joint name="leftForearmYaw">
      <hardwareInterface>EffortJointInterface</hardwareInterface>
    </joint>
    <actuator name="leftForearmYaw">
      <node name="/left_arm/j5"/>
      <mechanicalReduction>1</mechanicalReduction>
      <api name="robot_hardware_interface/TurbodriverAPI"/>
    </actuator>
  </transmission>
  <transmission name="leftWristTransmission">
    <type>robot_transmission_interface/WristPushrodTransmission</type>
    <joint name="leftWristPitch">
      <role>pitch</role>
      <hardwareInterface>EffortJointInterface</hardwareInterface>
    </joint>
    <joint name="leftWristRoll">
      <role>roll</role>
      <hardwareInterface>EffortJointInterface</hardwareInterface>
    </joint>
    <actuator name="leftWristRightActuator">
      <node name="/left_arm/wrist/right_actuator"/>
      <role>bottom</role>
      <mechanicalReduction>1</mechanicalReduction>
      <api name="robot_hardware_interface/TurbodriverAPI_linear_futek"/>
    </actuator>
    <actuator name="leftWristLeftActuator">
      <node name="/left_arm/wrist/left_actuator"/>
      <role>top</role>
      <mechanicalReduction>1</mechanicalReduction>
      <api name="robot_hardware_interface/TurbodriverAPI_linear_futek"/>
    </actuator>
  </transmission>
  <transmission name="leftIndexFingerMotorPitch1Transmission">
    <type>transmission_interface/SimpleTransmission</type>
    <joint name="leftIndexFingerMotorPitch1">
      <hardwareInterface>EffortJointInterface</hardwareInterface>
    </joint>
    <actuator name="leftIndexFingerMotorPitch1">
      <node name="/left_arm/hand/index"/>
      <mechanicalReduction>1</mechanicalReduction>
      <api name="robot_hardware_interface/TurbodriverAPI"/>
    </actuator>
  </transmission>
  <transmission name="leftMiddleFingerMotorPitch1Transmission">
    <type>transmission_interface/SimpleTransmission</type>
    <joint name="leftMiddleFingerMotorPitch1">
      <hardwareInterface>EffortJointInterface</hardwareInterface>
    </joint>
    <actuator name="leftMiddleFingerMotorPitch1">
      <node name="/left_arm/hand/middle"/>
      <mechanicalReduction>1</mechanicalReduction>
      <api name="robot_hardware_interface/TurbodriverAPI"/>
    </actuator>
  </transmission>
  <transmission name="leftPinkyMotorPitch1Transmission">
    <type>transmission_interface/SimpleTransmission</type>
    <joint name="leftPinkyMotorPitch1">
      <hardwareInterface>EffortJointInterface</hardwareInterface>
    </joint>
    <actuator name="leftPinkyMotorPitch1">
      <node name="/left_arm/hand/pinky"/>
      <mechanicalReduction>1</mechanicalReduction>
      <api name="robot_hardware_interface/TurbodriverAPI"/>
    </actuator>
  </transmission>
  <transmission name="leftThumbMotorRollTransmission">
    <type>transmission_interface/SimpleTransmission</type>
    <joint name="leftThumbMotorRoll">
      <hardwareInterface>EffortJointInterface</hardwareInterface>
    </joint>
    <actuator name="leftThumbMotorRoll">
      <node name="/left_arm/hand/thumb_roll"/>
      <mechanicalReduction>1</mechanicalReduction>
      <api name="robot_hardware_interface/TurbodriverAPI"/>
    </actuator>
  </transmission>
  <transmission name="leftThumbMotorPitch1Transmission">
    <type>transmission_interface/SimpleTransmission</type>
    <joint name="leftThumbMotorPitch1">
      <hardwareInterface>EffortJointInterface</hardwareInterface>
    </joint>
    <actuator name="leftThumbMotorPitch1">
      <node name="/left_arm/hand/thumb_proximal"/>
      <mechanicalReduction>1</mechanicalReduction>
      <api name="robot_hardware_interface/TurbodriverAPI"/>
    </actuator>
  </transmission>
  <transmission name="leftThumbMotorPitch2Transmission">
    <type>transmission_interface/SimpleTransmission</type>
    <joint name="leftThumbMotorPitch2">
      <hardwareInterface>EffortJointInterface</hardwareInterface>
    </joint>
    <actuator name="leftThumbMotorPitch2">
      <node name="/left_arm/hand/thumb_distal"/>
      <mechanicalReduction>1</mechanicalReduction>
      <api name="robot_hardware_interface/TurbodriverAPI"/>
    </actuator>
  </transmission>
  <!-- if val hand -->
  <!-- if zimmer gripper -->
  <link name="leftPsyonicAdapter">
    <inertial>
      <mass value="0.1"/>
      <origin rpy="0 0 0" xyz="0 0 0"/>
      <inertia ixx="1e-06" ixy="1e-06" ixz="1e-06" iyy="1e-06" iyz="1e-06" izz="1e-06"/>
    </inertial>
    <visual>
      <geometry>
        <mesh filename="package://val_description/model/meshes/psyonic/psyonic_adapter_left.dae"/>
      </geometry>
      <origin rpy="0.0 0.0 0.0" xyz="0.0 0.0 0.0"/>
    </visual>
    <collision>
      <geometry>
        <mesh filename="package://val_description/model/meshes/psyonic/psyonic_adapter_left.dae"/>
      </geometry>
      <origin rpy="0 0 0" xyz="0 0 0"/>
    </collision>
  </link>
  <!-- if prefix == right -->
  <material name="left_psyonic_black">
    <color rgba="0.2 0.2 0.2 1"/>
  </material>
  <joint name="psyonic_base_joint_left" type="fixed">
    <parent link="leftPsyonicAdapter"/>
    <child link="base_left"/>
    <origin rpy="-1.57079632679 -1.57079632679 0.0" xyz="0.0 0.01 0.0"/>
  </joint>
  <link name="base_left">
    <visual name="wrist_mesh_left">
      <material name="left_psyonic_black"/>
      <origin rpy="0 0 0" xyz="0 0 0"/>
      <geometry>
        <mesh filename="package://psyonic_hand_description/urdf/models/wristmesh.STL"/>
      </geometry>
    </visual>
    <inertial>
      <!-- the mass and inertia here are NOT correct -->
      <mass value="0.200"/>
      <inertia ixx="978.26e-6" ixy="87.34e-6" ixz="322.99e-6" iyy="1244.78e-6" iyz="244.74e-6" izz="456.22e-6"/>
      <origin rpy="0 0 0" xyz="22.41911e-3 -0.15798201e-3 -0.01319866e-3"/>
    </inertial>
  </link>
  <joint name="wrist2thumb_left" type="fixed">
    <parent link="base_left"/>
    <child link="thumb_base_left"/>
    <origin rpy="3.14148426 0.08848813 3.14036612" xyz="24.0476665e-3 3.78124745e-3 32.32964923e-3"/>
  </joint>
  <link name="thumb_base_left">
    <inertial>
      <mass value="0.400"/>
      <inertia ixx="978.26e-6" ixy="87.34e-6" ixz="322.99e-6" iyy="1244.78e-6" iyz="244.74e-6" izz="456.22e-6"/>
      <origin rpy="0 0 0" xyz="22.41911e-3 -0.15798201e-3 -0.01319866e-3"/>
    </inertial>
    <visual name="palm_mesh_left">
      <material name="left_psyonic_black"/>
      <origin rpy="0 0 0" xyz="0 0 0"/>
      <geometry>
        <mesh filename="package://psyonic_hand_description/urdf/models/FB_palm_ref.STL"/>
      </geometry>
    </visual>
  </link>
  <link name="index_L1_left">
    <inertial>
      <mass value="0.00635888"/>
      <inertia ixx="0.29766e-6" ixy="-0.06447133e-6" ixz="-0.00423315e-6" iyy="3.6947967e-6" iyz="0.00083028e-6" izz="3.8176336e-6"/>
      <origin rpy="0 0 0" xyz="22.41911e-3 -0.15798201e-3 -0.01319866e-3"/>
    </inertial>
    <visual name="index_mesh_1_left">
      <material name="left_psyonic_black"/>
      <origin rpy="0 0 0.084474" xyz="38.472723e-3 3.257695e-3 0.000000"/>
      <geometry>
        <mesh filename="package://psyonic_hand_description/urdf/models/idx-F1.STL"/>
      </geometry>
    </visual>
  </link>
  <link name="index_L2_left">
    <inertial>
      <mass value="0.00645"/>
      <inertia ixx="0.82671e-6" ixy="-1.08876e-6" ixz="-0.00037e-6" iyy="1.98028e-6" iyz="0.00081e-6" izz="2.64638e-6"/>
      <origin rpy="0 0 0" xyz="13.36818e-3 -8.75392e-3 -0.02886e-3"/>
    </inertial>
    <visual name="index_mesh_2_left">
      <material name="left_psyonic_black"/>
      <origin rpy="0 0 0" xyz="9.1241e-3 0 0"/>
      <geometry>
        <mesh filename="package://psyonic_hand_description/urdf/models/idx-F2.STL"/>
      </geometry>
    </visual>
  </link>
  <joint name="index_q1_left" type="revolute">
    <parent link="thumb_base_left"/>
    <child link="index_L1_left"/>
    <origin rpy="-1.982050 1.284473 -2.090591" xyz="-9.49e-3 -13.04e-3 -62.95e-3"/>
    <axis xyz="0 0 1"/>
    <limit effort="0.20" lower="0" upper="2.0943951" velocity="8.0677777442"/>
    <!-- angles in rad, efforts in N-m, velocity in rad/s -->
    <dynamics damping="0.001" friction="0.001"/>
    <!-- Friction coefficient is not from quantitative measurement -->
  </joint>
  <joint name="index_q2_left" type="revolute">
    <parent link="index_L1_left"/>
    <child link="index_L2_left"/>
    <origin rpy="0 0 0.084474" xyz="38.472723e-3 3.257695e-3 0.000000e-3"/>
    <axis xyz="0 0 1"/>
    <limit effort="0.20" lower="0.0" upper="2.6586" velocity="8.0677777442"/>
    <!-- angles in rad, efforts in N-m, velocity in rad/s -->
    <dynamics damping="0.001" friction="0.001"/>
    <!-- Friction coefficient is not from quantitative measurement -->
    <mimic joint="index_q1_left" multiplier="1.05851325" offset="0.72349796"/>
  </joint>
  <link name="index_anchor_left"/>
  <joint name="idx_anchor_left" type="fixed">
    <parent link="index_L2_left"/>
    <child link="index_anchor_left"/>
    <origin rpy="0 0 0" xyz="31.5541e-3  -10.44e-3 0.14e-3"/>
  </joint>
  <link name="middle_L1_left">
    <inertial>
      <mass value="0.00635888"/>
      <inertia ixx="0.29766e-6" ixy="-0.06447133e-6" ixz="-0.00423315e-6" iyy="3.6947967e-6" iyz="0.00083028e-6" izz="3.8176336e-6"/>
      <origin rpy="0 0 0" xyz="22.41911e-3 -0.15798201e-3 -0.01319866e-3"/>
    </inertial>
    <visual name="middle_mesh_1_left">
      <material name="left_psyonic_black"/>
      <origin rpy="0 0 0.084474" xyz="38.472723e-3 3.257695e-3 0.000000"/>
      <geometry>
        <mesh filename="package://psyonic_hand_description/urdf/models/idx-F1.STL"/>
      </geometry>
    </visual>
  </link>
  <link name="middle_L2_left">
    <inertial>
      <mass value="0.00645"/>
      <inertia ixx="0.82671e-6" ixy="-1.08876e-6" ixz="-0.00037e-6" iyy="1.98028e-6" iyz="0.00081e-6" izz="2.64638e-6"/>
      <origin rpy="0 0 0" xyz="13.36818e-3 -8.75392e-3 -0.02886e-3"/>
    </inertial>
    <visual name="middle_mesh_2_left">
      <material name="left_psyonic_black"/>
      <origin rpy="0 0 0" xyz="9.1241e-3 0 0"/>
      <geometry>
        <mesh filename="package://psyonic_hand_description/urdf/models/idx-F2.STL"/>
      </geometry>
    </visual>
  </link>
  <joint name="middle_q1_left" type="revolute">
    <parent link="thumb_base_left"/>
    <child link="middle_L1_left"/>
    <origin rpy="-1.860531 1.308458 -1.896217" xyz="9.653191e-3 -15.310271e-3 -67.853949e-3"/>
    <limit effort="0.20" lower="0" upper="2.0943951" velocity="8.0677777442"/>
    <!-- angles in rad, efforts in N-m, velocity in rad/s -->
    <dynamics damping="0.001" friction="0.001"/>
    <!-- Friction coefficient is not from quantitative measurement -->
    <axis xyz="0 0 1"/>
  </joint>
  <joint name="middle_q2_left" type="revolute">
    <parent link="middle_L1_left"/>
    <child link="middle_L2_left"/>
    <origin rpy="0 0 0.084474" xyz="38.472723e-3 3.257695e-3 0.000000"/>
    <axis xyz="0 0 1"/>
    <limit effort="0.20" lower="0.0" upper="2.6586" velocity="8.0677777442"/>
    <!-- angles in rad, efforts in N-m, velocity in rad/s -->
    <dynamics damping="0.001" friction="0.001"/>
    <!-- Friction coefficient is not from quantitative measurement -->
    <mimic joint="middle_q1_left" multiplier="1.05851325" offset="0.72349796"/>
  </joint>
  <link name="middle_anchor_left"/>
  <joint name="mid_anchor_left" type="fixed">
    <parent link="middle_L2_left"/>
    <child link="middle_anchor_left"/>
    <origin rpy="0 0 0" xyz="31.5541e-3  -10.44e-3 0.14e-3"/>
  </joint>
  <link name="ring_L1_left">
    <inertial>
      <mass value="0.00635888"/>
      <inertia ixx="0.29766e-6" ixy="-0.06447133e-6" ixz="-0.00423315e-6" iyy="3.6947967e-6" iyz="0.00083028e-6" izz="3.8176336e-6"/>
      <origin rpy="0 0 0" xyz="22.41911e-3 -0.15798201e-3 -0.01319866e-3"/>
    </inertial>
    <visual name="ring_mesh_1_left">
      <material name="left_psyonic_black"/>
      <origin rpy="0 0 0.084474" xyz="38.472723e-3 3.257695e-3 0.000000"/>
      <geometry>
        <mesh filename="package://psyonic_hand_description/urdf/models/idx-F1.STL"/>
      </geometry>
    </visual>
  </link>
  <link name="ring_L2_left">
    <inertial>
      <mass value="0.00645"/>
      <inertia ixx="0.82671e-6" ixy="-1.08876e-6" ixz="-0.00037e-6" iyy="1.98028e-6" iyz="0.00081e-6" izz="2.64638e-6"/>
      <origin rpy="0 0 0" xyz="13.36818e-3 -8.75392e-3 -0.02886e-3"/>
    </inertial>
    <visual name="ring_mesh_2_left">
      <material name="left_psyonic_black"/>
      <origin rpy="0 0 0" xyz="9.1241e-3 0 0"/>
      <geometry>
        <mesh filename="package://psyonic_hand_description/urdf/models/idx-F2.STL"/>
      </geometry>
    </visual>
  </link>
  <joint name="ring_q1_left" type="revolute">
    <parent link="thumb_base_left"/>
    <child link="ring_L1_left"/>
    <origin rpy="-1.716598 1.321452 -1.675862" xyz="29.954260e-3 -14.212492e-3 -67.286105e-3"/>
    <limit effort="0.20" lower="0" upper="2.0943951" velocity="8.0677777442"/>
    <!-- angles in rad, efforts in N-m, velocity in rad/s -->
    <dynamics damping="0.001" friction="0.001"/>
    <!-- Friction coefficient is not from quantitative measurement -->
    <axis xyz="0 0 1"/>
  </joint>
  <joint name="ring_q2_left" type="revolute">
    <parent link="ring_L1_left"/>
    <child link="ring_L2_left"/>
    <origin rpy="0 0 0.084474" xyz="38.472723e-3 3.257695e-3 0.000000"/>
    <axis xyz="0 0 1"/>
    <limit effort="0.20" lower="0.0" upper="2.6586" velocity="8.0677777442"/>
    <!-- angles in rad, efforts in N-m, velocity in rad/s -->
    <dynamics damping="0.001" friction="0.001"/>
    <!-- Friction coefficient is not from quantitative measurement -->
    <mimic joint="ring_q1_left" multiplier="1.05851325" offset="0.72349796"/>
  </joint>
  <link name="ring_anchor_left"/>
  <joint name="rng_anchor_left" type="fixed">
    <parent link="ring_L2_left"/>
    <child link="ring_anchor_left"/>
    <origin rpy="0 0 0" xyz="31.5541e-3  -10.44e-3 0.14e-3"/>
  </joint>
  <link name="pinky_L1_left">
    <inertial>
      <mass value="0.00635888"/>
      <inertia ixx="0.29766e-6" ixy="-0.06447133e-6" ixz="-0.00423315e-6" iyy="3.6947967e-6" iyz="0.00083028e-6" izz="3.8176336e-6"/>
      <origin rpy="0 0 0" xyz="22.41911e-3 -0.15798201e-3 -0.01319866e-3"/>
    </inertial>
    <visual name="pinky_mesh_1_left">
      <material name="left_psyonic_black"/>
      <origin rpy="0 0 0.084474" xyz="38.472723e-3 3.257695e-3 0.000000"/>
      <geometry>
        <mesh filename="package://psyonic_hand_description/urdf/models/idx-F1.STL"/>
      </geometry>
    </visual>
  </link>
  <link name="pinky_L2_left">
    <inertial>
      <mass value="0.00645"/>
      <inertia ixx="0.82671e-6" ixy="-1.08876e-6" ixz="-0.00037e-6" iyy="1.98028e-6" iyz="0.00081e-6" izz="2.64638e-6"/>
      <origin rpy="0 0 0" xyz="13.36818e-3 -8.75392e-3 -0.02886e-3"/>
    </inertial>
    <visual name="pinky_mesh_2_left">
      <material name="left_psyonic_black"/>
      <origin rpy="0 0 0" xyz="9.1241e-3 0 0"/>
      <geometry>
        <mesh filename="package://psyonic_hand_description/urdf/models/idx-F2.STL"/>
      </geometry>
    </visual>
  </link>
  <joint name="pinky_q1_left" type="revolute">
    <parent link="thumb_base_left"/>
    <child link="pinky_L1_left"/>
    <origin rpy="-1.765110 1.322220 -1.658383" xyz="49.521293e-3 -11.004583e-3 -63.029065e-3"/>
    <limit effort="0.20" lower="0" upper="2.0943951" velocity="8.0677777442"/>
    <!-- angles in rad, efforts in N-m, velocity in rad/s -->
    <dynamics damping="0.001" friction="0.001"/>
    <!-- Friction coefficient is not from quantitative measurement -->
    <axis xyz="0 0 1"/>
  </joint>
  <joint name="pinky_q2_left" type="revolute">
    <parent link="pinky_L1_left"/>
    <child link="pinky_L2_left"/>
    <origin rpy="0 0 0.084474" xyz="38.472723e-3 3.257695e-3 0.000000"/>
    <limit effort="0.20" lower="0.0" upper="2.6586" velocity="8.0677777442"/>
    <!-- angles in rad, efforts in N-m, velocity in rad/s -->
    <dynamics damping="0.001" friction="0.001"/>
    <!-- Friction coefficient is not from quantitative measurement -->
    <axis xyz="0 0 1"/>
    <mimic joint="pinky_q1_left" multiplier="1.05851325" offset="0.72349796"/>
  </joint>
  <link name="pinky_anchor_left"/>
  <joint name="pnky_anchor_left" type="fixed">
    <parent link="pinky_L2_left"/>
    <child link="pinky_anchor_left"/>
    <origin rpy="0 0 0" xyz="31.5541e-3  -10.44e-3 0.14e-3"/>
  </joint>
  <link name="thumb_L1_left">
    <inertial>
      <mass value="0.00268342"/>
      <inertia ixx="0.16931e-6" ixy="-0.076214e-6" ixz="-0.16959148e-6" iyy="0.77769934e-6" iyz="0.0156622e-6" izz="0.7249122e-6"/>
      <origin rpy="0 0 0" xyz="14.606e-3 -1.890854e-3 -3.1155356e-3"/>
    </inertial>
    <visual name="thumb_mesh_1_left">
      <material name="left_psyonic_black"/>
      <origin rpy="4.450589592585541 0 0" xyz="27.8283501e-3 0 -14.7507000e-3"/>
      <geometry>
        <mesh filename="package://psyonic_hand_description/urdf/models/thumb-F1.STL"/>
      </geometry>
    </visual>
  </link>
  <link name="thumb_L2_left">
    <inertial>
      <mass value="0.0055"/>
      <inertia ixx="4.4789082e-6" ixy="4.4789082e-6" ixz="-0.62144934e-6" iyy="15.600996e-6" iyz="-0.07466143e-6" izz="17.908554e-6"/>
      <origin rpy="0 0 0" xyz="30.020522e-3 5.59476e-3 -4.1504356e-3"/>
    </inertial>
    <visual name="thumb_mesh_2_left">
      <material name="left_psyonic_black"/>
      <origin rpy="3.141592 0 0.343830" xyz="65.18669e-3 23.34021e-3 -3.93483e-3"/>
      <geometry>
        <mesh filename="package://psyonic_hand_description/urdf/models/thumb-F2.STL"/>
      </geometry>
    </visual>
  </link>
  <joint name="thumb_q1_left" type="revolute">
    <parent link="thumb_base_left"/>
    <child link="thumb_L1_left"/>
    <origin rpy="0 0 3.330437" xyz="0 0 0"/>
    <axis xyz="0 0 1"/>
    <limit effort="0.20" lower="-2.0943951" upper="0" velocity="8.0677777442"/>
    <!-- angles in rad, efforts in N-m, velocity in rad/s -->
    <dynamics damping="0.001" friction="0.001"/>
    <!-- Friction coefficient is not from quantitative measurement -->
  </joint>
  <joint name="thumb_q2_left" type="revolute">
    <parent link="thumb_L1_left"/>
    <child link="thumb_L2_left"/>
    <origin rpy="4.450589592585541 0 0" xyz="27.8283501e-3 0 -14.7507000e-3"/>
    <axis xyz="0 0 1"/>
    <limit effort="0.20" lower="0" upper="2.0943951" velocity="8.0677777442"/>
    <!-- angles in rad, efforts in N-m, velocity in rad/s -->
    <dynamics damping="0.001" friction="0.001"/>
    <!-- Friction coefficient is not from quantitative measurement -->
  </joint>
  <link name="thumb_anchor_left"/>
  <joint name="thmb_anchor_left" type="fixed">
    <parent link="thumb_L2_left"/>
    <child link="thumb_anchor_left"/>
    <origin rpy="0 0 0" xyz="52.0012259e-3  28.0086971e-3 -.884835778e-3"/>
  </joint>
  <!-- if prefix == left -->
  <joint name="leftFixedPsyonic" type="fixed">
    <origin rpy="0.0 0.0 0.0" xyz="0.0 0.05 0.0"/>
    <axis xyz="0 0 1"/>
    <parent link="leftWristPitchFrame"/>
    <child link="leftPsyonicAdapter"/>
  </joint>
  <gazebo reference="leftFixedPsyonic">
    <implicitSpringDamper>1</implicitSpringDamper>
  </gazebo>
  <!-- if psyonic gripper -->
</robot>


