<?xml version="1.0" ?>
<!-- =================================================================================== -->
<!-- |    This document was autogenerated by xacro from llaQuadruped.xacro             | -->
<!-- |    EDITING THIS FILE BY HAND IS NOT RECOMMENDED                                 | -->
<!-- =================================================================================== -->
<robot name="llaQuadruped" xmlns:xacro="http://ros.org/wiki/xacro">
  <!-- if you edit the mass or dimensions please recompute the ineria! -->
  <!-- if you edit the mass or dimensions please recompute the ineria! -->
  <!-- if you edit the mass or dimensions please recompute the ineria! -->
  <link name="body">
    <visual>
      <origin xyz="0 0 0"/>
      <geometry>
        <box size="0.6 0.2 0.01"/>
      </geometry>
    </visual>
    <inertial>
      <origin rpy="0 0 0" xyz="0.3 0.1 0.1"/>
      <mass value="20.0"/>
      <inertia ixx="1.0" ixy="0.006" ixz="0.003" iyy="2.0" iyz="-0.0006" izz="2.0"/>
    </inertial>
  </link>
  <!-- Front Left Leg -->
  <joint name="front_left_hip_roll" type="revolute">
    <axis xyz="1 0 0"/>
    <parent link="body"/>
    <child link="front_left_hip"/>
    <origin xyz="-0.04 0.206 0.0"/>
    <limit effort="1000" lower="-3.141592" upper="3.141592" velocity="100.0"/>
  </joint>
  <link name="front_left_hip">
    <visual>
      <origin rpy="0 1.57075 0" xyz="0 0 0.04"/>
      <geometry>
        <mesh filename="package://lla_quadruped_description/model/meshes/lla_5A0-binary.stl"/>
        <!--box size="0.196 0.1 0.1"/-->
      </geometry>
      <material name="blue">
        <color rgba="0 0 .8 1"/>
      </material>
    </visual>
    <inertial>
      <origin xyz="-0.098 0.0 0.0"/>
      <mass value="2.0"/>
      <inertia ixx="0.006" ixy="-0.00004" ixz="0.004" iyy="0.025" iyz="-0.000004" izz="0.02"/>
    </inertial>
  </link>
  <joint name="front_left_hip_pitch" type="revolute">
    <axis xyz="0 1 0"/>
    <parent link="front_left_hip"/>
    <child link="front_left_thigh"/>
    <origin xyz="-0.196 0.064 0.0"/>
    <limit effort="1000" lower="-3.141592" upper="3.141592" velocity="100.0"/>
  </joint>
  <link name="front_left_thigh">
    <visual>
      <origin xyz="0 0 0"/>
      <material name="blue">
        <color rgba="0 0 .8 1"/>
      </material>
      <geometry>
        <mesh filename="package://lla_quadruped_description/model/meshes/lla_5A0-binary.stl"/>
        <!--box size="0.196 0.1 0.1"/-->
      </geometry>
    </visual>
    <inertial>
      <origin xyz="0.098 0.0 0.0"/>
      <mass value="2.0"/>
      <inertia ixx="0.006" ixy="-0.00004" ixz="0.004" iyy="0.025" iyz="-0.000004" izz="0.02"/>
    </inertial>
  </link>
  <joint name="front_left_knee_pitch" type="revolute">
    <axis xyz="0 1 0"/>
    <parent link="front_left_thigh"/>
    <child link="front_left_shin"/>
    <origin xyz="0.0 0 -0.196"/>
    <limit effort="1000" lower="-3.141592" upper="3.141592" velocity="100.0"/>
  </joint>
  <link name="front_left_shin">
    <visual>
      <origin xyz="0 0 -0.095"/>
      <geometry>
        <!--box size="0.196 0.1 0.1"/-->
        <box size="0.01 0.01 0.19"/>
      </geometry>
    </visual>
    <inertial>
      <origin rpy="0 0 0" xyz="0.0 0.0 -0.098"/>
      <mass value="0.5"/>
      <inertia ixx="0.005" ixy="-0.000001" ixz="0.0006" iyy="0.005" iyz="-0.000001" izz="0.0005"/>
    </inertial>
  </link>
  <!-- Front Right Leg -->
  <joint name="front_right_hip_roll" type="revolute">
    <axis xyz="1 0 0"/>
    <parent link="body"/>
    <child link="front_right_hip"/>
    <origin xyz="-0.04 -0.206 0.0"/>
    <limit effort="1000" lower="3.141592" upper="-3.141592" velocity="100.0"/>
  </joint>
  <link name="front_right_hip">
    <visual>
      <origin rpy="0 1.57075 0" xyz="0 0 0.04"/>
      <geometry>
        <mesh filename="package://lla_quadruped_description/model/meshes/lla_5A0-binary.stl"/>
        <!--box size="0.196 0.1 0.1"/-->
      </geometry>
      <material name="blue">
        <color rgba="0 0 .8 1"/>
      </material>
    </visual>
    <inertial>
      <origin xyz="-0.098 0.0 0.0"/>
      <mass value="2.0"/>
      <inertia ixx="0.006" ixy="-0.00004" ixz="0.004" iyy="0.025" iyz="-0.000004" izz="0.02"/>
    </inertial>
  </link>
  <joint name="front_right_hip_pitch" type="revolute">
    <axis xyz="0 1 0"/>
    <parent link="front_right_hip"/>
    <child link="front_right_thigh"/>
    <origin xyz="-0.196 -0.064 0.0"/>
    <limit effort="1000" lower="-3.141592" upper="3.141592" velocity="100.0"/>
  </joint>
  <link name="front_right_thigh">
    <visual>
      <origin xyz="0 0 0"/>
      <material name="blue">
        <color rgba="0 0 .8 1"/>
      </material>
      <geometry>
        <mesh filename="package://lla_quadruped_description/model/meshes/lla_5A0-binary.stl"/>
        <!--box size="0.196 0.1 0.1"/-->
      </geometry>
    </visual>
    <inertial>
      <origin xyz="0.098 0.0 0.0"/>
      <mass value="2.0"/>
      <inertia ixx="0.006" ixy="-0.00004" ixz="0.004" iyy="0.025" iyz="-0.000004" izz="0.02"/>
    </inertial>
  </link>
  <joint name="front_right_knee_pitch" type="revolute">
    <axis xyz="0 1 0"/>
    <parent link="front_right_thigh"/>
    <child link="front_right_shin"/>
    <origin xyz="0.0 0 -0.196"/>
    <limit effort="1000" lower="-3.141592" upper="3.141592" velocity="100.0"/>
  </joint>
  <link name="front_right_shin">
    <visual>
      <origin xyz="0 0 -0.095"/>
      <geometry>
        <!--box size="0.196 0.1 0.1"/-->
        <box size="0.01 0.01 0.19"/>
      </geometry>
    </visual>
    <inertial>
      <origin rpy="0 0 0" xyz="0.0 0.0 -0.098"/>
      <mass value="0.5"/>
      <inertia ixx="0.005" ixy="-0.000001" ixz="0.0006" iyy="0.005" iyz="-0.000001" izz="0.0005"/>
    </inertial>
  </link>
  <!-- Hind Left Leg -->
  <joint name="hind_left_hip_roll" type="revolute">
    <axis xyz="1 0 0"/>
    <parent link="body"/>
    <child link="hind_left_hip"/>
    <origin xyz="0.04 0.206 0.0"/>
    <limit effort="1000" lower="-3.141592" upper="3.141592" velocity="100.0"/>
  </joint>
  <link name="hind_left_hip">
    <visual>
      <origin rpy="0 1.57075 3.141592" xyz="0 0 0.04"/>
      <geometry>
        <mesh filename="package://lla_quadruped_description/model/meshes/lla_5A0-binary.stl"/>
        <!--box size="0.196 0.1 0.1"/-->
      </geometry>
      <material name="blue">
        <color rgba="0 0 .8 1"/>
      </material>
    </visual>
    <inertial>
      <origin xyz="0.098 0.0 0.0"/>
      <mass value="2.0"/>
      <inertia ixx="0.006" ixy="-0.00004" ixz="0.004" iyy="0.025" iyz="-0.000004" izz="0.02"/>
    </inertial>
  </link>
  <joint name="hind_left_hip_pitch" type="revolute">
    <axis xyz="0 1 0"/>
    <parent link="hind_left_hip"/>
    <child link="hind_left_thigh"/>
    <origin xyz="0.196 0.064 0.0"/>
    <limit effort="1000" lower="-3.141592" upper="3.141592" velocity="100.0"/>
  </joint>
  <link name="hind_left_thigh">
    <visual>
      <origin xyz="0 0 0"/>
      <material name="blue">
        <color rgba="0 0 .8 1"/>
      </material>
      <geometry>
        <mesh filename="package://lla_quadruped_description/model/meshes/lla_5A0-binary.stl"/>
        <!--box size="0.196 0.1 0.1"/-->
      </geometry>
    </visual>
    <inertial>
      <origin xyz="0.098 0.0 0.0"/>
      <mass value="2.0"/>
      <inertia ixx="0.006" ixy="-0.00004" ixz="0.004" iyy="0.025" iyz="-0.000004" izz="0.02"/>
    </inertial>
  </link>
  <joint name="hind_left_knee_pitch" type="revolute">
    <axis xyz="0 1 0"/>
    <parent link="hind_left_thigh"/>
    <child link="hind_left_shin"/>
    <origin xyz="0.0 0 -0.196"/>
    <limit effort="1000" lower="-3.141592" upper="3.141592" velocity="100.0"/>
  </joint>
  <link name="hind_left_shin">
    <visual>
      <origin xyz="0 0 -0.095"/>
      <geometry>
        <!--box size="0.196 0.1 0.1"/-->
        <box size="0.01 0.01 0.19"/>
      </geometry>
    </visual>
    <inertial>
      <origin rpy="0 0 0" xyz="0.0 0.0 -0.098"/>
      <mass value="0.5"/>
      <inertia ixx="0.005" ixy="-0.000001" ixz="0.0006" iyy="0.005" iyz="-0.000001" izz="0.0005"/>
    </inertial>
  </link>
  <!-- Hind Right Leg -->
  <joint name="hind_right_hip_roll" type="revolute">
    <axis xyz="1 0 0"/>
    <parent link="body"/>
    <child link="hind_right_hip"/>
    <origin xyz="0.04 -0.206 0.0"/>
    <limit effort="1000" lower="3.141592" upper="-3.141592" velocity="100.0"/>
  </joint>
  <link name="hind_right_hip">
    <visual>
      <origin rpy="0 1.57075 3.141592" xyz="0 0 0.04"/>
      <geometry>
        <mesh filename="package://lla_quadruped_description/model/meshes/lla_5A0-binary.stl"/>
        <!--box size="0.196 0.1 0.1"/-->
      </geometry>
      <material name="blue">
        <color rgba="0 0 .8 1"/>
      </material>
    </visual>
    <inertial>
      <origin xyz="0.098 0.0 0.0"/>
      <mass value="2.0"/>
      <inertia ixx="0.006" ixy="-0.00004" ixz="0.004" iyy="0.025" iyz="-0.000004" izz="0.02"/>
    </inertial>
  </link>
  <joint name="hind_right_hip_pitch" type="revolute">
    <axis xyz="0 1 0"/>
    <parent link="hind_right_hip"/>
    <child link="hind_right_thigh"/>
    <origin xyz="0.196 -0.064 0.0"/>
    <limit effort="1000" lower="-3.141592" upper="3.141592" velocity="100.0"/>
  </joint>
  <link name="hind_right_thigh">
    <visual>
      <origin xyz="0 0 0"/>
      <material name="blue">
        <color rgba="0 0 .8 1"/>
      </material>
      <geometry>
        <mesh filename="package://lla_quadruped_description/model/meshes/lla_5A0-binary.stl"/>
        <!--box size="0.196 0.1 0.1"/-->
      </geometry>
    </visual>
    <inertial>
      <origin xyz="0.098 0.0 0.0"/>
      <mass value="2.0"/>
      <inertia ixx="0.006" ixy="-0.00004" ixz="0.004" iyy="0.025" iyz="-0.000004" izz="0.02"/>
    </inertial>
  </link>
  <joint name="hind_right_knee_pitch" type="revolute">
    <axis xyz="0 1 0"/>
    <parent link="hind_right_thigh"/>
    <child link="hind_right_shin"/>
    <origin xyz="0.0 0 -0.196"/>
    <limit effort="1000" lower="-3.141592" upper="3.141592" velocity="100.0"/>
  </joint>
  <link name="hind_right_shin">
    <visual>
      <origin xyz="0 0 -0.095"/>
      <geometry>
        <!--box size="0.196 0.1 0.1"/-->
        <box size="0.01 0.01 0.19"/>
      </geometry>
    </visual>
    <inertial>
      <origin rpy="0 0 0" xyz="0.0 0.0 -0.098"/>
      <mass value="0.5"/>
      <inertia ixx="0.005" ixy="-0.000001" ixz="0.0006" iyy="0.005" iyz="-0.000001" izz="0.0005"/>
    </inertial>
  </link>
</robot>

