<?xml version="1.0"?>
<robot name="drc_skeleton">

    <link name="base_link" />

    <link name="r_foot">
        <inertial>
            <mass value="4.05" />
            <origin xyz="0.027 0 -0.067" rpy="0 -0 0" />
            <inertia ixx="0.002" ixy="0" ixz="0" iyy="0.007" iyz="0" izz="0.008" />
        </inertial>
        <visual>
            <origin xyz="0 0.1 0" rpy="0 -0 0" />
            <geometry>
                <mesh filename="package://atlas_description/meshes_v3/r_foot.dae" scale="1 1 1" />
            </geometry>
        </visual>
        <visual>
            <origin xyz="0 -0.1 0" rpy="0 -0 0" />
            <geometry>
                <mesh filename="package://atlas_description/meshes_v3/l_foot.dae" scale="1 1 1" />
            </geometry>
        </visual>
        <collision>
            <origin xyz="0 0.1 0" rpy="0 -0 0" />
            <geometry>
                <mesh filename="package://atlas_description/meshes_v3/r_foot.stl" scale="1 1 1" />
            </geometry>
        </collision>
    </link>
    
    <link name="r_lleg">
        <inertial>
            <mass value="11.0" />
            <origin xyz="0 0 0.23" rpy="0 -0 0" />
            <inertia ixx="0.077" ixy="-0" ixz="-0.003" iyy="0.076" iyz="-0" izz="0.01" />
        </inertial>

        <visual>
            <origin xyz="0 -0.1 0.422" rpy="0 -0 0" />
            <geometry>
                <mesh filename="package://atlas_description/meshes_v3/r_lleg.dae" scale="1 1 1" />
            </geometry>
        </visual>
        <visual>
            <origin xyz="0 0.1 0.422" rpy="0 -0 0" />
            <geometry>
                <mesh filename="package://atlas_description/meshes_v3/l_lleg.dae" scale="1 1 1" />
            </geometry>
        </visual>

        <collision>
            <origin xyz="0 0 0.422" rpy="0 -0 0" />
            <geometry>
                <mesh filename="package://atlas_description/meshes_v3/r_lleg.stl" scale="1 1 1" />
            </geometry>
        </collision>
    </link>
    
    <link name="r_uleg">
        <inertial>
            <mass value="18.4" />
            <origin xyz="0 0 0.16" rpy="0 -0 0" />
            <inertia ixx="0.09" ixy="0" ixz="0" iyy="0.09" iyz="0" izz="0.02" />
        </inertial>
        <visual>
            <origin xyz="0.05 -0.1 0.374" rpy="0 -0 0" />
            <geometry>
                <mesh filename="package://atlas_description/meshes_v3/r_uleg.dae" scale="1 1 1" />
            </geometry>
        </visual>

        <visual>
            <origin xyz="0.05 0.1 0.374" rpy="0 -0 0" />
            <geometry>
                <mesh filename="package://atlas_description/meshes_v3/l_uleg.dae" scale="1 1 1" />
            </geometry>
        </visual>

        <collision>
            <origin xyz="0.05 0 0.374" rpy="0 -0 0" />
            <geometry>
                <mesh filename="package://atlas_description/meshes_v3/r_uleg.stl" scale="1 1 1" />
            </geometry>
        </collision>
    </link>
    
    <link name="pelvis">
        <inertial>
            <mass value="17.882" />
            <origin xyz="0.0111 0 0.0271" rpy="0 -0 0" />
            <inertia ixx="0.1244" ixy="0.0008" ixz="-0.0007" iyy="0.0958" iyz="-0.0005" izz="0.1167" />
        </inertial>
        <visual>
            <origin xyz="0 0 0" rpy="0 -0 0" />
            <geometry>
                <mesh filename="package://atlas_description/meshes_v3/pelvis.dae" scale="1 1 1" />
            </geometry>
        </visual>
        <collision>
            <origin xyz="0 0 0" rpy="0 -0 0" />
            <geometry>
                <mesh filename="package://atlas_description/meshes_v3/pelvis.stl" scale="1 1 1" />
            </geometry>
        </collision>
    </link>
    
    <link name="ltorso">
    <inertial>
      <mass value="2.409" />
      <origin xyz="-0.0112984 -3.15366e-06 0.0746835" rpy="0 -0 0" />
      <inertia ixx="0.0039092" ixy="-5.04491e-08" ixz="-0.000342157" iyy="0.00341694" iyz="4.87119e-07" izz="0.00174492" />
    </inertial>
    <visual>
      <origin xyz="0 0 0" rpy="0 -0 0" />
      <geometry>
        <mesh filename="package://atlas_description/meshes_v3/ltorso.dae" scale="1 1 1" />
      </geometry>
    </visual>
  </link>
  
  <link name="mtorso">
        <inertial>
            <mass value="0.69" />
            <origin xyz="-0.00816266 -0.0131245 0.0305974" rpy="0 -0 0" />
            <inertia ixx="0.000454181" ixy="-6.10764e-05" ixz="3.94009e-05" iyy="0.000483282" iyz="5.27463e-05" izz="0.000444215" />
        </inertial>
        <visual>
            <origin xyz="0 0 0" rpy="0 -0 0" />
            <geometry>
                <mesh filename="package://atlas_description/meshes_v3/mtorso.dae" scale="1 1 1" />
            </geometry>
        </visual>
        <collision>
            <origin xyz="0 0 0" rpy="0 -0 0" />
            <geometry>
                <mesh filename="package://atlas_description/meshes_v3/mtorso.stl" scale="1 1 1" />
            </geometry>
        </collision>
    </link>
    
    <link name="utorso">
        <inertial>
            <mass value="63.73" />
            <origin xyz="-0.0581 0 0.3056" rpy="0 -0 0" />
            <inertia ixx="1.466" ixy="0.00362" ixz="0.336" iyy="1.51" iyz="0.001" izz="1.3" />
        </inertial>
        <visual>
            <origin xyz="0 0 0" rpy="0 -0 0" />
            <geometry>
                <mesh filename="package://atlas_description/meshes_v3/utorso.dae" scale="1 1 1" />
            </geometry>
        </visual>
        <collision>
            <origin xyz="0 0 0" rpy="0 -0 0" />
            <geometry>
                <mesh filename="package://atlas_description/meshes_v3/utorso.stl" scale="1 1 1" />
            </geometry>
        </collision>
        <visual>
            <origin xyz="0 0 0" rpy="0 -0 0" />
            <geometry>
                <mesh filename="package://atlas_description/meshes_v3/utorso_pack.dae" scale="1 1 1" />
            </geometry>
        </visual>
        <collision>
            <origin xyz="0 0 0" rpy="0 -0 0" />
            <geometry>
                <mesh filename="package://atlas_description/meshes_v3/utorso_pack.stl" scale="1 1 1" />
            </geometry>
        </collision>
    </link>
    
    
    <link name="r_clav">
        <inertial>
            <mass value="3.45" />
            <!--origin xyz="0 0.00 -0.284" rpy="0.5 -0 0" -->  
            <origin xyz="0 0.00 -0.284" rpy="0.0 -0 0" />
            <inertia ixx="0.011" ixy="0" ixz="0" iyy="0.009" iyz="0.004" izz="0.004" />
        </inertial>
        <visual>
            <origin xyz="0 0.048 -0.45" rpy="0 -0 0" />
            <geometry>
                <mesh filename="package://atlas_description/meshes_v3/r_clav.dae" scale="1 1 1" />
            </geometry>
        </visual>
        <collision>
            <origin xyz="0 0.048 -0.45" rpy="0 -0 0" />
            <geometry>
                <mesh filename="package://atlas_description/meshes_v3/r_clav.stl" scale="1 1 1" />
            </geometry>
        </collision>
    </link>
    
    <link name="l_clav">
        <inertial>
            <mass value="3.45" />
            <!--origin xyz="0 0.00 -0.284" rpy="0.5 -0 0" -->
            <origin xyz="0 0.00 -0.284" rpy="0.0 -0 0" />
            <inertia ixx="0.011" ixy="0" ixz="0" iyy="0.009" iyz="-0.004" izz="0.004" />
        </inertial>
        <visual>
            <origin xyz="0 -0.048 -0.45" rpy="0 -0 0" />
            <geometry>
                <mesh filename="package://atlas_description/meshes_v3/l_clav.dae" scale="1 1 1" />
            </geometry>
        </visual>
        <collision>
            <origin xyz="0 -0.048 -0.45" rpy="0 -0 0" />
            <geometry>
                <mesh filename="package://atlas_description/meshes_v3/l_clav.stl" scale="1 1 1" />
            </geometry>
        </collision>
    </link>
    
    <link name="r_scap">
        <inertial>
            <mass value="3.012" />
            <origin xyz="0 0 0" rpy="0 -0 0" />
            <inertia ixx="0.00319" ixy="0" ixz="0" iyy="0.00583" iyz="0" izz="0.00583" />
        </inertial>
        <visual>
            <origin xyz="0 0 0" rpy="0 -0 0" />
            <geometry>
                <mesh filename="package://atlas_description/meshes_v3/r_scap.dae" scale="1 1 1" />
            </geometry>
        </visual>
        <collision>
            <origin xyz="0 0 0" rpy="0 -0 0" />
            <geometry>
                <mesh filename="package://atlas_description/meshes_v3/r_scap.stl" scale="1 1 1" />
            </geometry>
        </collision>
    </link>
    
    <link name="l_scap">
        <inertial>
            <mass value="3.012" />
            <origin xyz="0 0 0" rpy="0 -0 0" />
            <inertia ixx="0.00319" ixy="0" ixz="0" iyy="0.00583" iyz="0" izz="0.00583" />
        </inertial>
        <visual>
            <origin xyz="0 0 0" rpy="0 -0 0" />
            <geometry>
                <mesh filename="package://atlas_description/meshes_v3/l_scap.dae" scale="1 1 1" />
            </geometry>
        </visual>
        <collision>
            <origin xyz="0 0 0" rpy="0 -0 0" />
            <geometry>
                <mesh filename="package://atlas_description/meshes_v3/l_scap.stl" scale="1 1 1" />
            </geometry>
        </collision>
    </link>

    <link name="r_uarm">
        <inertial>
            <mass value="3.388" />
            <origin xyz="0 0.065 0" rpy="0 -0 0" />
            <inertia ixx="0.00656" ixy="0" ixz="0" iyy="0.00358" iyz="0" izz="0.00656" />
        </inertial>
        <visual>
            <origin xyz="0 0 0" rpy="0 -0 0" />
            <geometry>
                <mesh filename="package://atlas_description/meshes_v3/r_uarm.dae" scale="1 1 1" />
            </geometry>
        </visual>
        <collision>
            <origin xyz="0 0 0" rpy="0 -0 0" />
            <geometry>
                <mesh filename="package://atlas_description/meshes_v3/r_uarm.stl" scale="1 1 1" />
            </geometry>
        </collision>
    </link>
    
        <link name="l_uarm">
        <inertial>
            <mass value="3.388" />
            <origin xyz="0 -0.065 0" rpy="0 -0 0" />
            <inertia ixx="0.00656" ixy="0" ixz="0" iyy="0.00358" iyz="0" izz="0.00656" />
        </inertial>
        <visual>
            <origin xyz="0 0 0" rpy="0 -0 0" />
            <geometry>
                <mesh filename="package://atlas_description/meshes_v3/l_uarm.dae" scale="1 1 1" />
            </geometry>
        </visual>
        <collision>
            <origin xyz="0 0 0" rpy="0 -0 0" />
            <geometry>
                <mesh filename="package://atlas_description/meshes_v3/l_uarm.stl" scale="1 1 1" />
            </geometry>
        </collision>
    </link>
    
   <link name="r_larm">
        <inertial>
            <mass value="2.509" />
            <origin xyz="0 0 0" rpy="0 -0 0" />
            <inertia ixx="0.00265" ixy="0" ixz="0" iyy="0.00446" iyz="0" izz="0.00446" />
        </inertial>
        <visual>
            <origin xyz="0 0 0" rpy="0 -0 0" />
            <geometry>
                <mesh filename="package://atlas_description/meshes_v3/r_larm.dae" scale="1 1 1" />
            </geometry>
        </visual>
        <collision>
            <origin xyz="0 0 0" rpy="0 -0 0" />
            <geometry>
                <mesh filename="package://atlas_description/meshes_v3/r_larm.stl" scale="1 1 1" />
            </geometry>
        </collision>
    </link>
    
    <link name="l_larm">
        <inertial>
            <mass value="2.509" />
            <origin xyz="0 0 0" rpy="0 -0 0" />
            <inertia ixx="0.00265" ixy="0" ixz="0" iyy="0.00446" iyz="0" izz="0.00446" />
        </inertial>
        <visual>
            <origin xyz="0 0 0" rpy="0 -0 0" />
            <geometry>
                <mesh filename="package://atlas_description/meshes_v3/l_larm.dae" scale="1 1 1" />
            </geometry>
        </visual>
        <collision>
            <origin xyz="0 0 0" rpy="0 -0 0" />
            <geometry>
                <mesh filename="package://atlas_description/meshes_v3/l_larm.stl" scale="1 1 1" />
            </geometry>
        </collision>
    </link>
    
    <link name="r_farm">
        <inertial>
            <mass value="3.388" />
            <origin xyz="0 0.065 0" rpy="0 -0 0" />
            <inertia ixx="0.00656" ixy="0" ixz="0" iyy="0.00358" iyz="0" izz="0.00656" />
        </inertial>
        <visual>
            <origin xyz="0 0 0" rpy="0 -0 0" />
            <geometry>
                <mesh filename="package://atlas_description/meshes_v3/r_farm.dae" scale="1 1 1" />
            </geometry>
        </visual>
        <collision>
            <origin xyz="0 0 0" rpy="0 -0 0" />
            <geometry>
                <mesh filename="package://atlas_description/meshes_v3/r_farm.stl" scale="1 1 1" />
            </geometry>
        </collision>
    </link>
    
    <link name="l_farm">
        <inertial>
            <mass value="3.388" />
            <origin xyz="0 -0.065 0" rpy="0 -0 0" />
            <inertia ixx="0.00656" ixy="0" ixz="0" iyy="0.00358" iyz="0" izz="0.00656" />
        </inertial>
        <visual>
            <origin xyz="0 0 0" rpy="0 -0 0" />
            <geometry>
                <mesh filename="package://atlas_description/meshes_v3/l_farm.dae" scale="1 1 1" />
            </geometry>
        </visual>
        <collision>
            <origin xyz="0 0 0" rpy="0 -0 0" />
            <geometry>
                <mesh filename="package://atlas_description/meshes_v3/l_farm.stl" scale="1 1 1" />
            </geometry>
        </collision>
    </link>
    
    <link name="r_hand">
        <inertial>
            <mass value="2.509" />
            <origin xyz="0 0 0" rpy="0 -0 0" />
            <inertia ixx="0.00265" ixy="0" ixz="0" iyy="0.00446" iyz="0" izz="0.00446" />
        </inertial>
        <visual>
            <origin xyz="0 0 0" rpy="0 -0 0" />
            <geometry>
                <mesh filename="package://atlas_description/meshes_v3/r_hand.dae" scale="1 1 1" />
            </geometry>
        </visual>
        <collision>
            <origin xyz="0 0 0" rpy="0 -0 0" />
            <geometry>
                <mesh filename="package://atlas_description/meshes_v3/r_hand.stl" scale="1 1 1" />
            </geometry>
        </collision>
    </link>
      
    <link name="l_hand">
        <inertial>
            <mass value="2.509" />
            <origin xyz="0 0 0" rpy="0 -0 0" />
            <inertia ixx="0.00265" ixy="0" ixz="0" iyy="0.00446" iyz="0" izz="0.00446" />
        </inertial>
        <visual>
            <origin xyz="0 0 0" rpy="0 -0 0" />
            <geometry>
                <mesh filename="package://atlas_description/meshes_v3/l_hand.dae" scale="1 1 1" />
            </geometry>
        </visual>
        <collision>
            <origin xyz="0 0 0" rpy="0 -0 0" />
            <geometry>
                <mesh filename="package://atlas_description/meshes_v3/l_hand.stl" scale="1 1 1" />
            </geometry>
        </collision>
    </link>  
    

    <joint name="base_to_right_foot" type="fixed">
        <parent link="base_link"/>
        <child link="r_foot"/>
    </joint>

    <joint name="r_leg_aky" type="revolute">
        <origin xyz="-0.07 0 0.15" rpy="0 -0 0" />
        <axis xyz="0 -1 0" />
        <parent link="r_foot" />
        <child link="r_lleg" />
        <dynamics damping="0.1" friction="0" />
        <limit effort="350" velocity="12" lower="-1" upper="0.7" />
        <safety_controller k_position="100" k_velocity="100" soft_lower_limit="-11" soft_upper_limit="10.7" />
    </joint>
    <joint name="r_leg_kny" type="revolute">
        <origin xyz="0 0 0.422" rpy="0 -0 0" />
        <axis xyz="0 -1 0" />
        <parent link="r_lleg" />
        <child link="r_uleg" />
        <dynamics damping="0.1" friction="0" />
        <limit effort="246" velocity="12" lower="0.1" upper="2.35637" />
        <safety_controller k_position="100" k_velocity="100" soft_lower_limit="-10" soft_upper_limit="12.3564" />
    </joint>
    <joint name="r_leg_hpy" type="revolute">
        <origin xyz="0.05  -0.111 0.374" rpy="0 -0 0" />
        <axis xyz="0 -1 0" />
        <parent link="r_uleg" />
        <child link="pelvis" />
        <dynamics damping="0.1" friction="0" />
        <limit effort="400" velocity="12" lower="-1.61234" upper="0.65764" />
        <safety_controller k_position="100" k_velocity="100" soft_lower_limit="-11.6123" soft_upper_limit="10.6576" />
    </joint>

    <joint name="back_bkx" type="revolute">
        <origin xyz="0 0 0.05" rpy="0 -0 0" />
        <axis xyz="1 0 0" />
        <parent link="mtorso" />
        <child link="utorso" />
        <dynamics damping="0.1" friction="0" />
        <limit effort="163" velocity="12" lower="-0.523599" upper="0.523599" />
        <safety_controller k_position="100" k_velocity="100" soft_lower_limit="-10.5236" soft_upper_limit="10.5236" />
    </joint>
    <joint name="back_bky" type="revolute">
        <origin xyz="0 0 0.162" rpy="0 -0 0" />
        <axis xyz="0 1 0" />
        <parent link="ltorso" />
        <child link="mtorso" />
        <dynamics damping="0.1" friction="0" />
        <limit effort="245" velocity="9" lower="-0.219388" upper="0.538783" />
        <safety_controller k_position="100" k_velocity="100" soft_lower_limit="-10.2194" soft_upper_limit="10.5388" />
    </joint>
    <joint name="back_bkz" type="revolute">
        <origin xyz="-0.0125 0 0" rpy="0 -0 0" />
        <axis xyz="0 0 1" />
        <parent link="pelvis" />
        <child link="ltorso" />
        <dynamics damping="0.1" friction="0" />
        <limit effort="62" velocity="12" lower="-0.663225" upper="0.663225" />
        <safety_controller k_position="100" k_velocity="100" soft_lower_limit="-10.6632" soft_upper_limit="10.6632" />
    </joint>

    <joint name="r_arm_shz" type="revolute">
        <origin xyz="0.1406 -0.2036 0.4776" rpy="0 -0 0" />
        <axis xyz="0 0 1" /> <!-- note, this is opposite of v1 and v3 -->
        <parent link="utorso" />
        <child link="r_clav" />
        <dynamics damping="0.1" friction="0" />
        <limit effort="198" velocity="12" lower="-0.785398" upper="1.5708" />
        <safety_controller k_position="100" k_velocity="100" soft_lower_limit="-10.7854" soft_upper_limit="11.5708" />
    </joint>
    <joint name="r_arm_shx" type="revolute">
        <origin xyz="0 -0.0981 -0.2511" rpy="0 -0 0" />
        <axis xyz="1 0 0" />
        <parent link="r_clav" />
        <child link="r_scap" />
        <dynamics damping="0.1" friction="0" />
        <limit effort="159" velocity="12" lower="-1.5708" upper="1.5708" />
        <safety_controller k_position="100" k_velocity="100" soft_lower_limit="-11.5708" soft_upper_limit="11.5708" />
    </joint>
    <joint name="r_arm_ely" type="revolute">
        <origin xyz="0 -0.187 0.016" rpy="0 -0 0" />
        <axis xyz="0 1 0" />
        <parent link="r_scap" />
        <child link="r_uarm" />
        <dynamics damping="0.1" friction="0" />
        <limit effort="106" velocity="12" lower="0" upper="3.14159" />
        <safety_controller k_position="100" k_velocity="100" soft_lower_limit="-10" soft_upper_limit="13.1416" />
    </joint>
    <joint name="r_arm_elx" type="revolute">
        <origin xyz="0 -0.119 0.0092" rpy="0 -0 0" />
        <axis xyz="1 0 0" />
        <parent link="r_uarm" />
        <child link="r_larm" />
        <dynamics damping="0.1" friction="0" />
        <limit effort="159" velocity="12" lower="-2.35619" upper="-0.2" />
        <safety_controller k_position="100" k_velocity="100" soft_lower_limit="-12.3562" soft_upper_limit="10" />
    </joint>
    <joint name="r_arm_wry" type="revolute">
        <origin xyz="0 -0.187 -0.0092" rpy="0 -0 0" />
        <axis xyz="0 1 0" />
        <parent link="r_larm" />
        <child link="r_farm" />
        <dynamics damping="0.1" friction="0" />
        <limit effort="106" velocity="12" lower="0" upper="3.14159" />
        <safety_controller k_position="100" k_velocity="100" soft_lower_limit="-10" soft_upper_limit="13.1416" />
    </joint>
    <joint name="r_arm_wrx" type="revolute">
        <origin xyz="0 -0.119 0.0092" rpy="0 -0 0" />
        <axis xyz="1 0 0" />
        <parent link="r_farm" />
        <child link="r_hand" />
        <dynamics damping="0.1" friction="0" />
        <limit effort="56" velocity="12" lower="-1.1781" upper="1.1781" />
        <safety_controller k_position="100" k_velocity="100" soft_lower_limit="-11.1781" soft_upper_limit="11.1781" />
    </joint>

    <joint name="r_ee_fixed_joint" type="fixed">
        <parent link="r_hand"/>
        <child  link="r_ee_link"/>
        <origin rpy=" 0 0 -1.5708" xyz="0 -0.10  0"/>
    </joint>    
    <link name="r_ee_link"/>

	
	
	<joint name="l_arm_shz" type="revolute">
        <origin xyz="0.1406 0.2036 0.4776" rpy="0 -0 0" />
        <axis xyz="0 0 1" />
        <parent link="utorso" />
        <child link="l_clav" />
        <dynamics damping="0.1" friction="0" />
        <limit effort="198" velocity="12" lower="-1.5708" upper="0.785398" />
        <safety_controller k_position="100" k_velocity="100" soft_lower_limit="-11.5708" soft_upper_limit="10.7854" />
    </joint>
    
    <joint name="l_arm_shx" type="revolute">
        <origin xyz="0 0.0981 -0.2511" rpy="0 -0 0" />
        <axis xyz="1 0 0" />
        <parent link="l_clav" />
        <child link="l_scap" />
        <dynamics damping="0.1" friction="0" />
        <limit effort="159" velocity="12" lower="-1.5708" upper="1.5708" />
        <safety_controller k_position="100" k_velocity="100" soft_lower_limit="-11.5708" soft_upper_limit="11.5708" />
    </joint>
    
    <joint name="l_arm_ely" type="revolute">
        <origin xyz="0 0.187 0.016" rpy="0 -0 0" />
        <axis xyz="0 1 0" />
        <parent link="l_scap" />
        <child link="l_uarm" />
        <dynamics damping="0.1" friction="0" />
        <limit effort="106" velocity="12" lower="0" upper="3.14159" />
        <safety_controller k_position="100" k_velocity="100" soft_lower_limit="-10" soft_upper_limit="13.1416" />
    </joint>
    
    <joint name="l_arm_elx" type="revolute">
        <origin xyz="0 0.119 0.0092" rpy="0 -0 0" />
        <axis xyz="1 0 0" />
        <parent link="l_uarm" />
        <child link="l_larm" />
        <dynamics damping="0.1" friction="0" />
        <limit effort="159" velocity="12" lower="0" upper="2.35619" />
        <safety_controller k_position="100" k_velocity="100" soft_lower_limit="-10" soft_upper_limit="12.3562" />
    </joint>
    
    <joint name="l_arm_wry" type="revolute">
        <origin xyz="0 0.187 -0.0092" rpy="0 -0 0" />
        <axis xyz="0 1 0" />
        <parent link="l_larm" />
        <child link="l_farm" />
        <dynamics damping="0.1" friction="0" />
        <limit effort="106" velocity="12" lower="0" upper="3.14159" />
        <safety_controller k_position="100" k_velocity="100" soft_lower_limit="-10" soft_upper_limit="13.1416" />
    </joint>
    
    <joint name="l_arm_wrx" type="revolute">
        <origin xyz="0 0.119 0.0092" rpy="0 -0 0" />
        <axis xyz="1 0 0" />
        <parent link="l_farm" />
        <child link="l_hand" />
        <dynamics damping="0.1" friction="0" />
        <limit effort="56" velocity="12" lower="-1.1781" upper="1.1781" />
        <safety_controller k_position="100" k_velocity="100" soft_lower_limit="-11.1781" soft_upper_limit="11.1781" />
    </joint>

	<joint name="l_ee_fixed_joint" type="fixed">
        <parent link="l_hand"/>
        <child  link="l_ee_link"/>
        <origin rpy=" 0 0  1.5708" xyz=" 0 0.10  0"/>
    </joint>    
    <link name="l_ee_link"/>

</robot>
