<sdf version='1.4'>
  <model name='genericQuadruped'>
    <link name='body'>
      <sensor name='IMU' type='imu'>
        <always_on>1</always_on>
        <update_rate>1000</update_rate>
        <imu>
          <noise>
            <type>gaussian</type>
            <rate>
              <mean>0</mean>
              <stddev>0.0002</stddev>
              <bias_mean>7.5e-06</bias_mean>
              <bias_stddev>8e-07</bias_stddev>
            </rate>
            <accel>
              <mean>0</mean>
              <stddev>0.017</stddev>
              <bias_mean>0.1</bias_mean>
              <bias_stddev>0.001</bias_stddev>
            </accel>
          </noise>
        </imu>
        <pose>-0.17998 0.01225 0.130 0 0 1.57079</pose>
      </sensor>

      <!-- TODO: These sensor locations are approximate and need to be measured when the cameras are locked down. -->
      <sensor name='front_left_realsense_rgb_sensor' type='camera'>
        <visualize>1</visualize>
        <update_rate>60</update_rate>
        <camera name='front_left_realsense_rgb_sensor_camera'>
          <horizontal_fov>2</horizontal_fov>
          <image>
            <width>640</width>
            <height>480</height>
            <format>R8G8B8</format>
          </image>
          <clip>
            <near>0.02</near>
            <far>300</far>
          </clip>
        </camera>
        <pose>0.335 0.305 -0.037 0 0.524 1.570</pose>
      </sensor>
      <sensor name='front_left_realsense_pointcloud_sensor' type='gpu_ray'>
        <visualize>1</visualize>
        <update_rate>60</update_rate>
        <ray>
          <scan>
            <horizontal>
              <samples>480</samples>
              <resolution>1</resolution>
              <min_angle>-1.0297</min_angle>
              <max_angle>1.0297</max_angle>
            </horizontal>
          </scan>
          <range>
            <min>0.1</min>
            <max>30</max>
            <resolution>0.01</resolution>
          </range>
        </ray>
        <pose>0.335 0.305 -0.037 0 0.524 1.570</pose>
      </sensor>

      <!-- TODO: These sensor locations are approximate and need to be measured when the cameras are locked down. -->
      <sensor name='front_right_realsense_rgb_sensor' type='camera'>
        <visualize>1</visualize>
        <update_rate>60</update_rate>
        <camera name='front_right_realsense_rgb_sensor_camera'>
          <horizontal_fov>2</horizontal_fov>
          <image>
            <width>640</width>
            <height>480</height>
            <format>R8G8B8</format>
          </image>
          <clip>
            <near>0.02</near>
            <far>300</far>
          </clip>
        </camera>
        <pose>0.335 -0.305 -0.037 0 0.524 -1.570</pose>
      </sensor>
      <sensor name='front_right_realsense_pointcloud_sensor' type='gpu_ray'>
        <visualize>1</visualize>
        <update_rate>60</update_rate>
        <ray>
          <scan>
            <horizontal>
              <samples>480</samples>
              <resolution>1</resolution>
              <min_angle>-1.0297</min_angle>
              <max_angle>1.0297</max_angle>
            </horizontal>
          </scan>
          <range>
            <min>0.1</min>
            <max>30</max>
            <resolution>0.01</resolution>
          </range>
        </ray>
        <pose>0.335 -0.305 -0.037 0 0.524 -1.570</pose>
      </sensor>

      <!-- TODO: These sensor locations are approximate and need to be measured when the cameras are locked down. -->
      <sensor name='hind_left_realsense_rgb_sensor' type='camera'>
        <visualize>1</visualize>
        <update_rate>60</update_rate>
        <camera name='hind_left_realsense_rgb_sensor_camera'>
          <horizontal_fov>2</horizontal_fov>
          <image>
            <width>640</width>
            <height>480</height>
            <format>R8G8B8</format>
          </image>
          <clip>
            <near>0.02</near>
            <far>300</far>
          </clip>
        </camera>
        <pose>-0.335 0.305 -0.037 0 0.524 1.570</pose>
      </sensor>
      <sensor name='hind_left_realsense_pointcloud_sensor' type='gpu_ray'>
        <visualize>1</visualize>
        <update_rate>60</update_rate>
        <ray>
          <scan>
            <horizontal>
              <samples>480</samples>
              <resolution>1</resolution>
              <min_angle>-1.0297</min_angle>
              <max_angle>1.0297</max_angle>
            </horizontal>
          </scan>
          <range>
            <min>0.1</min>
            <max>30</max>
            <resolution>0.01</resolution>
          </range>
        </ray>
        <pose>-0.335 0.305 -0.037 0 0.524 1.570</pose>
      </sensor>

      <!-- TODO: These sensor locations are approximate and need to be measured when the cameras are locked down. -->
      <sensor name='hind_right_realsense_rgb_sensor' type='camera'>
        <visualize>1</visualize>
        <update_rate>60</update_rate>
        <camera name='hind_right_realsense_rgb_sensor_camera'>
          <horizontal_fov>2</horizontal_fov>
          <image>
            <width>640</width>
            <height>480</height>
            <format>R8G8B8</format>
          </image>
          <clip>
            <near>0.02</near>
            <far>300</far>
          </clip>
        </camera>
        <pose>-0.335 -0.305 -0.037 0 0.524 -1.570</pose>
      </sensor>
      <sensor name='hind_right_realsense_pointcloud_sensor' type='gpu_ray'>
        <visualize>1</visualize>
        <update_rate>60</update_rate>
        <ray>
          <scan>
            <horizontal>
              <samples>480</samples>
              <resolution>1</resolution>
              <min_angle>-1.0297</min_angle>
              <max_angle>1.0297</max_angle>
            </horizontal>
          </scan>
          <range>
            <min>0.1</min>
            <max>30</max>
            <resolution>0.01</resolution>
          </range>
        </ray>
        <pose>-0.335 -0.305 -0.037 0 0.524 -1.570</pose>
      </sensor>

      <!-- TODO: These sensor locations are approximate and need to be measured when the cameras are locked down. -->
      <sensor name='hind_realsense_rgb_sensor' type='camera'>
        <visualize>1</visualize>
        <update_rate>60</update_rate>
        <camera name='hind_realsense_rgb_sensor_camera'>
          <horizontal_fov>2</horizontal_fov>
          <image>
            <width>640</width>
            <height>480</height>
            <format>R8G8B8</format>
          </image>
          <clip>
            <near>0.02</near>
            <far>300</far>
          </clip>
        </camera>
        <pose>-0.52 0 0.248 0 0.611 3.142</pose>
      </sensor>
      <sensor name='hind_realsense_pointcloud_sensor' type='gpu_ray'>
        <visualize>1</visualize>
        <update_rate>60</update_rate>
        <ray>
          <scan>
            <horizontal>
              <samples>480</samples>
              <resolution>1</resolution>
              <min_angle>-1.0297</min_angle>
              <max_angle>1.0297</max_angle>
            </horizontal>
          </scan>
          <range>
            <min>0.1</min>
            <max>30</max>
            <resolution>0.01</resolution>
          </range>
        </ray>
        <pose>-0.52 0 0.248 0 0.611 3.142</pose>
      </sensor>
      <pose>0 0 0 0 -0 0</pose>
      <inertial>
        <pose>0.015 -0.005 0.068 0 -0 0</pose>
        <mass>44.44</mass>
        <inertia>
          <ixx>1.20601</ixx>
          <ixy>0.00821625</ixy>
          <ixz>0.00675587</ixz>
          <iyy>2.65319</iyy>
          <iyz>-0.00089907</iyz>
          <izz>2.65845</izz>
        </inertia>
      </inertial>
      <visual name='body_visual'>
        <pose>0 0 0 0 -0 0</pose>
        <geometry>
          <mesh>
            <scale>1 1 1</scale>
            <uri>model://genericQuadruped/meshes/genericBody.obj</uri>
          </mesh>
        </geometry>
      </visual>
      <velocity_decay>
        <linear>0</linear>
        <angular>0</angular>
      </velocity_decay>
    </link>
    <link name='front_left_hip'>
      <pose>0.52 0.175 -0.037 0 -0 0</pose>
      <inertial>
        <pose>-0.191741 -0.00019543 0.00990686 0 -0 0</pose>
        <mass>3.3</mass>
        <inertia>
          <ixx>0.00756838</ixx>
          <ixy>-4.609e-05</ixy>
          <ixz>0.00507724</ixz>
          <iyy>0.0316583</iyy>
          <iyz>-5.84e-06</iyz>
          <izz>0.0299213</izz>
        </inertia>
      </inertial>
      <visual name='front_left_hip_visual'>
        <pose>0 0 0 0 -0 3.141592</pose>
        <geometry>
          <mesh>
            <scale>1 1 1</scale>
            <uri>model://genericQuadruped/meshes/genericHip.obj</uri>
          </mesh>
        </geometry>
      </visual>
      <velocity_decay>
        <linear>0</linear>
        <angular>0</angular>
      </velocity_decay>
    </link>
    <joint name='front_left_hip_roll' type='revolute'>
      <child>front_left_hip</child>
      <parent>body</parent>
      <axis>
        <xyz>1 0 0</xyz>
        <limit>
          <lower>-0.436332</lower>
          <upper>0.610865</upper>
          <effort>1000</effort>
          <velocity>100</velocity>
        </limit>
        <dynamics/>
      </axis>
    </joint>
    <link name='front_left_thigh'>
      <pose>0.41 0.175 -0.087 0 -0 0</pose>
      <inertial>
        <pose>0.00725758 -9.352e-05 -0.137599 0 -0 0</pose>
        <mass>3.3</mass>
        <inertia>
          <ixx>0.0355714</ixx>
          <ixy>7.74e-06</ixy>
          <ixz>-0.00339495</ixz>
          <iyy>0.0372191</iyy>
          <iyz>3.369e-05</iyz>
          <izz>0.00539764</izz>
        </inertia>
      </inertial>
      <visual name='front_left_thigh_visual'>
        <pose>0 0 0 0 0 3.141592</pose>
        <geometry>
          <mesh>
            <scale>1 1 1</scale>
            <uri>model://genericQuadruped/meshes/genericThigh.obj</uri>
          </mesh>
        </geometry>
      </visual>
      <velocity_decay>
        <linear>0</linear>
        <angular>0</angular>
      </velocity_decay>
    </link>
    <joint name='front_left_hip_pitch' type='revolute'>
      <child>front_left_thigh</child>
      <parent>front_left_hip</parent>
      <axis>
        <xyz>0 1 0</xyz>
        <limit>
          <lower>-0.872665</lower>
          <upper>1.22173</upper>
          <effort>1000</effort>
          <velocity>100</velocity>
        </limit>
        <dynamics/>
      </axis>
    </joint>
    <link name='front_left_shin'>
      <pose>0.41 0.175 -0.4028 0 -0 0</pose>
      <inertial>
        <pose>-0.0169721 -1.746e-05 -0.126855 0 -0 0</pose>
        <mass>0.4</mass>
        <inertia>
          <ixx>0.00724904</ixx>
          <ixy>-1.5e-07</ixy>
          <ixz>0.00088215</ixz>
          <iyy>0.00777078</iyy>
          <iyz>-1.08e-06</iyz>
          <izz>0.00071559</izz>
        </inertia>
      </inertial>
      <visual name='front_left_shin_visual'>
        <pose>0 0 0 0 -0 0</pose>
        <geometry>
          <mesh>
            <scale>1 1 1</scale>
            <uri>model://genericQuadruped/meshes/genericShin.obj</uri>
          </mesh>
        </geometry>
      </visual>
      <velocity_decay>
        <linear>0</linear>
        <angular>0</angular>
      </velocity_decay>
    </link>
    <joint name='front_left_knee_pitch' type='revolute'>
      <child>front_left_shin</child>
      <parent>front_left_thigh</parent>
      <axis>
        <xyz>0 1 0</xyz>
        <limit>
          <lower>-2.0944</lower>
          <upper>-0.08</upper>
          <effort>1000</effort>
          <velocity>100</velocity>
        </limit>
        <dynamics/>
      </axis>
    </joint>
    <link name='front_right_hip'>
      <pose>0.52 -0.175 -0.037 0 -0 0</pose>
      <inertial>
        <pose>-0.191741 -0.00019543 0.00990686 0 -0 0</pose>
        <mass>3.3</mass>
        <inertia>
          <ixx>0.00756838</ixx>
          <ixy>-4.609e-05</ixy>
          <ixz>0.00507724</ixz>
          <iyy>0.0316583</iyy>
          <iyz>-5.84e-06</iyz>
          <izz>0.0299213</izz>
        </inertia>
      </inertial>
      <visual name='front_right_hip_visual'>
        <pose>0 0 0 0 -0 3.141592</pose>
        <geometry>
          <mesh>
            <scale>1 1 1</scale>
            <uri>model://genericQuadruped/meshes/genericHip.obj</uri>
          </mesh>
        </geometry>
      </visual>
      <velocity_decay>
        <linear>0</linear>
        <angular>0</angular>
      </velocity_decay>
    </link>
    <joint name='front_right_hip_roll' type='revolute'>
      <child>front_right_hip</child>
      <parent>body</parent>
      <axis>
        <xyz>1 0 0</xyz>
        <limit>
          <lower>-0.610865</lower>
          <upper>0.436332</upper>
          <effort>1000</effort>
          <velocity>100</velocity>
        </limit>
        <dynamics/>
      </axis>
    </joint>
    <link name='front_right_thigh'>
      <pose>0.41 -0.175 -0.087 0 -0 0</pose>
      <inertial>
        <pose>0.00725758 -9.352e-05 -0.137599 0 -0 0</pose>
        <mass>3.3</mass>
        <inertia>
          <ixx>0.0355714</ixx>
          <ixy>7.74e-06</ixy>
          <ixz>-0.00339495</ixz>
          <iyy>0.0372191</iyy>
          <iyz>3.369e-05</iyz>
          <izz>0.00539764</izz>
        </inertia>
      </inertial>
      <visual name='front_right_thigh_visual'>
        <pose>0 0 0 0 0 0</pose>
        <geometry>
          <mesh>
            <scale>1 1 1</scale>
            <uri>model://genericQuadruped/meshes/genericThigh.obj</uri>
          </mesh>
        </geometry>
      </visual>
      <velocity_decay>
        <linear>0</linear>
        <angular>0</angular>
      </velocity_decay>
    </link>
    <joint name='front_right_hip_pitch' type='revolute'>
      <child>front_right_thigh</child>
      <parent>front_right_hip</parent>
      <axis>
        <xyz>0 1 0</xyz>
        <limit>
          <lower>-0.872665</lower>
          <upper>1.22173</upper>
          <effort>1000</effort>
          <velocity>100</velocity>
        </limit>
        <dynamics/>
      </axis>
    </joint>
    <link name='front_right_shin'>
      <pose>0.41 -0.175 -0.4028 0 -0 0</pose>
      <inertial>
        <pose>-0.0169721 -1.746e-05 -0.126855 0 -0 0</pose>
        <mass>0.4</mass>
        <inertia>
          <ixx>0.00724904</ixx>
          <ixy>-1.5e-07</ixy>
          <ixz>0.00088215</ixz>
          <iyy>0.00777078</iyy>
          <iyz>-1.08e-06</iyz>
          <izz>0.00071559</izz>
        </inertia>
      </inertial>
      <visual name='front_right_shin_visual'>
        <pose>0 0 0 0 -0 0</pose>
        <geometry>
          <mesh>
            <scale>1 1 1</scale>
            <uri>model://genericQuadruped/meshes/genericShin.obj</uri>
          </mesh>
        </geometry>
      </visual>
      <velocity_decay>
        <linear>0</linear>
        <angular>0</angular>
      </velocity_decay>
    </link>
    <joint name='front_right_knee_pitch' type='revolute'>
      <child>front_right_shin</child>
      <parent>front_right_thigh</parent>
      <axis>
        <xyz>0 1 0</xyz>
        <limit>
          <lower>-2.0944</lower>
          <upper>-0.08</upper>
          <effort>1000</effort>
          <velocity>100</velocity>
        </limit>
        <dynamics/>
      </axis>
    </joint>
    <link name='hind_left_hip'>
      <pose>-0.52 0.175 -0.037 0 -0 0</pose>
      <inertial>
        <pose>0.191741 -0.00019543 0.00990686 0 -0 0</pose>
        <mass>3.3</mass>
        <inertia>
          <ixx>0.00756838</ixx>
          <ixy>-4.609e-05</ixy>
          <ixz>0.00507724</ixz>
          <iyy>0.0316583</iyy>
          <iyz>-5.84e-06</iyz>
          <izz>0.0299213</izz>
        </inertia>
      </inertial>
      <visual name='hind_left_hip_visual'>
        <pose>0 0 0 0 -0 0</pose>
        <geometry>
          <mesh>
            <scale>1 1 1</scale>
            <uri>model://genericQuadruped/meshes/genericHip.obj</uri>
          </mesh>
        </geometry>
      </visual>
      <velocity_decay>
        <linear>0</linear>
        <angular>0</angular>
      </velocity_decay>
    </link>
    <joint name='hind_left_hip_roll' type='revolute'>
      <child>hind_left_hip</child>
      <parent>body</parent>
      <axis>
        <xyz>1 0 0</xyz>
        <limit>
          <lower>-0.436332</lower>
          <upper>0.610865</upper>
          <effort>1000</effort>
          <velocity>100</velocity>
        </limit>
        <dynamics/>
      </axis>
    </joint>
    <link name='hind_left_thigh'>
      <pose>-0.41 0.175 -0.087 0 -0 0</pose>
      <inertial>
        <pose>0.00725758 -9.352e-05 -0.137599 0 -0 0</pose>
        <mass>3.3</mass>
        <inertia>
          <ixx>0.0355714</ixx>
          <ixy>7.74e-06</ixy>
          <ixz>-0.00339495</ixz>
          <iyy>0.0372191</iyy>
          <iyz>3.369e-05</iyz>
          <izz>0.00539764</izz>
        </inertia>
      </inertial>
      <visual name='hind_left_thigh_visual'>
        <pose>0 0 0 0 0 3.141592</pose>
        <geometry>
          <mesh>
            <scale>1 1 1</scale>
            <uri>model://genericQuadruped/meshes/genericThigh.obj</uri>
          </mesh>
        </geometry>
      </visual>
      <velocity_decay>
        <linear>0</linear>
        <angular>0</angular>
      </velocity_decay>
    </link>
    <joint name='hind_left_hip_pitch' type='revolute'>
      <child>hind_left_thigh</child>
      <parent>hind_left_hip</parent>
      <axis>
        <xyz>0 1 0</xyz>
        <limit>
          <lower>-1.22173</lower>
          <upper>0.872665</upper>
          <effort>1000</effort>
          <velocity>100</velocity>
        </limit>
        <dynamics/>
      </axis>
    </joint>
    <link name='hind_left_shin'>
      <pose>-0.41 0.175 -0.4028 0 -0 0</pose>
      <inertial>
        <pose>-0.0169721 -1.746e-05 -0.126855 0 -0 0</pose>
        <mass>0.4</mass>
        <inertia>
          <ixx>0.00724904</ixx>
          <ixy>-1.5e-07</ixy>
          <ixz>0.00088215</ixz>
          <iyy>0.00777078</iyy>
          <iyz>-1.08e-06</iyz>
          <izz>0.00071559</izz>
        </inertia>
      </inertial>
      <visual name='hind_left_shin_visual'>
        <pose>0 0 0 0 -0 3.14158</pose>
        <geometry>
          <mesh>
            <scale>1 1 1</scale>
            <uri>model://genericQuadruped/meshes/genericShin.obj</uri>
          </mesh>
        </geometry>
      </visual>
      <velocity_decay>
        <linear>0</linear>
        <angular>0</angular>
      </velocity_decay>
    </link>
    <joint name='hind_left_knee_pitch' type='revolute'>
      <child>hind_left_shin</child>
      <parent>hind_left_thigh</parent>
      <axis>
        <xyz>0 1 0</xyz>
        <limit>
          <lower>0.08</lower>
          <upper>2.0944</upper>
          <effort>1000</effort>
          <velocity>100</velocity>
        </limit>
        <dynamics/>
      </axis>
    </joint>
    <link name='hind_right_hip'>
      <pose>-0.52 -0.175 -0.037 0 -0 0</pose>
      <inertial>
        <pose>0.191741 -0.00019543 0.00990686 0 -0 0</pose>
        <mass>3.3</mass>
        <inertia>
          <ixx>0.00756838</ixx>
          <ixy>-4.609e-05</ixy>
          <ixz>0.00507724</ixz>
          <iyy>0.0316583</iyy>
          <iyz>-5.84e-06</iyz>
          <izz>0.0299213</izz>
        </inertia>
      </inertial>
      <visual name='hind_right_hip_visual'>
        <pose>0 0 0 0 -0 0</pose>
        <geometry>
          <mesh>
            <scale>1 1 1</scale>
            <uri>model://genericQuadruped/meshes/genericHip.obj</uri>
          </mesh>
        </geometry>
      </visual>
      <velocity_decay>
        <linear>0</linear>
        <angular>0</angular>
      </velocity_decay>
    </link>
    <joint name='hind_right_hip_roll' type='revolute'>
      <child>hind_right_hip</child>
      <parent>body</parent>
      <axis>
        <xyz>1 0 0</xyz>
        <limit>
          <lower>-0.610865</lower>
          <upper>0.436332</upper>
          <effort>1000</effort>
          <velocity>100</velocity>
        </limit>
        <dynamics/>
      </axis>
    </joint>
    <link name='hind_right_thigh'>
      <pose>-0.41 -0.175 -0.087 0 -0 0</pose>
      <inertial>
        <pose>0.00725758 -9.352e-05 -0.137599 0 -0 0</pose>
        <mass>3.3</mass>
        <inertia>
          <ixx>0.0355714</ixx>
          <ixy>7.74e-06</ixy>
          <ixz>-0.00339495</ixz>
          <iyy>0.0372191</iyy>
          <iyz>3.369e-05</iyz>
          <izz>0.00539764</izz>
        </inertia>
      </inertial>
      <visual name='hind_right_thigh_visual'>
        <pose>0 0 0 0 0 0</pose>
        <geometry>
          <mesh>
            <scale>1 1 1</scale>
            <uri>model://genericQuadruped/meshes/genericThigh.obj</uri>
          </mesh>
        </geometry>
      </visual>
      <velocity_decay>
        <linear>0</linear>
        <angular>0</angular>
      </velocity_decay>
    </link>
    <joint name='hind_right_hip_pitch' type='revolute'>
      <child>hind_right_thigh</child>
      <parent>hind_right_hip</parent>
      <axis>
        <xyz>0 1 0</xyz>
        <limit>
          <lower>-1.22173</lower>
          <upper>0.872665</upper>
          <effort>1000</effort>
          <velocity>100</velocity>
        </limit>
        <dynamics/>
      </axis>
    </joint>
    <link name='hind_right_shin'>
      <pose>-0.41 -0.175 -0.4028 0 -0 0</pose>
      <inertial>
        <pose>-0.0169721 -1.746e-05 -0.126855 0 -0 0</pose>
        <mass>0.4</mass>
        <inertia>
          <ixx>0.00724904</ixx>
          <ixy>-1.5e-07</ixy>
          <ixz>0.00088215</ixz>
          <iyy>0.00777078</iyy>
          <iyz>-1.08e-06</iyz>
          <izz>0.00071559</izz>
        </inertia>
      </inertial>
      <visual name='hind_right_shin_visual'>
        <pose>0 0 0 0 -0 3.14158</pose>
        <geometry>
          <mesh>
            <scale>1 1 1</scale>
            <uri>model://genericQuadruped/meshes/genericShin.obj</uri>
          </mesh>
        </geometry>
      </visual>
      <velocity_decay>
        <linear>0</linear>
        <angular>0</angular>
      </velocity_decay>
    </link>
    <joint name='hind_right_knee_pitch' type='revolute'>
      <child>hind_right_shin</child>
      <parent>hind_right_thigh</parent>
      <axis>
        <xyz>0 1 0</xyz>
        <limit>
          <lower>0.08</lower>
          <upper>2.0944</upper>
          <effort>1000</effort>
          <velocity>100</velocity>
        </limit>
        <dynamics/>
      </axis>
    </joint>
  </model>
</sdf>
